[2025-04-05T23:17:32.240+0000] {processor.py:186} INFO - Started process (PID=40) to work on /opt/airflow/dags/dag.py
[2025-04-05T23:17:32.241+0000] {processor.py:914} INFO - Processing file /opt/airflow/dags/dag.py for tasks to queue
[2025-04-05T23:17:32.244+0000] {logging_mixin.py:190} INFO - [2025-04-05T23:17:32.244+0000] {dagbag.py:588} INFO - Filling up the DagBag from /opt/airflow/dags/dag.py
[2025-04-05T23:17:32.264+0000] {logging_mixin.py:190} INFO - [2025-04-05T23:17:32.261+0000] {dagbag.py:387} ERROR - Failed to import: /opt/airflow/dags/dag.py
Traceback (most recent call last):
  File "/home/airflow/.local/lib/python3.12/site-packages/airflow/models/dagbag.py", line 383, in parse
    loader.exec_module(new_module)
  File "<frozen importlib._bootstrap_external>", line 999, in exec_module
  File "<frozen importlib._bootstrap>", line 488, in _call_with_frames_removed
  File "/opt/airflow/dags/dag.py", line 8, in <module>
    from tqdm import tqdm
ModuleNotFoundError: No module named 'tqdm'
[2025-04-05T23:17:32.266+0000] {processor.py:927} WARNING - No viable dags retrieved from /opt/airflow/dags/dag.py
[2025-04-05T23:17:32.289+0000] {processor.py:208} INFO - Processing /opt/airflow/dags/dag.py took 0.058 seconds
[2025-04-05T23:17:58.741+0000] {processor.py:186} INFO - Started process (PID=42) to work on /opt/airflow/dags/dag.py
[2025-04-05T23:17:58.744+0000] {processor.py:914} INFO - Processing file /opt/airflow/dags/dag.py for tasks to queue
[2025-04-05T23:17:58.749+0000] {logging_mixin.py:190} INFO - [2025-04-05T23:17:58.747+0000] {dagbag.py:588} INFO - Filling up the DagBag from /opt/airflow/dags/dag.py
[2025-04-05T23:17:58.764+0000] {logging_mixin.py:190} INFO - [2025-04-05T23:17:58.761+0000] {dagbag.py:387} ERROR - Failed to import: /opt/airflow/dags/dag.py
Traceback (most recent call last):
  File "/home/airflow/.local/lib/python3.12/site-packages/airflow/models/dagbag.py", line 383, in parse
    loader.exec_module(new_module)
  File "<frozen importlib._bootstrap_external>", line 999, in exec_module
  File "<frozen importlib._bootstrap>", line 488, in _call_with_frames_removed
  File "/opt/airflow/dags/dag.py", line 8, in <module>
    from tqdm import tqdm
ModuleNotFoundError: No module named 'tqdm'
[2025-04-05T23:17:58.764+0000] {processor.py:927} WARNING - No viable dags retrieved from /opt/airflow/dags/dag.py
[2025-04-05T23:17:58.791+0000] {processor.py:208} INFO - Processing /opt/airflow/dags/dag.py took 0.058 seconds
[2025-04-05T23:18:29.305+0000] {processor.py:186} INFO - Started process (PID=105) to work on /opt/airflow/dags/dag.py
[2025-04-05T23:18:29.308+0000] {processor.py:914} INFO - Processing file /opt/airflow/dags/dag.py for tasks to queue
[2025-04-05T23:18:29.314+0000] {logging_mixin.py:190} INFO - [2025-04-05T23:18:29.312+0000] {dagbag.py:588} INFO - Filling up the DagBag from /opt/airflow/dags/dag.py
[2025-04-05T23:18:29.331+0000] {logging_mixin.py:190} INFO - [2025-04-05T23:18:29.330+0000] {dagbag.py:387} ERROR - Failed to import: /opt/airflow/dags/dag.py
Traceback (most recent call last):
  File "/home/airflow/.local/lib/python3.12/site-packages/airflow/models/dagbag.py", line 383, in parse
    loader.exec_module(new_module)
  File "<frozen importlib._bootstrap_external>", line 999, in exec_module
  File "<frozen importlib._bootstrap>", line 488, in _call_with_frames_removed
  File "/opt/airflow/dags/dag.py", line 8, in <module>
    from tqdm import tqdm
ModuleNotFoundError: No module named 'tqdm'
[2025-04-05T23:18:29.332+0000] {processor.py:927} WARNING - No viable dags retrieved from /opt/airflow/dags/dag.py
[2025-04-05T23:18:29.362+0000] {processor.py:208} INFO - Processing /opt/airflow/dags/dag.py took 0.072 seconds
[2025-04-05T23:18:59.640+0000] {processor.py:186} INFO - Started process (PID=169) to work on /opt/airflow/dags/dag.py
[2025-04-05T23:18:59.641+0000] {processor.py:914} INFO - Processing file /opt/airflow/dags/dag.py for tasks to queue
[2025-04-05T23:18:59.644+0000] {logging_mixin.py:190} INFO - [2025-04-05T23:18:59.644+0000] {dagbag.py:588} INFO - Filling up the DagBag from /opt/airflow/dags/dag.py
[2025-04-05T23:18:59.652+0000] {logging_mixin.py:190} INFO - [2025-04-05T23:18:59.652+0000] {dagbag.py:387} ERROR - Failed to import: /opt/airflow/dags/dag.py
Traceback (most recent call last):
  File "/home/airflow/.local/lib/python3.12/site-packages/airflow/models/dagbag.py", line 383, in parse
    loader.exec_module(new_module)
  File "<frozen importlib._bootstrap_external>", line 999, in exec_module
  File "<frozen importlib._bootstrap>", line 488, in _call_with_frames_removed
  File "/opt/airflow/dags/dag.py", line 8, in <module>
    from tqdm import tqdm
ModuleNotFoundError: No module named 'tqdm'
[2025-04-05T23:18:59.653+0000] {processor.py:927} WARNING - No viable dags retrieved from /opt/airflow/dags/dag.py
[2025-04-05T23:18:59.669+0000] {processor.py:208} INFO - Processing /opt/airflow/dags/dag.py took 0.036 seconds
[2025-04-05T23:19:29.806+0000] {processor.py:186} INFO - Started process (PID=233) to work on /opt/airflow/dags/dag.py
[2025-04-05T23:19:29.808+0000] {processor.py:914} INFO - Processing file /opt/airflow/dags/dag.py for tasks to queue
[2025-04-05T23:19:29.811+0000] {logging_mixin.py:190} INFO - [2025-04-05T23:19:29.810+0000] {dagbag.py:588} INFO - Filling up the DagBag from /opt/airflow/dags/dag.py
[2025-04-05T23:19:29.820+0000] {logging_mixin.py:190} INFO - [2025-04-05T23:19:29.818+0000] {dagbag.py:387} ERROR - Failed to import: /opt/airflow/dags/dag.py
Traceback (most recent call last):
  File "/home/airflow/.local/lib/python3.12/site-packages/airflow/models/dagbag.py", line 383, in parse
    loader.exec_module(new_module)
  File "<frozen importlib._bootstrap_external>", line 999, in exec_module
  File "<frozen importlib._bootstrap>", line 488, in _call_with_frames_removed
  File "/opt/airflow/dags/dag.py", line 8, in <module>
    from tqdm import tqdm
ModuleNotFoundError: No module named 'tqdm'
[2025-04-05T23:19:29.821+0000] {processor.py:927} WARNING - No viable dags retrieved from /opt/airflow/dags/dag.py
[2025-04-05T23:19:29.843+0000] {processor.py:208} INFO - Processing /opt/airflow/dags/dag.py took 0.046 seconds
[2025-04-05T23:20:00.017+0000] {processor.py:186} INFO - Started process (PID=297) to work on /opt/airflow/dags/dag.py
[2025-04-05T23:20:00.022+0000] {processor.py:914} INFO - Processing file /opt/airflow/dags/dag.py for tasks to queue
[2025-04-05T23:20:00.032+0000] {logging_mixin.py:190} INFO - [2025-04-05T23:20:00.031+0000] {dagbag.py:588} INFO - Filling up the DagBag from /opt/airflow/dags/dag.py
[2025-04-05T23:20:00.045+0000] {logging_mixin.py:190} INFO - [2025-04-05T23:20:00.044+0000] {dagbag.py:387} ERROR - Failed to import: /opt/airflow/dags/dag.py
Traceback (most recent call last):
  File "/home/airflow/.local/lib/python3.12/site-packages/airflow/models/dagbag.py", line 383, in parse
    loader.exec_module(new_module)
  File "<frozen importlib._bootstrap_external>", line 999, in exec_module
  File "<frozen importlib._bootstrap>", line 488, in _call_with_frames_removed
  File "/opt/airflow/dags/dag.py", line 8, in <module>
    from tqdm import tqdm
ModuleNotFoundError: No module named 'tqdm'
[2025-04-05T23:20:00.047+0000] {processor.py:927} WARNING - No viable dags retrieved from /opt/airflow/dags/dag.py
[2025-04-05T23:20:00.070+0000] {processor.py:208} INFO - Processing /opt/airflow/dags/dag.py took 0.067 seconds
[2025-04-05T23:20:30.309+0000] {processor.py:186} INFO - Started process (PID=361) to work on /opt/airflow/dags/dag.py
[2025-04-05T23:20:30.312+0000] {processor.py:914} INFO - Processing file /opt/airflow/dags/dag.py for tasks to queue
[2025-04-05T23:20:30.316+0000] {logging_mixin.py:190} INFO - [2025-04-05T23:20:30.316+0000] {dagbag.py:588} INFO - Filling up the DagBag from /opt/airflow/dags/dag.py
[2025-04-05T23:20:30.330+0000] {logging_mixin.py:190} INFO - [2025-04-05T23:20:30.326+0000] {dagbag.py:387} ERROR - Failed to import: /opt/airflow/dags/dag.py
Traceback (most recent call last):
  File "/home/airflow/.local/lib/python3.12/site-packages/airflow/models/dagbag.py", line 383, in parse
    loader.exec_module(new_module)
  File "<frozen importlib._bootstrap_external>", line 999, in exec_module
  File "<frozen importlib._bootstrap>", line 488, in _call_with_frames_removed
  File "/opt/airflow/dags/dag.py", line 8, in <module>
    from tqdm import tqdm
ModuleNotFoundError: No module named 'tqdm'
[2025-04-05T23:20:30.330+0000] {processor.py:927} WARNING - No viable dags retrieved from /opt/airflow/dags/dag.py
[2025-04-05T23:20:30.353+0000] {processor.py:208} INFO - Processing /opt/airflow/dags/dag.py took 0.055 seconds
[2025-04-05T23:21:00.517+0000] {processor.py:186} INFO - Started process (PID=425) to work on /opt/airflow/dags/dag.py
[2025-04-05T23:21:00.522+0000] {processor.py:914} INFO - Processing file /opt/airflow/dags/dag.py for tasks to queue
[2025-04-05T23:21:00.528+0000] {logging_mixin.py:190} INFO - [2025-04-05T23:21:00.527+0000] {dagbag.py:588} INFO - Filling up the DagBag from /opt/airflow/dags/dag.py
[2025-04-05T23:21:00.544+0000] {logging_mixin.py:190} INFO - [2025-04-05T23:21:00.541+0000] {dagbag.py:387} ERROR - Failed to import: /opt/airflow/dags/dag.py
Traceback (most recent call last):
  File "/home/airflow/.local/lib/python3.12/site-packages/airflow/models/dagbag.py", line 383, in parse
    loader.exec_module(new_module)
  File "<frozen importlib._bootstrap_external>", line 999, in exec_module
  File "<frozen importlib._bootstrap>", line 488, in _call_with_frames_removed
  File "/opt/airflow/dags/dag.py", line 8, in <module>
    from tqdm import tqdm
ModuleNotFoundError: No module named 'tqdm'
[2025-04-05T23:21:00.545+0000] {processor.py:927} WARNING - No viable dags retrieved from /opt/airflow/dags/dag.py
[2025-04-05T23:21:00.574+0000] {processor.py:208} INFO - Processing /opt/airflow/dags/dag.py took 0.071 seconds
[2025-04-05T23:21:30.907+0000] {processor.py:186} INFO - Started process (PID=489) to work on /opt/airflow/dags/dag.py
[2025-04-05T23:21:30.908+0000] {processor.py:914} INFO - Processing file /opt/airflow/dags/dag.py for tasks to queue
[2025-04-05T23:21:30.915+0000] {logging_mixin.py:190} INFO - [2025-04-05T23:21:30.913+0000] {dagbag.py:588} INFO - Filling up the DagBag from /opt/airflow/dags/dag.py
[2025-04-05T23:21:30.932+0000] {logging_mixin.py:190} INFO - [2025-04-05T23:21:30.931+0000] {dagbag.py:387} ERROR - Failed to import: /opt/airflow/dags/dag.py
Traceback (most recent call last):
  File "/home/airflow/.local/lib/python3.12/site-packages/airflow/models/dagbag.py", line 383, in parse
    loader.exec_module(new_module)
  File "<frozen importlib._bootstrap_external>", line 999, in exec_module
  File "<frozen importlib._bootstrap>", line 488, in _call_with_frames_removed
  File "/opt/airflow/dags/dag.py", line 8, in <module>
    from tqdm import tqdm
ModuleNotFoundError: No module named 'tqdm'
[2025-04-05T23:21:30.933+0000] {processor.py:927} WARNING - No viable dags retrieved from /opt/airflow/dags/dag.py
[2025-04-05T23:21:30.960+0000] {processor.py:208} INFO - Processing /opt/airflow/dags/dag.py took 0.068 seconds
[2025-04-05T23:22:01.143+0000] {processor.py:186} INFO - Started process (PID=553) to work on /opt/airflow/dags/dag.py
[2025-04-05T23:22:01.144+0000] {processor.py:914} INFO - Processing file /opt/airflow/dags/dag.py for tasks to queue
[2025-04-05T23:22:01.149+0000] {logging_mixin.py:190} INFO - [2025-04-05T23:22:01.149+0000] {dagbag.py:588} INFO - Filling up the DagBag from /opt/airflow/dags/dag.py
[2025-04-05T23:22:01.160+0000] {logging_mixin.py:190} INFO - [2025-04-05T23:22:01.158+0000] {dagbag.py:387} ERROR - Failed to import: /opt/airflow/dags/dag.py
Traceback (most recent call last):
  File "/home/airflow/.local/lib/python3.12/site-packages/airflow/models/dagbag.py", line 383, in parse
    loader.exec_module(new_module)
  File "<frozen importlib._bootstrap_external>", line 999, in exec_module
  File "<frozen importlib._bootstrap>", line 488, in _call_with_frames_removed
  File "/opt/airflow/dags/dag.py", line 8, in <module>
    from tqdm import tqdm
ModuleNotFoundError: No module named 'tqdm'
[2025-04-05T23:22:01.160+0000] {processor.py:927} WARNING - No viable dags retrieved from /opt/airflow/dags/dag.py
[2025-04-05T23:22:01.187+0000] {processor.py:208} INFO - Processing /opt/airflow/dags/dag.py took 0.058 seconds
[2025-04-05T23:22:31.326+0000] {processor.py:186} INFO - Started process (PID=617) to work on /opt/airflow/dags/dag.py
[2025-04-05T23:22:31.329+0000] {processor.py:914} INFO - Processing file /opt/airflow/dags/dag.py for tasks to queue
[2025-04-05T23:22:31.333+0000] {logging_mixin.py:190} INFO - [2025-04-05T23:22:31.333+0000] {dagbag.py:588} INFO - Filling up the DagBag from /opt/airflow/dags/dag.py
[2025-04-05T23:22:31.344+0000] {logging_mixin.py:190} INFO - [2025-04-05T23:22:31.344+0000] {dagbag.py:387} ERROR - Failed to import: /opt/airflow/dags/dag.py
Traceback (most recent call last):
  File "/home/airflow/.local/lib/python3.12/site-packages/airflow/models/dagbag.py", line 383, in parse
    loader.exec_module(new_module)
  File "<frozen importlib._bootstrap_external>", line 999, in exec_module
  File "<frozen importlib._bootstrap>", line 488, in _call_with_frames_removed
  File "/opt/airflow/dags/dag.py", line 8, in <module>
    from tqdm import tqdm
ModuleNotFoundError: No module named 'tqdm'
[2025-04-05T23:22:31.345+0000] {processor.py:927} WARNING - No viable dags retrieved from /opt/airflow/dags/dag.py
[2025-04-05T23:22:31.361+0000] {processor.py:208} INFO - Processing /opt/airflow/dags/dag.py took 0.040 seconds
[2025-04-05T23:23:01.591+0000] {processor.py:186} INFO - Started process (PID=681) to work on /opt/airflow/dags/dag.py
[2025-04-05T23:23:01.593+0000] {processor.py:914} INFO - Processing file /opt/airflow/dags/dag.py for tasks to queue
[2025-04-05T23:23:01.595+0000] {logging_mixin.py:190} INFO - [2025-04-05T23:23:01.595+0000] {dagbag.py:588} INFO - Filling up the DagBag from /opt/airflow/dags/dag.py
[2025-04-05T23:23:01.613+0000] {logging_mixin.py:190} INFO - [2025-04-05T23:23:01.610+0000] {dagbag.py:387} ERROR - Failed to import: /opt/airflow/dags/dag.py
Traceback (most recent call last):
  File "/home/airflow/.local/lib/python3.12/site-packages/airflow/models/dagbag.py", line 383, in parse
    loader.exec_module(new_module)
  File "<frozen importlib._bootstrap_external>", line 999, in exec_module
  File "<frozen importlib._bootstrap>", line 488, in _call_with_frames_removed
  File "/opt/airflow/dags/dag.py", line 8, in <module>
    from tqdm import tqdm
ModuleNotFoundError: No module named 'tqdm'
[2025-04-05T23:23:01.613+0000] {processor.py:927} WARNING - No viable dags retrieved from /opt/airflow/dags/dag.py
[2025-04-05T23:23:01.633+0000] {processor.py:208} INFO - Processing /opt/airflow/dags/dag.py took 0.053 seconds
[2025-04-05T23:23:31.807+0000] {processor.py:186} INFO - Started process (PID=745) to work on /opt/airflow/dags/dag.py
[2025-04-05T23:23:31.808+0000] {processor.py:914} INFO - Processing file /opt/airflow/dags/dag.py for tasks to queue
[2025-04-05T23:23:31.813+0000] {logging_mixin.py:190} INFO - [2025-04-05T23:23:31.813+0000] {dagbag.py:588} INFO - Filling up the DagBag from /opt/airflow/dags/dag.py
[2025-04-05T23:23:31.823+0000] {logging_mixin.py:190} INFO - [2025-04-05T23:23:31.821+0000] {dagbag.py:387} ERROR - Failed to import: /opt/airflow/dags/dag.py
Traceback (most recent call last):
  File "/home/airflow/.local/lib/python3.12/site-packages/airflow/models/dagbag.py", line 383, in parse
    loader.exec_module(new_module)
  File "<frozen importlib._bootstrap_external>", line 999, in exec_module
  File "<frozen importlib._bootstrap>", line 488, in _call_with_frames_removed
  File "/opt/airflow/dags/dag.py", line 8, in <module>
    from tqdm import tqdm
ModuleNotFoundError: No module named 'tqdm'
[2025-04-05T23:23:31.824+0000] {processor.py:927} WARNING - No viable dags retrieved from /opt/airflow/dags/dag.py
[2025-04-05T23:23:31.857+0000] {processor.py:208} INFO - Processing /opt/airflow/dags/dag.py took 0.073 seconds
[2025-04-05T23:24:02.030+0000] {processor.py:186} INFO - Started process (PID=809) to work on /opt/airflow/dags/dag.py
[2025-04-05T23:24:02.033+0000] {processor.py:914} INFO - Processing file /opt/airflow/dags/dag.py for tasks to queue
[2025-04-05T23:24:02.037+0000] {logging_mixin.py:190} INFO - [2025-04-05T23:24:02.037+0000] {dagbag.py:588} INFO - Filling up the DagBag from /opt/airflow/dags/dag.py
[2025-04-05T23:24:02.043+0000] {logging_mixin.py:190} INFO - [2025-04-05T23:24:02.042+0000] {dagbag.py:387} ERROR - Failed to import: /opt/airflow/dags/dag.py
Traceback (most recent call last):
  File "/home/airflow/.local/lib/python3.12/site-packages/airflow/models/dagbag.py", line 383, in parse
    loader.exec_module(new_module)
  File "<frozen importlib._bootstrap_external>", line 999, in exec_module
  File "<frozen importlib._bootstrap>", line 488, in _call_with_frames_removed
  File "/opt/airflow/dags/dag.py", line 8, in <module>
    from tqdm import tqdm
ModuleNotFoundError: No module named 'tqdm'
[2025-04-05T23:24:02.043+0000] {processor.py:927} WARNING - No viable dags retrieved from /opt/airflow/dags/dag.py
[2025-04-05T23:24:02.061+0000] {processor.py:208} INFO - Processing /opt/airflow/dags/dag.py took 0.038 seconds
[2025-04-05T23:24:28.434+0000] {processor.py:186} INFO - Started process (PID=40) to work on /opt/airflow/dags/dag.py
[2025-04-05T23:24:28.437+0000] {processor.py:914} INFO - Processing file /opt/airflow/dags/dag.py for tasks to queue
[2025-04-05T23:24:28.439+0000] {logging_mixin.py:190} INFO - [2025-04-05T23:24:28.439+0000] {dagbag.py:588} INFO - Filling up the DagBag from /opt/airflow/dags/dag.py
[2025-04-05T23:24:28.447+0000] {logging_mixin.py:190} INFO - [2025-04-05T23:24:28.445+0000] {dagbag.py:387} ERROR - Failed to import: /opt/airflow/dags/dag.py
Traceback (most recent call last):
  File "/home/airflow/.local/lib/python3.12/site-packages/airflow/models/dagbag.py", line 383, in parse
    loader.exec_module(new_module)
  File "<frozen importlib._bootstrap_external>", line 999, in exec_module
  File "<frozen importlib._bootstrap>", line 488, in _call_with_frames_removed
  File "/opt/airflow/dags/dag.py", line 8, in <module>
    from tqdm import tqdm
ModuleNotFoundError: No module named 'tqdm'
[2025-04-05T23:24:28.448+0000] {processor.py:927} WARNING - No viable dags retrieved from /opt/airflow/dags/dag.py
[2025-04-05T23:24:28.479+0000] {processor.py:208} INFO - Processing /opt/airflow/dags/dag.py took 0.051 seconds
[2025-04-05T23:24:58.540+0000] {processor.py:186} INFO - Started process (PID=104) to work on /opt/airflow/dags/dag.py
[2025-04-05T23:24:58.542+0000] {processor.py:914} INFO - Processing file /opt/airflow/dags/dag.py for tasks to queue
[2025-04-05T23:24:58.544+0000] {logging_mixin.py:190} INFO - [2025-04-05T23:24:58.544+0000] {dagbag.py:588} INFO - Filling up the DagBag from /opt/airflow/dags/dag.py
[2025-04-05T23:24:58.549+0000] {logging_mixin.py:190} INFO - [2025-04-05T23:24:58.548+0000] {dagbag.py:387} ERROR - Failed to import: /opt/airflow/dags/dag.py
Traceback (most recent call last):
  File "/home/airflow/.local/lib/python3.12/site-packages/airflow/models/dagbag.py", line 383, in parse
    loader.exec_module(new_module)
  File "<frozen importlib._bootstrap_external>", line 999, in exec_module
  File "<frozen importlib._bootstrap>", line 488, in _call_with_frames_removed
  File "/opt/airflow/dags/dag.py", line 8, in <module>
    from tqdm import tqdm
ModuleNotFoundError: No module named 'tqdm'
[2025-04-05T23:24:58.549+0000] {processor.py:927} WARNING - No viable dags retrieved from /opt/airflow/dags/dag.py
[2025-04-05T23:24:58.565+0000] {processor.py:208} INFO - Processing /opt/airflow/dags/dag.py took 0.032 seconds
[2025-04-05T23:25:28.783+0000] {processor.py:186} INFO - Started process (PID=168) to work on /opt/airflow/dags/dag.py
[2025-04-05T23:25:28.785+0000] {processor.py:914} INFO - Processing file /opt/airflow/dags/dag.py for tasks to queue
[2025-04-05T23:25:28.796+0000] {logging_mixin.py:190} INFO - [2025-04-05T23:25:28.795+0000] {dagbag.py:588} INFO - Filling up the DagBag from /opt/airflow/dags/dag.py
[2025-04-05T23:25:28.805+0000] {logging_mixin.py:190} INFO - [2025-04-05T23:25:28.803+0000] {dagbag.py:387} ERROR - Failed to import: /opt/airflow/dags/dag.py
Traceback (most recent call last):
  File "/home/airflow/.local/lib/python3.12/site-packages/airflow/models/dagbag.py", line 383, in parse
    loader.exec_module(new_module)
  File "<frozen importlib._bootstrap_external>", line 999, in exec_module
  File "<frozen importlib._bootstrap>", line 488, in _call_with_frames_removed
  File "/opt/airflow/dags/dag.py", line 8, in <module>
    from tqdm import tqdm
ModuleNotFoundError: No module named 'tqdm'
[2025-04-05T23:25:28.806+0000] {processor.py:927} WARNING - No viable dags retrieved from /opt/airflow/dags/dag.py
[2025-04-05T23:25:28.828+0000] {processor.py:208} INFO - Processing /opt/airflow/dags/dag.py took 0.057 seconds
[2025-04-05T23:25:59.104+0000] {processor.py:186} INFO - Started process (PID=232) to work on /opt/airflow/dags/dag.py
[2025-04-05T23:25:59.106+0000] {processor.py:914} INFO - Processing file /opt/airflow/dags/dag.py for tasks to queue
[2025-04-05T23:25:59.112+0000] {logging_mixin.py:190} INFO - [2025-04-05T23:25:59.112+0000] {dagbag.py:588} INFO - Filling up the DagBag from /opt/airflow/dags/dag.py
[2025-04-05T23:25:59.119+0000] {logging_mixin.py:190} INFO - [2025-04-05T23:25:59.118+0000] {dagbag.py:387} ERROR - Failed to import: /opt/airflow/dags/dag.py
Traceback (most recent call last):
  File "/home/airflow/.local/lib/python3.12/site-packages/airflow/models/dagbag.py", line 383, in parse
    loader.exec_module(new_module)
  File "<frozen importlib._bootstrap_external>", line 999, in exec_module
  File "<frozen importlib._bootstrap>", line 488, in _call_with_frames_removed
  File "/opt/airflow/dags/dag.py", line 8, in <module>
    from tqdm import tqdm
ModuleNotFoundError: No module named 'tqdm'
[2025-04-05T23:25:59.120+0000] {processor.py:927} WARNING - No viable dags retrieved from /opt/airflow/dags/dag.py
[2025-04-05T23:25:59.144+0000] {processor.py:208} INFO - Processing /opt/airflow/dags/dag.py took 0.049 seconds
[2025-04-05T23:26:29.438+0000] {processor.py:186} INFO - Started process (PID=296) to work on /opt/airflow/dags/dag.py
[2025-04-05T23:26:29.439+0000] {processor.py:914} INFO - Processing file /opt/airflow/dags/dag.py for tasks to queue
[2025-04-05T23:26:29.443+0000] {logging_mixin.py:190} INFO - [2025-04-05T23:26:29.442+0000] {dagbag.py:588} INFO - Filling up the DagBag from /opt/airflow/dags/dag.py
[2025-04-05T23:26:29.448+0000] {logging_mixin.py:190} INFO - [2025-04-05T23:26:29.447+0000] {dagbag.py:387} ERROR - Failed to import: /opt/airflow/dags/dag.py
Traceback (most recent call last):
  File "/home/airflow/.local/lib/python3.12/site-packages/airflow/models/dagbag.py", line 383, in parse
    loader.exec_module(new_module)
  File "<frozen importlib._bootstrap_external>", line 999, in exec_module
  File "<frozen importlib._bootstrap>", line 488, in _call_with_frames_removed
  File "/opt/airflow/dags/dag.py", line 8, in <module>
    from tqdm import tqdm
ModuleNotFoundError: No module named 'tqdm'
[2025-04-05T23:26:29.449+0000] {processor.py:927} WARNING - No viable dags retrieved from /opt/airflow/dags/dag.py
[2025-04-05T23:26:29.466+0000] {processor.py:208} INFO - Processing /opt/airflow/dags/dag.py took 0.038 seconds
[2025-04-05T23:26:59.608+0000] {processor.py:186} INFO - Started process (PID=360) to work on /opt/airflow/dags/dag.py
[2025-04-05T23:26:59.610+0000] {processor.py:914} INFO - Processing file /opt/airflow/dags/dag.py for tasks to queue
[2025-04-05T23:26:59.612+0000] {logging_mixin.py:190} INFO - [2025-04-05T23:26:59.612+0000] {dagbag.py:588} INFO - Filling up the DagBag from /opt/airflow/dags/dag.py
[2025-04-05T23:26:59.616+0000] {logging_mixin.py:190} INFO - [2025-04-05T23:26:59.615+0000] {dagbag.py:387} ERROR - Failed to import: /opt/airflow/dags/dag.py
Traceback (most recent call last):
  File "/home/airflow/.local/lib/python3.12/site-packages/airflow/models/dagbag.py", line 383, in parse
    loader.exec_module(new_module)
  File "<frozen importlib._bootstrap_external>", line 999, in exec_module
  File "<frozen importlib._bootstrap>", line 488, in _call_with_frames_removed
  File "/opt/airflow/dags/dag.py", line 8, in <module>
    from tqdm import tqdm
ModuleNotFoundError: No module named 'tqdm'
[2025-04-05T23:26:59.616+0000] {processor.py:927} WARNING - No viable dags retrieved from /opt/airflow/dags/dag.py
[2025-04-05T23:26:59.628+0000] {processor.py:208} INFO - Processing /opt/airflow/dags/dag.py took 0.025 seconds
[2025-04-05T23:27:29.793+0000] {processor.py:186} INFO - Started process (PID=424) to work on /opt/airflow/dags/dag.py
[2025-04-05T23:27:29.794+0000] {processor.py:914} INFO - Processing file /opt/airflow/dags/dag.py for tasks to queue
[2025-04-05T23:27:29.797+0000] {logging_mixin.py:190} INFO - [2025-04-05T23:27:29.797+0000] {dagbag.py:588} INFO - Filling up the DagBag from /opt/airflow/dags/dag.py
[2025-04-05T23:27:29.803+0000] {logging_mixin.py:190} INFO - [2025-04-05T23:27:29.802+0000] {dagbag.py:387} ERROR - Failed to import: /opt/airflow/dags/dag.py
Traceback (most recent call last):
  File "/home/airflow/.local/lib/python3.12/site-packages/airflow/models/dagbag.py", line 383, in parse
    loader.exec_module(new_module)
  File "<frozen importlib._bootstrap_external>", line 999, in exec_module
  File "<frozen importlib._bootstrap>", line 488, in _call_with_frames_removed
  File "/opt/airflow/dags/dag.py", line 8, in <module>
    from tqdm import tqdm
ModuleNotFoundError: No module named 'tqdm'
[2025-04-05T23:27:29.803+0000] {processor.py:927} WARNING - No viable dags retrieved from /opt/airflow/dags/dag.py
[2025-04-05T23:27:29.832+0000] {processor.py:208} INFO - Processing /opt/airflow/dags/dag.py took 0.052 seconds
[2025-04-05T23:28:00.108+0000] {processor.py:186} INFO - Started process (PID=488) to work on /opt/airflow/dags/dag.py
[2025-04-05T23:28:00.111+0000] {processor.py:914} INFO - Processing file /opt/airflow/dags/dag.py for tasks to queue
[2025-04-05T23:28:00.118+0000] {logging_mixin.py:190} INFO - [2025-04-05T23:28:00.117+0000] {dagbag.py:588} INFO - Filling up the DagBag from /opt/airflow/dags/dag.py
[2025-04-05T23:28:00.126+0000] {logging_mixin.py:190} INFO - [2025-04-05T23:28:00.125+0000] {dagbag.py:387} ERROR - Failed to import: /opt/airflow/dags/dag.py
Traceback (most recent call last):
  File "/home/airflow/.local/lib/python3.12/site-packages/airflow/models/dagbag.py", line 383, in parse
    loader.exec_module(new_module)
  File "<frozen importlib._bootstrap_external>", line 999, in exec_module
  File "<frozen importlib._bootstrap>", line 488, in _call_with_frames_removed
  File "/opt/airflow/dags/dag.py", line 8, in <module>
    from tqdm import tqdm
ModuleNotFoundError: No module named 'tqdm'
[2025-04-05T23:28:00.127+0000] {processor.py:927} WARNING - No viable dags retrieved from /opt/airflow/dags/dag.py
[2025-04-05T23:28:00.145+0000] {processor.py:208} INFO - Processing /opt/airflow/dags/dag.py took 0.048 seconds
[2025-04-05T23:28:30.380+0000] {processor.py:186} INFO - Started process (PID=552) to work on /opt/airflow/dags/dag.py
[2025-04-05T23:28:30.381+0000] {processor.py:914} INFO - Processing file /opt/airflow/dags/dag.py for tasks to queue
[2025-04-05T23:28:30.383+0000] {logging_mixin.py:190} INFO - [2025-04-05T23:28:30.383+0000] {dagbag.py:588} INFO - Filling up the DagBag from /opt/airflow/dags/dag.py
[2025-04-05T23:28:30.388+0000] {logging_mixin.py:190} INFO - [2025-04-05T23:28:30.387+0000] {dagbag.py:387} ERROR - Failed to import: /opt/airflow/dags/dag.py
Traceback (most recent call last):
  File "/home/airflow/.local/lib/python3.12/site-packages/airflow/models/dagbag.py", line 383, in parse
    loader.exec_module(new_module)
  File "<frozen importlib._bootstrap_external>", line 999, in exec_module
  File "<frozen importlib._bootstrap>", line 488, in _call_with_frames_removed
  File "/opt/airflow/dags/dag.py", line 8, in <module>
    from tqdm import tqdm
ModuleNotFoundError: No module named 'tqdm'
[2025-04-05T23:28:30.388+0000] {processor.py:927} WARNING - No viable dags retrieved from /opt/airflow/dags/dag.py
[2025-04-05T23:28:30.400+0000] {processor.py:208} INFO - Processing /opt/airflow/dags/dag.py took 0.028 seconds
[2025-04-05T23:29:00.500+0000] {processor.py:186} INFO - Started process (PID=616) to work on /opt/airflow/dags/dag.py
[2025-04-05T23:29:00.502+0000] {processor.py:914} INFO - Processing file /opt/airflow/dags/dag.py for tasks to queue
[2025-04-05T23:29:00.504+0000] {logging_mixin.py:190} INFO - [2025-04-05T23:29:00.504+0000] {dagbag.py:588} INFO - Filling up the DagBag from /opt/airflow/dags/dag.py
[2025-04-05T23:29:00.509+0000] {logging_mixin.py:190} INFO - [2025-04-05T23:29:00.508+0000] {dagbag.py:387} ERROR - Failed to import: /opt/airflow/dags/dag.py
Traceback (most recent call last):
  File "/home/airflow/.local/lib/python3.12/site-packages/airflow/models/dagbag.py", line 383, in parse
    loader.exec_module(new_module)
  File "<frozen importlib._bootstrap_external>", line 999, in exec_module
  File "<frozen importlib._bootstrap>", line 488, in _call_with_frames_removed
  File "/opt/airflow/dags/dag.py", line 8, in <module>
    from tqdm import tqdm
ModuleNotFoundError: No module named 'tqdm'
[2025-04-05T23:29:00.509+0000] {processor.py:927} WARNING - No viable dags retrieved from /opt/airflow/dags/dag.py
[2025-04-05T23:29:00.522+0000] {processor.py:208} INFO - Processing /opt/airflow/dags/dag.py took 0.026 seconds
[2025-04-05T23:29:31.003+0000] {processor.py:186} INFO - Started process (PID=680) to work on /opt/airflow/dags/dag.py
[2025-04-05T23:29:31.005+0000] {processor.py:914} INFO - Processing file /opt/airflow/dags/dag.py for tasks to queue
[2025-04-05T23:29:31.012+0000] {logging_mixin.py:190} INFO - [2025-04-05T23:29:31.012+0000] {dagbag.py:588} INFO - Filling up the DagBag from /opt/airflow/dags/dag.py
[2025-04-05T23:29:31.040+0000] {logging_mixin.py:190} INFO - [2025-04-05T23:29:31.039+0000] {dagbag.py:387} ERROR - Failed to import: /opt/airflow/dags/dag.py
Traceback (most recent call last):
  File "/home/airflow/.local/lib/python3.12/site-packages/airflow/models/dagbag.py", line 383, in parse
    loader.exec_module(new_module)
  File "<frozen importlib._bootstrap_external>", line 999, in exec_module
  File "<frozen importlib._bootstrap>", line 488, in _call_with_frames_removed
  File "/opt/airflow/dags/dag.py", line 8, in <module>
    from tqdm import tqdm
ModuleNotFoundError: No module named 'tqdm'
[2025-04-05T23:29:31.041+0000] {processor.py:927} WARNING - No viable dags retrieved from /opt/airflow/dags/dag.py
[2025-04-05T23:29:31.064+0000] {processor.py:208} INFO - Processing /opt/airflow/dags/dag.py took 0.078 seconds
[2025-04-05T23:30:01.217+0000] {processor.py:186} INFO - Started process (PID=743) to work on /opt/airflow/dags/dag.py
[2025-04-05T23:30:01.217+0000] {processor.py:914} INFO - Processing file /opt/airflow/dags/dag.py for tasks to queue
[2025-04-05T23:30:01.219+0000] {logging_mixin.py:190} INFO - [2025-04-05T23:30:01.219+0000] {dagbag.py:588} INFO - Filling up the DagBag from /opt/airflow/dags/dag.py
[2025-04-05T23:30:01.222+0000] {logging_mixin.py:190} INFO - [2025-04-05T23:30:01.222+0000] {dagbag.py:387} ERROR - Failed to import: /opt/airflow/dags/dag.py
Traceback (most recent call last):
  File "/home/airflow/.local/lib/python3.12/site-packages/airflow/models/dagbag.py", line 383, in parse
    loader.exec_module(new_module)
  File "<frozen importlib._bootstrap_external>", line 999, in exec_module
  File "<frozen importlib._bootstrap>", line 488, in _call_with_frames_removed
  File "/opt/airflow/dags/dag.py", line 8, in <module>
    from tqdm import tqdm
ModuleNotFoundError: No module named 'tqdm'
[2025-04-05T23:30:01.223+0000] {processor.py:927} WARNING - No viable dags retrieved from /opt/airflow/dags/dag.py
[2025-04-05T23:30:01.234+0000] {processor.py:208} INFO - Processing /opt/airflow/dags/dag.py took 0.021 seconds
[2025-04-05T23:30:31.369+0000] {processor.py:186} INFO - Started process (PID=807) to work on /opt/airflow/dags/dag.py
[2025-04-05T23:30:31.370+0000] {processor.py:914} INFO - Processing file /opt/airflow/dags/dag.py for tasks to queue
[2025-04-05T23:30:31.374+0000] {logging_mixin.py:190} INFO - [2025-04-05T23:30:31.374+0000] {dagbag.py:588} INFO - Filling up the DagBag from /opt/airflow/dags/dag.py
[2025-04-05T23:30:31.381+0000] {logging_mixin.py:190} INFO - [2025-04-05T23:30:31.380+0000] {dagbag.py:387} ERROR - Failed to import: /opt/airflow/dags/dag.py
Traceback (most recent call last):
  File "/home/airflow/.local/lib/python3.12/site-packages/airflow/models/dagbag.py", line 383, in parse
    loader.exec_module(new_module)
  File "<frozen importlib._bootstrap_external>", line 999, in exec_module
  File "<frozen importlib._bootstrap>", line 488, in _call_with_frames_removed
  File "/opt/airflow/dags/dag.py", line 8, in <module>
    from tqdm import tqdm
ModuleNotFoundError: No module named 'tqdm'
[2025-04-05T23:30:31.382+0000] {processor.py:927} WARNING - No viable dags retrieved from /opt/airflow/dags/dag.py
[2025-04-05T23:30:31.399+0000] {processor.py:208} INFO - Processing /opt/airflow/dags/dag.py took 0.043 seconds
[2025-04-05T23:31:01.656+0000] {processor.py:186} INFO - Started process (PID=871) to work on /opt/airflow/dags/dag.py
[2025-04-05T23:31:01.657+0000] {processor.py:914} INFO - Processing file /opt/airflow/dags/dag.py for tasks to queue
[2025-04-05T23:31:01.661+0000] {logging_mixin.py:190} INFO - [2025-04-05T23:31:01.661+0000] {dagbag.py:588} INFO - Filling up the DagBag from /opt/airflow/dags/dag.py
[2025-04-05T23:31:01.673+0000] {logging_mixin.py:190} INFO - [2025-04-05T23:31:01.671+0000] {dagbag.py:387} ERROR - Failed to import: /opt/airflow/dags/dag.py
Traceback (most recent call last):
  File "/home/airflow/.local/lib/python3.12/site-packages/airflow/models/dagbag.py", line 383, in parse
    loader.exec_module(new_module)
  File "<frozen importlib._bootstrap_external>", line 999, in exec_module
  File "<frozen importlib._bootstrap>", line 488, in _call_with_frames_removed
  File "/opt/airflow/dags/dag.py", line 8, in <module>
    from tqdm import tqdm
ModuleNotFoundError: No module named 'tqdm'
[2025-04-05T23:31:01.673+0000] {processor.py:927} WARNING - No viable dags retrieved from /opt/airflow/dags/dag.py
[2025-04-05T23:31:01.700+0000] {processor.py:208} INFO - Processing /opt/airflow/dags/dag.py took 0.061 seconds
[2025-04-05T23:31:29.804+0000] {processor.py:186} INFO - Started process (PID=935) to work on /opt/airflow/dags/dag.py
[2025-04-05T23:31:29.809+0000] {processor.py:914} INFO - Processing file /opt/airflow/dags/dag.py for tasks to queue
[2025-04-05T23:31:29.814+0000] {logging_mixin.py:190} INFO - [2025-04-05T23:31:29.814+0000] {dagbag.py:588} INFO - Filling up the DagBag from /opt/airflow/dags/dag.py
[2025-04-05T23:31:29.830+0000] {logging_mixin.py:190} INFO - [2025-04-05T23:31:29.823+0000] {dagbag.py:387} ERROR - Failed to import: /opt/airflow/dags/dag.py
Traceback (most recent call last):
  File "/home/airflow/.local/lib/python3.12/site-packages/airflow/models/dagbag.py", line 383, in parse
    loader.exec_module(new_module)
  File "<frozen importlib._bootstrap_external>", line 999, in exec_module
  File "<frozen importlib._bootstrap>", line 488, in _call_with_frames_removed
  File "/opt/airflow/dags/dag.py", line 25, in <module>
    storage_client = storage.Client()
                     ^^^^^^^^^^^^^^^^
  File "/home/airflow/.local/lib/python3.12/site-packages/google/cloud/storage/client.py", line 228, in __init__
    super(Client, self).__init__(
  File "/home/airflow/.local/lib/python3.12/site-packages/google/cloud/client/__init__.py", line 320, in __init__
    _ClientProjectMixin.__init__(self, project=project, credentials=credentials)
  File "/home/airflow/.local/lib/python3.12/site-packages/google/cloud/client/__init__.py", line 268, in __init__
    project = self._determine_default(project)
              ^^^^^^^^^^^^^^^^^^^^^^^^^^^^^^^^
  File "/home/airflow/.local/lib/python3.12/site-packages/google/cloud/client/__init__.py", line 287, in _determine_default
    return _determine_default_project(project)
           ^^^^^^^^^^^^^^^^^^^^^^^^^^^^^^^^^^^
  File "/home/airflow/.local/lib/python3.12/site-packages/google/cloud/_helpers/__init__.py", line 152, in _determine_default_project
    _, project = google.auth.default()
                 ^^^^^^^^^^^^^^^^^^^^^
  File "/home/airflow/.local/lib/python3.12/site-packages/google/auth/_default.py", line 685, in default
    credentials, project_id = checker()
                              ^^^^^^^^^
  File "/home/airflow/.local/lib/python3.12/site-packages/google/auth/_default.py", line 678, in <lambda>
    lambda: _get_explicit_environ_credentials(quota_project_id=quota_project_id),
            ^^^^^^^^^^^^^^^^^^^^^^^^^^^^^^^^^^^^^^^^^^^^^^^^^^^^^^^^^^^^^^^^^^^^
  File "/home/airflow/.local/lib/python3.12/site-packages/google/auth/_default.py", line 293, in _get_explicit_environ_credentials
    credentials, project_id = load_credentials_from_file(
                              ^^^^^^^^^^^^^^^^^^^^^^^^^^^
  File "/home/airflow/.local/lib/python3.12/site-packages/google/auth/_default.py", line 125, in load_credentials_from_file
    raise exceptions.DefaultCredentialsError(
google.auth.exceptions.DefaultCredentialsError: File /Users/nd_blaze/nd_blaze.dev/python_dev/DataEngineering/ZoomCamp/taxi-rides-ny-450705-77964478f823.json was not found.
[2025-04-05T23:31:29.831+0000] {processor.py:927} WARNING - No viable dags retrieved from /opt/airflow/dags/dag.py
[2025-04-05T23:31:29.853+0000] {processor.py:208} INFO - Processing /opt/airflow/dags/dag.py took 0.060 seconds
[2025-04-05T23:32:00.036+0000] {processor.py:186} INFO - Started process (PID=999) to work on /opt/airflow/dags/dag.py
[2025-04-05T23:32:00.039+0000] {processor.py:914} INFO - Processing file /opt/airflow/dags/dag.py for tasks to queue
[2025-04-05T23:32:00.043+0000] {logging_mixin.py:190} INFO - [2025-04-05T23:32:00.042+0000] {dagbag.py:588} INFO - Filling up the DagBag from /opt/airflow/dags/dag.py
[2025-04-05T23:32:00.053+0000] {logging_mixin.py:190} INFO - [2025-04-05T23:32:00.050+0000] {dagbag.py:387} ERROR - Failed to import: /opt/airflow/dags/dag.py
Traceback (most recent call last):
  File "/home/airflow/.local/lib/python3.12/site-packages/airflow/models/dagbag.py", line 383, in parse
    loader.exec_module(new_module)
  File "<frozen importlib._bootstrap_external>", line 999, in exec_module
  File "<frozen importlib._bootstrap>", line 488, in _call_with_frames_removed
  File "/opt/airflow/dags/dag.py", line 25, in <module>
    storage_client = storage.Client()
                     ^^^^^^^^^^^^^^^^
  File "/home/airflow/.local/lib/python3.12/site-packages/google/cloud/storage/client.py", line 228, in __init__
    super(Client, self).__init__(
  File "/home/airflow/.local/lib/python3.12/site-packages/google/cloud/client/__init__.py", line 320, in __init__
    _ClientProjectMixin.__init__(self, project=project, credentials=credentials)
  File "/home/airflow/.local/lib/python3.12/site-packages/google/cloud/client/__init__.py", line 268, in __init__
    project = self._determine_default(project)
              ^^^^^^^^^^^^^^^^^^^^^^^^^^^^^^^^
  File "/home/airflow/.local/lib/python3.12/site-packages/google/cloud/client/__init__.py", line 287, in _determine_default
    return _determine_default_project(project)
           ^^^^^^^^^^^^^^^^^^^^^^^^^^^^^^^^^^^
  File "/home/airflow/.local/lib/python3.12/site-packages/google/cloud/_helpers/__init__.py", line 152, in _determine_default_project
    _, project = google.auth.default()
                 ^^^^^^^^^^^^^^^^^^^^^
  File "/home/airflow/.local/lib/python3.12/site-packages/google/auth/_default.py", line 685, in default
    credentials, project_id = checker()
                              ^^^^^^^^^
  File "/home/airflow/.local/lib/python3.12/site-packages/google/auth/_default.py", line 678, in <lambda>
    lambda: _get_explicit_environ_credentials(quota_project_id=quota_project_id),
            ^^^^^^^^^^^^^^^^^^^^^^^^^^^^^^^^^^^^^^^^^^^^^^^^^^^^^^^^^^^^^^^^^^^^
  File "/home/airflow/.local/lib/python3.12/site-packages/google/auth/_default.py", line 293, in _get_explicit_environ_credentials
    credentials, project_id = load_credentials_from_file(
                              ^^^^^^^^^^^^^^^^^^^^^^^^^^^
  File "/home/airflow/.local/lib/python3.12/site-packages/google/auth/_default.py", line 125, in load_credentials_from_file
    raise exceptions.DefaultCredentialsError(
google.auth.exceptions.DefaultCredentialsError: File /Users/nd_blaze/nd_blaze.dev/python_dev/DataEngineering/ZoomCamp/taxi-rides-ny-450705-77964478f823.json was not found.
[2025-04-05T23:32:00.054+0000] {processor.py:927} WARNING - No viable dags retrieved from /opt/airflow/dags/dag.py
[2025-04-05T23:32:00.072+0000] {processor.py:208} INFO - Processing /opt/airflow/dags/dag.py took 0.052 seconds
[2025-04-05T23:32:10.124+0000] {processor.py:186} INFO - Started process (PID=1063) to work on /opt/airflow/dags/dag.py
[2025-04-05T23:32:10.125+0000] {processor.py:914} INFO - Processing file /opt/airflow/dags/dag.py for tasks to queue
[2025-04-05T23:32:10.127+0000] {logging_mixin.py:190} INFO - [2025-04-05T23:32:10.126+0000] {dagbag.py:588} INFO - Filling up the DagBag from /opt/airflow/dags/dag.py
[2025-04-05T23:32:10.134+0000] {logging_mixin.py:190} INFO - [2025-04-05T23:32:10.132+0000] {dagbag.py:387} ERROR - Failed to import: /opt/airflow/dags/dag.py
Traceback (most recent call last):
  File "/home/airflow/.local/lib/python3.12/site-packages/airflow/models/dagbag.py", line 383, in parse
    loader.exec_module(new_module)
  File "<frozen importlib._bootstrap_external>", line 999, in exec_module
  File "<frozen importlib._bootstrap>", line 488, in _call_with_frames_removed
  File "/opt/airflow/dags/dag.py", line 25, in <module>
    storage_client = storage.Client()
                     ^^^^^^^^^^^^^^^^
  File "/home/airflow/.local/lib/python3.12/site-packages/google/cloud/storage/client.py", line 228, in __init__
    super(Client, self).__init__(
  File "/home/airflow/.local/lib/python3.12/site-packages/google/cloud/client/__init__.py", line 320, in __init__
    _ClientProjectMixin.__init__(self, project=project, credentials=credentials)
  File "/home/airflow/.local/lib/python3.12/site-packages/google/cloud/client/__init__.py", line 268, in __init__
    project = self._determine_default(project)
              ^^^^^^^^^^^^^^^^^^^^^^^^^^^^^^^^
  File "/home/airflow/.local/lib/python3.12/site-packages/google/cloud/client/__init__.py", line 287, in _determine_default
    return _determine_default_project(project)
           ^^^^^^^^^^^^^^^^^^^^^^^^^^^^^^^^^^^
  File "/home/airflow/.local/lib/python3.12/site-packages/google/cloud/_helpers/__init__.py", line 152, in _determine_default_project
    _, project = google.auth.default()
                 ^^^^^^^^^^^^^^^^^^^^^
  File "/home/airflow/.local/lib/python3.12/site-packages/google/auth/_default.py", line 685, in default
    credentials, project_id = checker()
                              ^^^^^^^^^
  File "/home/airflow/.local/lib/python3.12/site-packages/google/auth/_default.py", line 678, in <lambda>
    lambda: _get_explicit_environ_credentials(quota_project_id=quota_project_id),
            ^^^^^^^^^^^^^^^^^^^^^^^^^^^^^^^^^^^^^^^^^^^^^^^^^^^^^^^^^^^^^^^^^^^^
  File "/home/airflow/.local/lib/python3.12/site-packages/google/auth/_default.py", line 293, in _get_explicit_environ_credentials
    credentials, project_id = load_credentials_from_file(
                              ^^^^^^^^^^^^^^^^^^^^^^^^^^^
  File "/home/airflow/.local/lib/python3.12/site-packages/google/auth/_default.py", line 125, in load_credentials_from_file
    raise exceptions.DefaultCredentialsError(
google.auth.exceptions.DefaultCredentialsError: File /Users/nd_blaze/nd_blaze.dev/python_dev/DataEngineering/ZoomCamp/taxi-rides-ny-450705-77964478f823.json was not found.
[2025-04-05T23:32:10.134+0000] {processor.py:927} WARNING - No viable dags retrieved from /opt/airflow/dags/dag.py
[2025-04-05T23:32:10.148+0000] {processor.py:208} INFO - Processing /opt/airflow/dags/dag.py took 0.030 seconds
[2025-04-05T23:32:40.236+0000] {processor.py:186} INFO - Started process (PID=1127) to work on /opt/airflow/dags/dag.py
[2025-04-05T23:32:40.239+0000] {processor.py:914} INFO - Processing file /opt/airflow/dags/dag.py for tasks to queue
[2025-04-05T23:32:40.240+0000] {logging_mixin.py:190} INFO - [2025-04-05T23:32:40.240+0000] {dagbag.py:588} INFO - Filling up the DagBag from /opt/airflow/dags/dag.py
[2025-04-05T23:32:40.245+0000] {logging_mixin.py:190} INFO - [2025-04-05T23:32:40.243+0000] {dagbag.py:387} ERROR - Failed to import: /opt/airflow/dags/dag.py
Traceback (most recent call last):
  File "/home/airflow/.local/lib/python3.12/site-packages/airflow/models/dagbag.py", line 383, in parse
    loader.exec_module(new_module)
  File "<frozen importlib._bootstrap_external>", line 999, in exec_module
  File "<frozen importlib._bootstrap>", line 488, in _call_with_frames_removed
  File "/opt/airflow/dags/dag.py", line 25, in <module>
    storage_client = storage.Client()
                     ^^^^^^^^^^^^^^^^
  File "/home/airflow/.local/lib/python3.12/site-packages/google/cloud/storage/client.py", line 228, in __init__
    super(Client, self).__init__(
  File "/home/airflow/.local/lib/python3.12/site-packages/google/cloud/client/__init__.py", line 320, in __init__
    _ClientProjectMixin.__init__(self, project=project, credentials=credentials)
  File "/home/airflow/.local/lib/python3.12/site-packages/google/cloud/client/__init__.py", line 268, in __init__
    project = self._determine_default(project)
              ^^^^^^^^^^^^^^^^^^^^^^^^^^^^^^^^
  File "/home/airflow/.local/lib/python3.12/site-packages/google/cloud/client/__init__.py", line 287, in _determine_default
    return _determine_default_project(project)
           ^^^^^^^^^^^^^^^^^^^^^^^^^^^^^^^^^^^
  File "/home/airflow/.local/lib/python3.12/site-packages/google/cloud/_helpers/__init__.py", line 152, in _determine_default_project
    _, project = google.auth.default()
                 ^^^^^^^^^^^^^^^^^^^^^
  File "/home/airflow/.local/lib/python3.12/site-packages/google/auth/_default.py", line 685, in default
    credentials, project_id = checker()
                              ^^^^^^^^^
  File "/home/airflow/.local/lib/python3.12/site-packages/google/auth/_default.py", line 678, in <lambda>
    lambda: _get_explicit_environ_credentials(quota_project_id=quota_project_id),
            ^^^^^^^^^^^^^^^^^^^^^^^^^^^^^^^^^^^^^^^^^^^^^^^^^^^^^^^^^^^^^^^^^^^^
  File "/home/airflow/.local/lib/python3.12/site-packages/google/auth/_default.py", line 293, in _get_explicit_environ_credentials
    credentials, project_id = load_credentials_from_file(
                              ^^^^^^^^^^^^^^^^^^^^^^^^^^^
  File "/home/airflow/.local/lib/python3.12/site-packages/google/auth/_default.py", line 125, in load_credentials_from_file
    raise exceptions.DefaultCredentialsError(
google.auth.exceptions.DefaultCredentialsError: File /Users/nd_blaze/nd_blaze.dev/python_dev/DataEngineering/ZoomCamp/taxi-rides-ny-450705-77964478f823.json was not found.
[2025-04-05T23:32:40.245+0000] {processor.py:927} WARNING - No viable dags retrieved from /opt/airflow/dags/dag.py
[2025-04-05T23:32:40.255+0000] {processor.py:208} INFO - Processing /opt/airflow/dags/dag.py took 0.022 seconds
[2025-04-05T23:33:10.347+0000] {processor.py:186} INFO - Started process (PID=1185) to work on /opt/airflow/dags/dag.py
[2025-04-05T23:33:10.348+0000] {processor.py:914} INFO - Processing file /opt/airflow/dags/dag.py for tasks to queue
[2025-04-05T23:33:10.349+0000] {logging_mixin.py:190} INFO - [2025-04-05T23:33:10.349+0000] {dagbag.py:588} INFO - Filling up the DagBag from /opt/airflow/dags/dag.py
[2025-04-05T23:33:10.355+0000] {logging_mixin.py:190} INFO - [2025-04-05T23:33:10.354+0000] {dagbag.py:387} ERROR - Failed to import: /opt/airflow/dags/dag.py
Traceback (most recent call last):
  File "/home/airflow/.local/lib/python3.12/site-packages/airflow/models/dagbag.py", line 383, in parse
    loader.exec_module(new_module)
  File "<frozen importlib._bootstrap_external>", line 999, in exec_module
  File "<frozen importlib._bootstrap>", line 488, in _call_with_frames_removed
  File "/opt/airflow/dags/dag.py", line 25, in <module>
    storage_client = storage.Client()
                     ^^^^^^^^^^^^^^^^
  File "/home/airflow/.local/lib/python3.12/site-packages/google/cloud/storage/client.py", line 228, in __init__
    super(Client, self).__init__(
  File "/home/airflow/.local/lib/python3.12/site-packages/google/cloud/client/__init__.py", line 320, in __init__
    _ClientProjectMixin.__init__(self, project=project, credentials=credentials)
  File "/home/airflow/.local/lib/python3.12/site-packages/google/cloud/client/__init__.py", line 268, in __init__
    project = self._determine_default(project)
              ^^^^^^^^^^^^^^^^^^^^^^^^^^^^^^^^
  File "/home/airflow/.local/lib/python3.12/site-packages/google/cloud/client/__init__.py", line 287, in _determine_default
    return _determine_default_project(project)
           ^^^^^^^^^^^^^^^^^^^^^^^^^^^^^^^^^^^
  File "/home/airflow/.local/lib/python3.12/site-packages/google/cloud/_helpers/__init__.py", line 152, in _determine_default_project
    _, project = google.auth.default()
                 ^^^^^^^^^^^^^^^^^^^^^
  File "/home/airflow/.local/lib/python3.12/site-packages/google/auth/_default.py", line 685, in default
    credentials, project_id = checker()
                              ^^^^^^^^^
  File "/home/airflow/.local/lib/python3.12/site-packages/google/auth/_default.py", line 678, in <lambda>
    lambda: _get_explicit_environ_credentials(quota_project_id=quota_project_id),
            ^^^^^^^^^^^^^^^^^^^^^^^^^^^^^^^^^^^^^^^^^^^^^^^^^^^^^^^^^^^^^^^^^^^^
  File "/home/airflow/.local/lib/python3.12/site-packages/google/auth/_default.py", line 293, in _get_explicit_environ_credentials
    credentials, project_id = load_credentials_from_file(
                              ^^^^^^^^^^^^^^^^^^^^^^^^^^^
  File "/home/airflow/.local/lib/python3.12/site-packages/google/auth/_default.py", line 125, in load_credentials_from_file
    raise exceptions.DefaultCredentialsError(
google.auth.exceptions.DefaultCredentialsError: File /Users/nd_blaze/nd_blaze.dev/python_dev/DataEngineering/ZoomCamp/taxi-rides-ny-450705-77964478f823.json was not found.
[2025-04-05T23:33:10.356+0000] {processor.py:927} WARNING - No viable dags retrieved from /opt/airflow/dags/dag.py
[2025-04-05T23:33:10.368+0000] {processor.py:208} INFO - Processing /opt/airflow/dags/dag.py took 0.024 seconds
[2025-04-05T23:33:40.501+0000] {processor.py:186} INFO - Started process (PID=1246) to work on /opt/airflow/dags/dag.py
[2025-04-05T23:33:40.502+0000] {processor.py:914} INFO - Processing file /opt/airflow/dags/dag.py for tasks to queue
[2025-04-05T23:33:40.503+0000] {logging_mixin.py:190} INFO - [2025-04-05T23:33:40.503+0000] {dagbag.py:588} INFO - Filling up the DagBag from /opt/airflow/dags/dag.py
[2025-04-05T23:33:40.511+0000] {logging_mixin.py:190} INFO - [2025-04-05T23:33:40.509+0000] {dagbag.py:387} ERROR - Failed to import: /opt/airflow/dags/dag.py
Traceback (most recent call last):
  File "/home/airflow/.local/lib/python3.12/site-packages/airflow/models/dagbag.py", line 383, in parse
    loader.exec_module(new_module)
  File "<frozen importlib._bootstrap_external>", line 999, in exec_module
  File "<frozen importlib._bootstrap>", line 488, in _call_with_frames_removed
  File "/opt/airflow/dags/dag.py", line 25, in <module>
    storage_client = storage.Client()
                     ^^^^^^^^^^^^^^^^
  File "/home/airflow/.local/lib/python3.12/site-packages/google/cloud/storage/client.py", line 228, in __init__
    super(Client, self).__init__(
  File "/home/airflow/.local/lib/python3.12/site-packages/google/cloud/client/__init__.py", line 320, in __init__
    _ClientProjectMixin.__init__(self, project=project, credentials=credentials)
  File "/home/airflow/.local/lib/python3.12/site-packages/google/cloud/client/__init__.py", line 268, in __init__
    project = self._determine_default(project)
              ^^^^^^^^^^^^^^^^^^^^^^^^^^^^^^^^
  File "/home/airflow/.local/lib/python3.12/site-packages/google/cloud/client/__init__.py", line 287, in _determine_default
    return _determine_default_project(project)
           ^^^^^^^^^^^^^^^^^^^^^^^^^^^^^^^^^^^
  File "/home/airflow/.local/lib/python3.12/site-packages/google/cloud/_helpers/__init__.py", line 152, in _determine_default_project
    _, project = google.auth.default()
                 ^^^^^^^^^^^^^^^^^^^^^
  File "/home/airflow/.local/lib/python3.12/site-packages/google/auth/_default.py", line 685, in default
    credentials, project_id = checker()
                              ^^^^^^^^^
  File "/home/airflow/.local/lib/python3.12/site-packages/google/auth/_default.py", line 678, in <lambda>
    lambda: _get_explicit_environ_credentials(quota_project_id=quota_project_id),
            ^^^^^^^^^^^^^^^^^^^^^^^^^^^^^^^^^^^^^^^^^^^^^^^^^^^^^^^^^^^^^^^^^^^^
  File "/home/airflow/.local/lib/python3.12/site-packages/google/auth/_default.py", line 293, in _get_explicit_environ_credentials
    credentials, project_id = load_credentials_from_file(
                              ^^^^^^^^^^^^^^^^^^^^^^^^^^^
  File "/home/airflow/.local/lib/python3.12/site-packages/google/auth/_default.py", line 125, in load_credentials_from_file
    raise exceptions.DefaultCredentialsError(
google.auth.exceptions.DefaultCredentialsError: File /Users/nd_blaze/nd_blaze.dev/python_dev/DataEngineering/ZoomCamp/taxi-rides-ny-450705-77964478f823.json was not found.
[2025-04-05T23:33:40.511+0000] {processor.py:927} WARNING - No viable dags retrieved from /opt/airflow/dags/dag.py
[2025-04-05T23:33:40.520+0000] {processor.py:208} INFO - Processing /opt/airflow/dags/dag.py took 0.022 seconds
[2025-04-05T23:34:01.923+0000] {processor.py:186} INFO - Started process (PID=1256) to work on /opt/airflow/dags/dag.py
[2025-04-05T23:34:01.924+0000] {processor.py:914} INFO - Processing file /opt/airflow/dags/dag.py for tasks to queue
[2025-04-05T23:34:01.929+0000] {logging_mixin.py:190} INFO - [2025-04-05T23:34:01.929+0000] {dagbag.py:588} INFO - Filling up the DagBag from /opt/airflow/dags/dag.py
[2025-04-05T23:34:04.952+0000] {logging_mixin.py:190} INFO - [2025-04-05T23:34:04.950+0000] {_metadata.py:142} WARNING - Compute Engine Metadata server unavailable on attempt 1 of 3. Reason: timed out
[2025-04-05T23:34:05.883+0000] {logging_mixin.py:190} INFO - [2025-04-05T23:34:05.882+0000] {_metadata.py:142} WARNING - Compute Engine Metadata server unavailable on attempt 2 of 3. Reason: [Errno 111] Connection refused
[2025-04-05T23:34:07.997+0000] {logging_mixin.py:190} INFO - [2025-04-05T23:34:07.997+0000] {_metadata.py:142} WARNING - Compute Engine Metadata server unavailable on attempt 3 of 3. Reason: [Errno 111] Connection refused
[2025-04-05T23:34:07.998+0000] {logging_mixin.py:190} INFO - [2025-04-05T23:34:07.998+0000] {_default.py:362} WARNING - Authentication failed using Compute Engine authentication due to unavailable metadata server.
[2025-04-05T23:34:08.003+0000] {logging_mixin.py:190} INFO - [2025-04-05T23:34:07.999+0000] {dagbag.py:387} ERROR - Failed to import: /opt/airflow/dags/dag.py
Traceback (most recent call last):
  File "/home/airflow/.local/lib/python3.12/site-packages/airflow/models/dagbag.py", line 383, in parse
    loader.exec_module(new_module)
  File "<frozen importlib._bootstrap_external>", line 999, in exec_module
  File "<frozen importlib._bootstrap>", line 488, in _call_with_frames_removed
  File "/opt/airflow/dags/dag.py", line 25, in <module>
    storage_client = storage.Client()
                     ^^^^^^^^^^^^^^^^
  File "/home/airflow/.local/lib/python3.12/site-packages/google/cloud/storage/client.py", line 228, in __init__
    super(Client, self).__init__(
  File "/home/airflow/.local/lib/python3.12/site-packages/google/cloud/client/__init__.py", line 320, in __init__
    _ClientProjectMixin.__init__(self, project=project, credentials=credentials)
  File "/home/airflow/.local/lib/python3.12/site-packages/google/cloud/client/__init__.py", line 268, in __init__
    project = self._determine_default(project)
              ^^^^^^^^^^^^^^^^^^^^^^^^^^^^^^^^
  File "/home/airflow/.local/lib/python3.12/site-packages/google/cloud/client/__init__.py", line 287, in _determine_default
    return _determine_default_project(project)
           ^^^^^^^^^^^^^^^^^^^^^^^^^^^^^^^^^^^
  File "/home/airflow/.local/lib/python3.12/site-packages/google/cloud/_helpers/__init__.py", line 152, in _determine_default_project
    _, project = google.auth.default()
                 ^^^^^^^^^^^^^^^^^^^^^
  File "/home/airflow/.local/lib/python3.12/site-packages/google/auth/_default.py", line 719, in default
    raise exceptions.DefaultCredentialsError(_CLOUD_SDK_MISSING_CREDENTIALS)
google.auth.exceptions.DefaultCredentialsError: Your default credentials were not found. To set up Application Default Credentials, see https://cloud.google.com/docs/authentication/external/set-up-adc for more information.
[2025-04-05T23:34:08.005+0000] {processor.py:927} WARNING - No viable dags retrieved from /opt/airflow/dags/dag.py
[2025-04-05T23:34:08.018+0000] {processor.py:208} INFO - Processing /opt/airflow/dags/dag.py took 6.101 seconds
[2025-04-05T23:34:38.209+0000] {processor.py:186} INFO - Started process (PID=1340) to work on /opt/airflow/dags/dag.py
[2025-04-05T23:34:38.210+0000] {processor.py:914} INFO - Processing file /opt/airflow/dags/dag.py for tasks to queue
[2025-04-05T23:34:38.211+0000] {logging_mixin.py:190} INFO - [2025-04-05T23:34:38.211+0000] {dagbag.py:588} INFO - Filling up the DagBag from /opt/airflow/dags/dag.py
[2025-04-05T23:34:41.223+0000] {logging_mixin.py:190} INFO - [2025-04-05T23:34:41.222+0000] {_metadata.py:142} WARNING - Compute Engine Metadata server unavailable on attempt 1 of 3. Reason: timed out
[2025-04-05T23:34:42.206+0000] {logging_mixin.py:190} INFO - [2025-04-05T23:34:42.206+0000] {_metadata.py:142} WARNING - Compute Engine Metadata server unavailable on attempt 2 of 3. Reason: [Errno 111] Connection refused
[2025-04-05T23:34:44.161+0000] {logging_mixin.py:190} INFO - [2025-04-05T23:34:44.160+0000] {_metadata.py:142} WARNING - Compute Engine Metadata server unavailable on attempt 3 of 3. Reason: [Errno 111] Connection refused
[2025-04-05T23:34:44.162+0000] {logging_mixin.py:190} INFO - [2025-04-05T23:34:44.161+0000] {_default.py:362} WARNING - Authentication failed using Compute Engine authentication due to unavailable metadata server.
[2025-04-05T23:34:44.168+0000] {logging_mixin.py:190} INFO - [2025-04-05T23:34:44.162+0000] {dagbag.py:387} ERROR - Failed to import: /opt/airflow/dags/dag.py
Traceback (most recent call last):
  File "/home/airflow/.local/lib/python3.12/site-packages/airflow/models/dagbag.py", line 383, in parse
    loader.exec_module(new_module)
  File "<frozen importlib._bootstrap_external>", line 999, in exec_module
  File "<frozen importlib._bootstrap>", line 488, in _call_with_frames_removed
  File "/opt/airflow/dags/dag.py", line 25, in <module>
    storage_client = storage.Client()
                     ^^^^^^^^^^^^^^^^
  File "/home/airflow/.local/lib/python3.12/site-packages/google/cloud/storage/client.py", line 228, in __init__
    super(Client, self).__init__(
  File "/home/airflow/.local/lib/python3.12/site-packages/google/cloud/client/__init__.py", line 320, in __init__
    _ClientProjectMixin.__init__(self, project=project, credentials=credentials)
  File "/home/airflow/.local/lib/python3.12/site-packages/google/cloud/client/__init__.py", line 268, in __init__
    project = self._determine_default(project)
              ^^^^^^^^^^^^^^^^^^^^^^^^^^^^^^^^
  File "/home/airflow/.local/lib/python3.12/site-packages/google/cloud/client/__init__.py", line 287, in _determine_default
    return _determine_default_project(project)
           ^^^^^^^^^^^^^^^^^^^^^^^^^^^^^^^^^^^
  File "/home/airflow/.local/lib/python3.12/site-packages/google/cloud/_helpers/__init__.py", line 152, in _determine_default_project
    _, project = google.auth.default()
                 ^^^^^^^^^^^^^^^^^^^^^
  File "/home/airflow/.local/lib/python3.12/site-packages/google/auth/_default.py", line 719, in default
    raise exceptions.DefaultCredentialsError(_CLOUD_SDK_MISSING_CREDENTIALS)
google.auth.exceptions.DefaultCredentialsError: Your default credentials were not found. To set up Application Default Credentials, see https://cloud.google.com/docs/authentication/external/set-up-adc for more information.
[2025-04-05T23:34:44.170+0000] {processor.py:927} WARNING - No viable dags retrieved from /opt/airflow/dags/dag.py
[2025-04-05T23:34:44.193+0000] {processor.py:208} INFO - Processing /opt/airflow/dags/dag.py took 5.987 seconds
[2025-04-05T23:35:14.418+0000] {processor.py:186} INFO - Started process (PID=1447) to work on /opt/airflow/dags/dag.py
[2025-04-05T23:35:14.421+0000] {processor.py:914} INFO - Processing file /opt/airflow/dags/dag.py for tasks to queue
[2025-04-05T23:35:14.423+0000] {logging_mixin.py:190} INFO - [2025-04-05T23:35:14.422+0000] {dagbag.py:588} INFO - Filling up the DagBag from /opt/airflow/dags/dag.py
[2025-04-05T23:35:17.434+0000] {logging_mixin.py:190} INFO - [2025-04-05T23:35:17.432+0000] {_metadata.py:142} WARNING - Compute Engine Metadata server unavailable on attempt 1 of 3. Reason: timed out
[2025-04-05T23:35:18.423+0000] {logging_mixin.py:190} INFO - [2025-04-05T23:35:18.422+0000] {_metadata.py:142} WARNING - Compute Engine Metadata server unavailable on attempt 2 of 3. Reason: [Errno 111] Connection refused
[2025-04-05T23:35:20.492+0000] {logging_mixin.py:190} INFO - [2025-04-05T23:35:20.492+0000] {_metadata.py:142} WARNING - Compute Engine Metadata server unavailable on attempt 3 of 3. Reason: [Errno 111] Connection refused
[2025-04-05T23:35:20.493+0000] {logging_mixin.py:190} INFO - [2025-04-05T23:35:20.493+0000] {_default.py:362} WARNING - Authentication failed using Compute Engine authentication due to unavailable metadata server.
[2025-04-05T23:35:20.498+0000] {logging_mixin.py:190} INFO - [2025-04-05T23:35:20.494+0000] {dagbag.py:387} ERROR - Failed to import: /opt/airflow/dags/dag.py
Traceback (most recent call last):
  File "/home/airflow/.local/lib/python3.12/site-packages/airflow/models/dagbag.py", line 383, in parse
    loader.exec_module(new_module)
  File "<frozen importlib._bootstrap_external>", line 999, in exec_module
  File "<frozen importlib._bootstrap>", line 488, in _call_with_frames_removed
  File "/opt/airflow/dags/dag.py", line 25, in <module>
    storage_client = storage.Client()
                     ^^^^^^^^^^^^^^^^
  File "/home/airflow/.local/lib/python3.12/site-packages/google/cloud/storage/client.py", line 228, in __init__
    super(Client, self).__init__(
  File "/home/airflow/.local/lib/python3.12/site-packages/google/cloud/client/__init__.py", line 320, in __init__
    _ClientProjectMixin.__init__(self, project=project, credentials=credentials)
  File "/home/airflow/.local/lib/python3.12/site-packages/google/cloud/client/__init__.py", line 268, in __init__
    project = self._determine_default(project)
              ^^^^^^^^^^^^^^^^^^^^^^^^^^^^^^^^
  File "/home/airflow/.local/lib/python3.12/site-packages/google/cloud/client/__init__.py", line 287, in _determine_default
    return _determine_default_project(project)
           ^^^^^^^^^^^^^^^^^^^^^^^^^^^^^^^^^^^
  File "/home/airflow/.local/lib/python3.12/site-packages/google/cloud/_helpers/__init__.py", line 152, in _determine_default_project
    _, project = google.auth.default()
                 ^^^^^^^^^^^^^^^^^^^^^
  File "/home/airflow/.local/lib/python3.12/site-packages/google/auth/_default.py", line 719, in default
    raise exceptions.DefaultCredentialsError(_CLOUD_SDK_MISSING_CREDENTIALS)
google.auth.exceptions.DefaultCredentialsError: Your default credentials were not found. To set up Application Default Credentials, see https://cloud.google.com/docs/authentication/external/set-up-adc for more information.
[2025-04-05T23:35:20.499+0000] {processor.py:927} WARNING - No viable dags retrieved from /opt/airflow/dags/dag.py
[2025-04-05T23:35:20.523+0000] {processor.py:208} INFO - Processing /opt/airflow/dags/dag.py took 6.109 seconds
[2025-04-05T23:35:50.702+0000] {processor.py:186} INFO - Started process (PID=1511) to work on /opt/airflow/dags/dag.py
[2025-04-05T23:35:50.703+0000] {processor.py:914} INFO - Processing file /opt/airflow/dags/dag.py for tasks to queue
[2025-04-05T23:35:50.706+0000] {logging_mixin.py:190} INFO - [2025-04-05T23:35:50.705+0000] {dagbag.py:588} INFO - Filling up the DagBag from /opt/airflow/dags/dag.py
[2025-04-05T23:35:53.718+0000] {logging_mixin.py:190} INFO - [2025-04-05T23:35:53.717+0000] {_metadata.py:142} WARNING - Compute Engine Metadata server unavailable on attempt 1 of 3. Reason: timed out
[2025-04-05T23:35:54.656+0000] {logging_mixin.py:190} INFO - [2025-04-05T23:35:54.655+0000] {_metadata.py:142} WARNING - Compute Engine Metadata server unavailable on attempt 2 of 3. Reason: [Errno 111] Connection refused
[2025-04-05T23:35:56.615+0000] {logging_mixin.py:190} INFO - [2025-04-05T23:35:56.614+0000] {_metadata.py:142} WARNING - Compute Engine Metadata server unavailable on attempt 3 of 3. Reason: [Errno 111] Connection refused
[2025-04-05T23:35:56.616+0000] {logging_mixin.py:190} INFO - [2025-04-05T23:35:56.616+0000] {_default.py:362} WARNING - Authentication failed using Compute Engine authentication due to unavailable metadata server.
[2025-04-05T23:35:56.623+0000] {logging_mixin.py:190} INFO - [2025-04-05T23:35:56.617+0000] {dagbag.py:387} ERROR - Failed to import: /opt/airflow/dags/dag.py
Traceback (most recent call last):
  File "/home/airflow/.local/lib/python3.12/site-packages/airflow/models/dagbag.py", line 383, in parse
    loader.exec_module(new_module)
  File "<frozen importlib._bootstrap_external>", line 999, in exec_module
  File "<frozen importlib._bootstrap>", line 488, in _call_with_frames_removed
  File "/opt/airflow/dags/dag.py", line 25, in <module>
    storage_client = storage.Client()
                     ^^^^^^^^^^^^^^^^
  File "/home/airflow/.local/lib/python3.12/site-packages/google/cloud/storage/client.py", line 228, in __init__
    super(Client, self).__init__(
  File "/home/airflow/.local/lib/python3.12/site-packages/google/cloud/client/__init__.py", line 320, in __init__
    _ClientProjectMixin.__init__(self, project=project, credentials=credentials)
  File "/home/airflow/.local/lib/python3.12/site-packages/google/cloud/client/__init__.py", line 268, in __init__
    project = self._determine_default(project)
              ^^^^^^^^^^^^^^^^^^^^^^^^^^^^^^^^
  File "/home/airflow/.local/lib/python3.12/site-packages/google/cloud/client/__init__.py", line 287, in _determine_default
    return _determine_default_project(project)
           ^^^^^^^^^^^^^^^^^^^^^^^^^^^^^^^^^^^
  File "/home/airflow/.local/lib/python3.12/site-packages/google/cloud/_helpers/__init__.py", line 152, in _determine_default_project
    _, project = google.auth.default()
                 ^^^^^^^^^^^^^^^^^^^^^
  File "/home/airflow/.local/lib/python3.12/site-packages/google/auth/_default.py", line 719, in default
    raise exceptions.DefaultCredentialsError(_CLOUD_SDK_MISSING_CREDENTIALS)
google.auth.exceptions.DefaultCredentialsError: Your default credentials were not found. To set up Application Default Credentials, see https://cloud.google.com/docs/authentication/external/set-up-adc for more information.
[2025-04-05T23:35:56.624+0000] {processor.py:927} WARNING - No viable dags retrieved from /opt/airflow/dags/dag.py
[2025-04-05T23:35:56.651+0000] {processor.py:208} INFO - Processing /opt/airflow/dags/dag.py took 5.955 seconds
[2025-04-05T23:36:27.002+0000] {processor.py:186} INFO - Started process (PID=1575) to work on /opt/airflow/dags/dag.py
[2025-04-05T23:36:27.005+0000] {processor.py:914} INFO - Processing file /opt/airflow/dags/dag.py for tasks to queue
[2025-04-05T23:36:27.009+0000] {logging_mixin.py:190} INFO - [2025-04-05T23:36:27.008+0000] {dagbag.py:588} INFO - Filling up the DagBag from /opt/airflow/dags/dag.py
[2025-04-05T23:36:30.021+0000] {logging_mixin.py:190} INFO - [2025-04-05T23:36:30.019+0000] {_metadata.py:142} WARNING - Compute Engine Metadata server unavailable on attempt 1 of 3. Reason: timed out
[2025-04-05T23:36:31.011+0000] {logging_mixin.py:190} INFO - [2025-04-05T23:36:31.010+0000] {_metadata.py:142} WARNING - Compute Engine Metadata server unavailable on attempt 2 of 3. Reason: [Errno 111] Connection refused
[2025-04-05T23:36:33.182+0000] {logging_mixin.py:190} INFO - [2025-04-05T23:36:33.181+0000] {_metadata.py:142} WARNING - Compute Engine Metadata server unavailable on attempt 3 of 3. Reason: [Errno 111] Connection refused
[2025-04-05T23:36:33.182+0000] {logging_mixin.py:190} INFO - [2025-04-05T23:36:33.182+0000] {_default.py:362} WARNING - Authentication failed using Compute Engine authentication due to unavailable metadata server.
[2025-04-05T23:36:33.185+0000] {logging_mixin.py:190} INFO - [2025-04-05T23:36:33.183+0000] {dagbag.py:387} ERROR - Failed to import: /opt/airflow/dags/dag.py
Traceback (most recent call last):
  File "/home/airflow/.local/lib/python3.12/site-packages/airflow/models/dagbag.py", line 383, in parse
    loader.exec_module(new_module)
  File "<frozen importlib._bootstrap_external>", line 999, in exec_module
  File "<frozen importlib._bootstrap>", line 488, in _call_with_frames_removed
  File "/opt/airflow/dags/dag.py", line 25, in <module>
    storage_client = storage.Client()
                     ^^^^^^^^^^^^^^^^
  File "/home/airflow/.local/lib/python3.12/site-packages/google/cloud/storage/client.py", line 228, in __init__
    super(Client, self).__init__(
  File "/home/airflow/.local/lib/python3.12/site-packages/google/cloud/client/__init__.py", line 320, in __init__
    _ClientProjectMixin.__init__(self, project=project, credentials=credentials)
  File "/home/airflow/.local/lib/python3.12/site-packages/google/cloud/client/__init__.py", line 268, in __init__
    project = self._determine_default(project)
              ^^^^^^^^^^^^^^^^^^^^^^^^^^^^^^^^
  File "/home/airflow/.local/lib/python3.12/site-packages/google/cloud/client/__init__.py", line 287, in _determine_default
    return _determine_default_project(project)
           ^^^^^^^^^^^^^^^^^^^^^^^^^^^^^^^^^^^
  File "/home/airflow/.local/lib/python3.12/site-packages/google/cloud/_helpers/__init__.py", line 152, in _determine_default_project
    _, project = google.auth.default()
                 ^^^^^^^^^^^^^^^^^^^^^
  File "/home/airflow/.local/lib/python3.12/site-packages/google/auth/_default.py", line 719, in default
    raise exceptions.DefaultCredentialsError(_CLOUD_SDK_MISSING_CREDENTIALS)
google.auth.exceptions.DefaultCredentialsError: Your default credentials were not found. To set up Application Default Credentials, see https://cloud.google.com/docs/authentication/external/set-up-adc for more information.
[2025-04-05T23:36:33.186+0000] {processor.py:927} WARNING - No viable dags retrieved from /opt/airflow/dags/dag.py
[2025-04-05T23:36:33.199+0000] {processor.py:208} INFO - Processing /opt/airflow/dags/dag.py took 6.206 seconds
[2025-04-05T23:36:45.089+0000] {processor.py:186} INFO - Started process (PID=1639) to work on /opt/airflow/dags/dag.py
[2025-04-05T23:36:45.090+0000] {processor.py:914} INFO - Processing file /opt/airflow/dags/dag.py for tasks to queue
[2025-04-05T23:36:45.093+0000] {logging_mixin.py:190} INFO - [2025-04-05T23:36:45.093+0000] {dagbag.py:588} INFO - Filling up the DagBag from /opt/airflow/dags/dag.py
[2025-04-05T23:36:45.102+0000] {logging_mixin.py:190} INFO - [2025-04-05T23:36:45.099+0000] {dagbag.py:387} ERROR - Failed to import: /opt/airflow/dags/dag.py
Traceback (most recent call last):
  File "/home/airflow/.local/lib/python3.12/site-packages/airflow/models/dagbag.py", line 383, in parse
    loader.exec_module(new_module)
  File "<frozen importlib._bootstrap_external>", line 999, in exec_module
  File "<frozen importlib._bootstrap>", line 488, in _call_with_frames_removed
  File "/opt/airflow/dags/dag.py", line 25, in <module>
    storage_client = storage.Client()
                     ^^^^^^^^^^^^^^^^
  File "/home/airflow/.local/lib/python3.12/site-packages/google/cloud/storage/client.py", line 228, in __init__
    super(Client, self).__init__(
  File "/home/airflow/.local/lib/python3.12/site-packages/google/cloud/client/__init__.py", line 320, in __init__
    _ClientProjectMixin.__init__(self, project=project, credentials=credentials)
  File "/home/airflow/.local/lib/python3.12/site-packages/google/cloud/client/__init__.py", line 268, in __init__
    project = self._determine_default(project)
              ^^^^^^^^^^^^^^^^^^^^^^^^^^^^^^^^
  File "/home/airflow/.local/lib/python3.12/site-packages/google/cloud/client/__init__.py", line 287, in _determine_default
    return _determine_default_project(project)
           ^^^^^^^^^^^^^^^^^^^^^^^^^^^^^^^^^^^
  File "/home/airflow/.local/lib/python3.12/site-packages/google/cloud/_helpers/__init__.py", line 152, in _determine_default_project
    _, project = google.auth.default()
                 ^^^^^^^^^^^^^^^^^^^^^
  File "/home/airflow/.local/lib/python3.12/site-packages/google/auth/_default.py", line 685, in default
    credentials, project_id = checker()
                              ^^^^^^^^^
  File "/home/airflow/.local/lib/python3.12/site-packages/google/auth/_default.py", line 678, in <lambda>
    lambda: _get_explicit_environ_credentials(quota_project_id=quota_project_id),
            ^^^^^^^^^^^^^^^^^^^^^^^^^^^^^^^^^^^^^^^^^^^^^^^^^^^^^^^^^^^^^^^^^^^^
  File "/home/airflow/.local/lib/python3.12/site-packages/google/auth/_default.py", line 293, in _get_explicit_environ_credentials
    credentials, project_id = load_credentials_from_file(
                              ^^^^^^^^^^^^^^^^^^^^^^^^^^^
  File "/home/airflow/.local/lib/python3.12/site-packages/google/auth/_default.py", line 125, in load_credentials_from_file
    raise exceptions.DefaultCredentialsError(
google.auth.exceptions.DefaultCredentialsError: File ./taxi-rides-ny-450705-77964478f823.json was not found.
[2025-04-05T23:36:45.102+0000] {processor.py:927} WARNING - No viable dags retrieved from /opt/airflow/dags/dag.py
[2025-04-05T23:36:45.119+0000] {processor.py:208} INFO - Processing /opt/airflow/dags/dag.py took 0.038 seconds
[2025-04-05T23:37:15.422+0000] {processor.py:186} INFO - Started process (PID=1703) to work on /opt/airflow/dags/dag.py
[2025-04-05T23:37:15.425+0000] {processor.py:914} INFO - Processing file /opt/airflow/dags/dag.py for tasks to queue
[2025-04-05T23:37:15.430+0000] {logging_mixin.py:190} INFO - [2025-04-05T23:37:15.429+0000] {dagbag.py:588} INFO - Filling up the DagBag from /opt/airflow/dags/dag.py
[2025-04-05T23:37:15.436+0000] {logging_mixin.py:190} INFO - [2025-04-05T23:37:15.434+0000] {dagbag.py:387} ERROR - Failed to import: /opt/airflow/dags/dag.py
Traceback (most recent call last):
  File "/home/airflow/.local/lib/python3.12/site-packages/airflow/models/dagbag.py", line 383, in parse
    loader.exec_module(new_module)
  File "<frozen importlib._bootstrap_external>", line 999, in exec_module
  File "<frozen importlib._bootstrap>", line 488, in _call_with_frames_removed
  File "/opt/airflow/dags/dag.py", line 25, in <module>
    storage_client = storage.Client()
                     ^^^^^^^^^^^^^^^^
  File "/home/airflow/.local/lib/python3.12/site-packages/google/cloud/storage/client.py", line 228, in __init__
    super(Client, self).__init__(
  File "/home/airflow/.local/lib/python3.12/site-packages/google/cloud/client/__init__.py", line 320, in __init__
    _ClientProjectMixin.__init__(self, project=project, credentials=credentials)
  File "/home/airflow/.local/lib/python3.12/site-packages/google/cloud/client/__init__.py", line 268, in __init__
    project = self._determine_default(project)
              ^^^^^^^^^^^^^^^^^^^^^^^^^^^^^^^^
  File "/home/airflow/.local/lib/python3.12/site-packages/google/cloud/client/__init__.py", line 287, in _determine_default
    return _determine_default_project(project)
           ^^^^^^^^^^^^^^^^^^^^^^^^^^^^^^^^^^^
  File "/home/airflow/.local/lib/python3.12/site-packages/google/cloud/_helpers/__init__.py", line 152, in _determine_default_project
    _, project = google.auth.default()
                 ^^^^^^^^^^^^^^^^^^^^^
  File "/home/airflow/.local/lib/python3.12/site-packages/google/auth/_default.py", line 685, in default
    credentials, project_id = checker()
                              ^^^^^^^^^
  File "/home/airflow/.local/lib/python3.12/site-packages/google/auth/_default.py", line 678, in <lambda>
    lambda: _get_explicit_environ_credentials(quota_project_id=quota_project_id),
            ^^^^^^^^^^^^^^^^^^^^^^^^^^^^^^^^^^^^^^^^^^^^^^^^^^^^^^^^^^^^^^^^^^^^
  File "/home/airflow/.local/lib/python3.12/site-packages/google/auth/_default.py", line 293, in _get_explicit_environ_credentials
    credentials, project_id = load_credentials_from_file(
                              ^^^^^^^^^^^^^^^^^^^^^^^^^^^
  File "/home/airflow/.local/lib/python3.12/site-packages/google/auth/_default.py", line 125, in load_credentials_from_file
    raise exceptions.DefaultCredentialsError(
google.auth.exceptions.DefaultCredentialsError: File ./taxi-rides-ny-450705-77964478f823.json was not found.
[2025-04-05T23:37:15.437+0000] {processor.py:927} WARNING - No viable dags retrieved from /opt/airflow/dags/dag.py
[2025-04-05T23:37:15.453+0000] {processor.py:208} INFO - Processing /opt/airflow/dags/dag.py took 0.039 seconds
[2025-04-05T23:37:45.602+0000] {processor.py:186} INFO - Started process (PID=1767) to work on /opt/airflow/dags/dag.py
[2025-04-05T23:37:45.603+0000] {processor.py:914} INFO - Processing file /opt/airflow/dags/dag.py for tasks to queue
[2025-04-05T23:37:45.605+0000] {logging_mixin.py:190} INFO - [2025-04-05T23:37:45.605+0000] {dagbag.py:588} INFO - Filling up the DagBag from /opt/airflow/dags/dag.py
[2025-04-05T23:37:45.612+0000] {logging_mixin.py:190} INFO - [2025-04-05T23:37:45.610+0000] {dagbag.py:387} ERROR - Failed to import: /opt/airflow/dags/dag.py
Traceback (most recent call last):
  File "/home/airflow/.local/lib/python3.12/site-packages/airflow/models/dagbag.py", line 383, in parse
    loader.exec_module(new_module)
  File "<frozen importlib._bootstrap_external>", line 999, in exec_module
  File "<frozen importlib._bootstrap>", line 488, in _call_with_frames_removed
  File "/opt/airflow/dags/dag.py", line 25, in <module>
    storage_client = storage.Client()
                     ^^^^^^^^^^^^^^^^
  File "/home/airflow/.local/lib/python3.12/site-packages/google/cloud/storage/client.py", line 228, in __init__
    super(Client, self).__init__(
  File "/home/airflow/.local/lib/python3.12/site-packages/google/cloud/client/__init__.py", line 320, in __init__
    _ClientProjectMixin.__init__(self, project=project, credentials=credentials)
  File "/home/airflow/.local/lib/python3.12/site-packages/google/cloud/client/__init__.py", line 268, in __init__
    project = self._determine_default(project)
              ^^^^^^^^^^^^^^^^^^^^^^^^^^^^^^^^
  File "/home/airflow/.local/lib/python3.12/site-packages/google/cloud/client/__init__.py", line 287, in _determine_default
    return _determine_default_project(project)
           ^^^^^^^^^^^^^^^^^^^^^^^^^^^^^^^^^^^
  File "/home/airflow/.local/lib/python3.12/site-packages/google/cloud/_helpers/__init__.py", line 152, in _determine_default_project
    _, project = google.auth.default()
                 ^^^^^^^^^^^^^^^^^^^^^
  File "/home/airflow/.local/lib/python3.12/site-packages/google/auth/_default.py", line 685, in default
    credentials, project_id = checker()
                              ^^^^^^^^^
  File "/home/airflow/.local/lib/python3.12/site-packages/google/auth/_default.py", line 678, in <lambda>
    lambda: _get_explicit_environ_credentials(quota_project_id=quota_project_id),
            ^^^^^^^^^^^^^^^^^^^^^^^^^^^^^^^^^^^^^^^^^^^^^^^^^^^^^^^^^^^^^^^^^^^^
  File "/home/airflow/.local/lib/python3.12/site-packages/google/auth/_default.py", line 293, in _get_explicit_environ_credentials
    credentials, project_id = load_credentials_from_file(
                              ^^^^^^^^^^^^^^^^^^^^^^^^^^^
  File "/home/airflow/.local/lib/python3.12/site-packages/google/auth/_default.py", line 125, in load_credentials_from_file
    raise exceptions.DefaultCredentialsError(
google.auth.exceptions.DefaultCredentialsError: File ./taxi-rides-ny-450705-77964478f823.json was not found.
[2025-04-05T23:37:45.613+0000] {processor.py:927} WARNING - No viable dags retrieved from /opt/airflow/dags/dag.py
[2025-04-05T23:37:45.626+0000] {processor.py:208} INFO - Processing /opt/airflow/dags/dag.py took 0.030 seconds
[2025-04-05T23:38:15.947+0000] {processor.py:186} INFO - Started process (PID=1831) to work on /opt/airflow/dags/dag.py
[2025-04-05T23:38:15.949+0000] {processor.py:914} INFO - Processing file /opt/airflow/dags/dag.py for tasks to queue
[2025-04-05T23:38:15.951+0000] {logging_mixin.py:190} INFO - [2025-04-05T23:38:15.951+0000] {dagbag.py:588} INFO - Filling up the DagBag from /opt/airflow/dags/dag.py
[2025-04-05T23:38:15.958+0000] {logging_mixin.py:190} INFO - [2025-04-05T23:38:15.955+0000] {dagbag.py:387} ERROR - Failed to import: /opt/airflow/dags/dag.py
Traceback (most recent call last):
  File "/home/airflow/.local/lib/python3.12/site-packages/airflow/models/dagbag.py", line 383, in parse
    loader.exec_module(new_module)
  File "<frozen importlib._bootstrap_external>", line 999, in exec_module
  File "<frozen importlib._bootstrap>", line 488, in _call_with_frames_removed
  File "/opt/airflow/dags/dag.py", line 25, in <module>
    storage_client = storage.Client()
                     ^^^^^^^^^^^^^^^^
  File "/home/airflow/.local/lib/python3.12/site-packages/google/cloud/storage/client.py", line 228, in __init__
    super(Client, self).__init__(
  File "/home/airflow/.local/lib/python3.12/site-packages/google/cloud/client/__init__.py", line 320, in __init__
    _ClientProjectMixin.__init__(self, project=project, credentials=credentials)
  File "/home/airflow/.local/lib/python3.12/site-packages/google/cloud/client/__init__.py", line 268, in __init__
    project = self._determine_default(project)
              ^^^^^^^^^^^^^^^^^^^^^^^^^^^^^^^^
  File "/home/airflow/.local/lib/python3.12/site-packages/google/cloud/client/__init__.py", line 287, in _determine_default
    return _determine_default_project(project)
           ^^^^^^^^^^^^^^^^^^^^^^^^^^^^^^^^^^^
  File "/home/airflow/.local/lib/python3.12/site-packages/google/cloud/_helpers/__init__.py", line 152, in _determine_default_project
    _, project = google.auth.default()
                 ^^^^^^^^^^^^^^^^^^^^^
  File "/home/airflow/.local/lib/python3.12/site-packages/google/auth/_default.py", line 685, in default
    credentials, project_id = checker()
                              ^^^^^^^^^
  File "/home/airflow/.local/lib/python3.12/site-packages/google/auth/_default.py", line 678, in <lambda>
    lambda: _get_explicit_environ_credentials(quota_project_id=quota_project_id),
            ^^^^^^^^^^^^^^^^^^^^^^^^^^^^^^^^^^^^^^^^^^^^^^^^^^^^^^^^^^^^^^^^^^^^
  File "/home/airflow/.local/lib/python3.12/site-packages/google/auth/_default.py", line 293, in _get_explicit_environ_credentials
    credentials, project_id = load_credentials_from_file(
                              ^^^^^^^^^^^^^^^^^^^^^^^^^^^
  File "/home/airflow/.local/lib/python3.12/site-packages/google/auth/_default.py", line 125, in load_credentials_from_file
    raise exceptions.DefaultCredentialsError(
google.auth.exceptions.DefaultCredentialsError: File ./taxi-rides-ny-450705-77964478f823.json was not found.
[2025-04-05T23:38:15.958+0000] {processor.py:927} WARNING - No viable dags retrieved from /opt/airflow/dags/dag.py
[2025-04-05T23:38:15.974+0000] {processor.py:208} INFO - Processing /opt/airflow/dags/dag.py took 0.034 seconds
[2025-04-05T23:38:46.323+0000] {processor.py:186} INFO - Started process (PID=1895) to work on /opt/airflow/dags/dag.py
[2025-04-05T23:38:46.324+0000] {processor.py:914} INFO - Processing file /opt/airflow/dags/dag.py for tasks to queue
[2025-04-05T23:38:46.326+0000] {logging_mixin.py:190} INFO - [2025-04-05T23:38:46.326+0000] {dagbag.py:588} INFO - Filling up the DagBag from /opt/airflow/dags/dag.py
[2025-04-05T23:38:46.332+0000] {logging_mixin.py:190} INFO - [2025-04-05T23:38:46.330+0000] {dagbag.py:387} ERROR - Failed to import: /opt/airflow/dags/dag.py
Traceback (most recent call last):
  File "/home/airflow/.local/lib/python3.12/site-packages/airflow/models/dagbag.py", line 383, in parse
    loader.exec_module(new_module)
  File "<frozen importlib._bootstrap_external>", line 999, in exec_module
  File "<frozen importlib._bootstrap>", line 488, in _call_with_frames_removed
  File "/opt/airflow/dags/dag.py", line 25, in <module>
    storage_client = storage.Client()
                     ^^^^^^^^^^^^^^^^
  File "/home/airflow/.local/lib/python3.12/site-packages/google/cloud/storage/client.py", line 228, in __init__
    super(Client, self).__init__(
  File "/home/airflow/.local/lib/python3.12/site-packages/google/cloud/client/__init__.py", line 320, in __init__
    _ClientProjectMixin.__init__(self, project=project, credentials=credentials)
  File "/home/airflow/.local/lib/python3.12/site-packages/google/cloud/client/__init__.py", line 268, in __init__
    project = self._determine_default(project)
              ^^^^^^^^^^^^^^^^^^^^^^^^^^^^^^^^
  File "/home/airflow/.local/lib/python3.12/site-packages/google/cloud/client/__init__.py", line 287, in _determine_default
    return _determine_default_project(project)
           ^^^^^^^^^^^^^^^^^^^^^^^^^^^^^^^^^^^
  File "/home/airflow/.local/lib/python3.12/site-packages/google/cloud/_helpers/__init__.py", line 152, in _determine_default_project
    _, project = google.auth.default()
                 ^^^^^^^^^^^^^^^^^^^^^
  File "/home/airflow/.local/lib/python3.12/site-packages/google/auth/_default.py", line 685, in default
    credentials, project_id = checker()
                              ^^^^^^^^^
  File "/home/airflow/.local/lib/python3.12/site-packages/google/auth/_default.py", line 678, in <lambda>
    lambda: _get_explicit_environ_credentials(quota_project_id=quota_project_id),
            ^^^^^^^^^^^^^^^^^^^^^^^^^^^^^^^^^^^^^^^^^^^^^^^^^^^^^^^^^^^^^^^^^^^^
  File "/home/airflow/.local/lib/python3.12/site-packages/google/auth/_default.py", line 293, in _get_explicit_environ_credentials
    credentials, project_id = load_credentials_from_file(
                              ^^^^^^^^^^^^^^^^^^^^^^^^^^^
  File "/home/airflow/.local/lib/python3.12/site-packages/google/auth/_default.py", line 125, in load_credentials_from_file
    raise exceptions.DefaultCredentialsError(
google.auth.exceptions.DefaultCredentialsError: File ./taxi-rides-ny-450705-77964478f823.json was not found.
[2025-04-05T23:38:46.333+0000] {processor.py:927} WARNING - No viable dags retrieved from /opt/airflow/dags/dag.py
[2025-04-05T23:38:46.345+0000] {processor.py:208} INFO - Processing /opt/airflow/dags/dag.py took 0.028 seconds
[2025-04-05T23:39:28.851+0000] {processor.py:186} INFO - Started process (PID=42) to work on /opt/airflow/dags/dag.py
[2025-04-05T23:39:28.854+0000] {processor.py:914} INFO - Processing file /opt/airflow/dags/dag.py for tasks to queue
[2025-04-05T23:39:28.859+0000] {logging_mixin.py:190} INFO - [2025-04-05T23:39:28.859+0000] {dagbag.py:588} INFO - Filling up the DagBag from /opt/airflow/dags/dag.py
[2025-04-05T23:39:28.884+0000] {logging_mixin.py:190} INFO - [2025-04-05T23:39:28.879+0000] {dagbag.py:387} ERROR - Failed to import: /opt/airflow/dags/dag.py
Traceback (most recent call last):
  File "/home/airflow/.local/lib/python3.12/site-packages/airflow/models/dagbag.py", line 383, in parse
    loader.exec_module(new_module)
  File "<frozen importlib._bootstrap_external>", line 999, in exec_module
  File "<frozen importlib._bootstrap>", line 488, in _call_with_frames_removed
  File "/opt/airflow/dags/dag.py", line 25, in <module>
    storage_client = storage.Client()
                     ^^^^^^^^^^^^^^^^
  File "/home/airflow/.local/lib/python3.12/site-packages/google/cloud/storage/client.py", line 228, in __init__
    super(Client, self).__init__(
  File "/home/airflow/.local/lib/python3.12/site-packages/google/cloud/client/__init__.py", line 320, in __init__
    _ClientProjectMixin.__init__(self, project=project, credentials=credentials)
  File "/home/airflow/.local/lib/python3.12/site-packages/google/cloud/client/__init__.py", line 268, in __init__
    project = self._determine_default(project)
              ^^^^^^^^^^^^^^^^^^^^^^^^^^^^^^^^
  File "/home/airflow/.local/lib/python3.12/site-packages/google/cloud/client/__init__.py", line 287, in _determine_default
    return _determine_default_project(project)
           ^^^^^^^^^^^^^^^^^^^^^^^^^^^^^^^^^^^
  File "/home/airflow/.local/lib/python3.12/site-packages/google/cloud/_helpers/__init__.py", line 152, in _determine_default_project
    _, project = google.auth.default()
                 ^^^^^^^^^^^^^^^^^^^^^
  File "/home/airflow/.local/lib/python3.12/site-packages/google/auth/_default.py", line 685, in default
    credentials, project_id = checker()
                              ^^^^^^^^^
  File "/home/airflow/.local/lib/python3.12/site-packages/google/auth/_default.py", line 678, in <lambda>
    lambda: _get_explicit_environ_credentials(quota_project_id=quota_project_id),
            ^^^^^^^^^^^^^^^^^^^^^^^^^^^^^^^^^^^^^^^^^^^^^^^^^^^^^^^^^^^^^^^^^^^^
  File "/home/airflow/.local/lib/python3.12/site-packages/google/auth/_default.py", line 293, in _get_explicit_environ_credentials
    credentials, project_id = load_credentials_from_file(
                              ^^^^^^^^^^^^^^^^^^^^^^^^^^^
  File "/home/airflow/.local/lib/python3.12/site-packages/google/auth/_default.py", line 125, in load_credentials_from_file
    raise exceptions.DefaultCredentialsError(
google.auth.exceptions.DefaultCredentialsError: File /Users/nd_blaze/nd_blaze.dev/python_dev/DataEngineering/ZoomCamp/taxi-rides-ny-450705-77964478f823.json was not found.
[2025-04-05T23:39:28.886+0000] {processor.py:927} WARNING - No viable dags retrieved from /opt/airflow/dags/dag.py
[2025-04-05T23:39:28.905+0000] {processor.py:208} INFO - Processing /opt/airflow/dags/dag.py took 0.060 seconds
[2025-04-05T23:40:15.809+0000] {processor.py:186} INFO - Started process (PID=41) to work on /opt/airflow/dags/dag.py
[2025-04-05T23:40:15.812+0000] {processor.py:914} INFO - Processing file /opt/airflow/dags/dag.py for tasks to queue
[2025-04-05T23:40:15.817+0000] {logging_mixin.py:190} INFO - [2025-04-05T23:40:15.817+0000] {dagbag.py:588} INFO - Filling up the DagBag from /opt/airflow/dags/dag.py
[2025-04-05T23:40:15.831+0000] {logging_mixin.py:190} INFO - [2025-04-05T23:40:15.822+0000] {dagbag.py:387} ERROR - Failed to import: /opt/airflow/dags/dag.py
Traceback (most recent call last):
  File "/home/airflow/.local/lib/python3.12/site-packages/airflow/models/dagbag.py", line 383, in parse
    loader.exec_module(new_module)
  File "<frozen importlib._bootstrap_external>", line 999, in exec_module
  File "<frozen importlib._bootstrap>", line 488, in _call_with_frames_removed
  File "/opt/airflow/dags/dag.py", line 25, in <module>
    storage_client = storage.Client()
                     ^^^^^^^^^^^^^^^^
  File "/home/airflow/.local/lib/python3.12/site-packages/google/cloud/storage/client.py", line 228, in __init__
    super(Client, self).__init__(
  File "/home/airflow/.local/lib/python3.12/site-packages/google/cloud/client/__init__.py", line 320, in __init__
    _ClientProjectMixin.__init__(self, project=project, credentials=credentials)
  File "/home/airflow/.local/lib/python3.12/site-packages/google/cloud/client/__init__.py", line 268, in __init__
    project = self._determine_default(project)
              ^^^^^^^^^^^^^^^^^^^^^^^^^^^^^^^^
  File "/home/airflow/.local/lib/python3.12/site-packages/google/cloud/client/__init__.py", line 287, in _determine_default
    return _determine_default_project(project)
           ^^^^^^^^^^^^^^^^^^^^^^^^^^^^^^^^^^^
  File "/home/airflow/.local/lib/python3.12/site-packages/google/cloud/_helpers/__init__.py", line 152, in _determine_default_project
    _, project = google.auth.default()
                 ^^^^^^^^^^^^^^^^^^^^^
  File "/home/airflow/.local/lib/python3.12/site-packages/google/auth/_default.py", line 685, in default
    credentials, project_id = checker()
                              ^^^^^^^^^
  File "/home/airflow/.local/lib/python3.12/site-packages/google/auth/_default.py", line 678, in <lambda>
    lambda: _get_explicit_environ_credentials(quota_project_id=quota_project_id),
            ^^^^^^^^^^^^^^^^^^^^^^^^^^^^^^^^^^^^^^^^^^^^^^^^^^^^^^^^^^^^^^^^^^^^
  File "/home/airflow/.local/lib/python3.12/site-packages/google/auth/_default.py", line 293, in _get_explicit_environ_credentials
    credentials, project_id = load_credentials_from_file(
                              ^^^^^^^^^^^^^^^^^^^^^^^^^^^
  File "/home/airflow/.local/lib/python3.12/site-packages/google/auth/_default.py", line 125, in load_credentials_from_file
    raise exceptions.DefaultCredentialsError(
google.auth.exceptions.DefaultCredentialsError: File /Users/nd_blaze/nd_blaze.dev/python_dev/DataEngineering/ZoomCamp/taxi-rides-ny-450705-77964478f823.json was not found.
[2025-04-05T23:40:15.842+0000] {processor.py:927} WARNING - No viable dags retrieved from /opt/airflow/dags/dag.py
[2025-04-05T23:40:15.878+0000] {processor.py:208} INFO - Processing /opt/airflow/dags/dag.py took 0.081 seconds
[2025-04-05T23:40:46.128+0000] {processor.py:186} INFO - Started process (PID=105) to work on /opt/airflow/dags/dag.py
[2025-04-05T23:40:46.129+0000] {processor.py:914} INFO - Processing file /opt/airflow/dags/dag.py for tasks to queue
[2025-04-05T23:40:46.131+0000] {logging_mixin.py:190} INFO - [2025-04-05T23:40:46.131+0000] {dagbag.py:588} INFO - Filling up the DagBag from /opt/airflow/dags/dag.py
[2025-04-05T23:40:46.138+0000] {logging_mixin.py:190} INFO - [2025-04-05T23:40:46.136+0000] {dagbag.py:387} ERROR - Failed to import: /opt/airflow/dags/dag.py
Traceback (most recent call last):
  File "/home/airflow/.local/lib/python3.12/site-packages/airflow/models/dagbag.py", line 383, in parse
    loader.exec_module(new_module)
  File "<frozen importlib._bootstrap_external>", line 999, in exec_module
  File "<frozen importlib._bootstrap>", line 488, in _call_with_frames_removed
  File "/opt/airflow/dags/dag.py", line 25, in <module>
    storage_client = storage.Client()
                     ^^^^^^^^^^^^^^^^
  File "/home/airflow/.local/lib/python3.12/site-packages/google/cloud/storage/client.py", line 228, in __init__
    super(Client, self).__init__(
  File "/home/airflow/.local/lib/python3.12/site-packages/google/cloud/client/__init__.py", line 320, in __init__
    _ClientProjectMixin.__init__(self, project=project, credentials=credentials)
  File "/home/airflow/.local/lib/python3.12/site-packages/google/cloud/client/__init__.py", line 268, in __init__
    project = self._determine_default(project)
              ^^^^^^^^^^^^^^^^^^^^^^^^^^^^^^^^
  File "/home/airflow/.local/lib/python3.12/site-packages/google/cloud/client/__init__.py", line 287, in _determine_default
    return _determine_default_project(project)
           ^^^^^^^^^^^^^^^^^^^^^^^^^^^^^^^^^^^
  File "/home/airflow/.local/lib/python3.12/site-packages/google/cloud/_helpers/__init__.py", line 152, in _determine_default_project
    _, project = google.auth.default()
                 ^^^^^^^^^^^^^^^^^^^^^
  File "/home/airflow/.local/lib/python3.12/site-packages/google/auth/_default.py", line 685, in default
    credentials, project_id = checker()
                              ^^^^^^^^^
  File "/home/airflow/.local/lib/python3.12/site-packages/google/auth/_default.py", line 678, in <lambda>
    lambda: _get_explicit_environ_credentials(quota_project_id=quota_project_id),
            ^^^^^^^^^^^^^^^^^^^^^^^^^^^^^^^^^^^^^^^^^^^^^^^^^^^^^^^^^^^^^^^^^^^^
  File "/home/airflow/.local/lib/python3.12/site-packages/google/auth/_default.py", line 293, in _get_explicit_environ_credentials
    credentials, project_id = load_credentials_from_file(
                              ^^^^^^^^^^^^^^^^^^^^^^^^^^^
  File "/home/airflow/.local/lib/python3.12/site-packages/google/auth/_default.py", line 125, in load_credentials_from_file
    raise exceptions.DefaultCredentialsError(
google.auth.exceptions.DefaultCredentialsError: File /Users/nd_blaze/nd_blaze.dev/python_dev/DataEngineering/ZoomCamp/taxi-rides-ny-450705-77964478f823.json was not found.
[2025-04-05T23:40:46.139+0000] {processor.py:927} WARNING - No viable dags retrieved from /opt/airflow/dags/dag.py
[2025-04-05T23:40:46.152+0000] {processor.py:208} INFO - Processing /opt/airflow/dags/dag.py took 0.029 seconds
[2025-04-05T23:41:16.382+0000] {processor.py:186} INFO - Started process (PID=169) to work on /opt/airflow/dags/dag.py
[2025-04-05T23:41:16.383+0000] {processor.py:914} INFO - Processing file /opt/airflow/dags/dag.py for tasks to queue
[2025-04-05T23:41:16.387+0000] {logging_mixin.py:190} INFO - [2025-04-05T23:41:16.386+0000] {dagbag.py:588} INFO - Filling up the DagBag from /opt/airflow/dags/dag.py
[2025-04-05T23:41:16.398+0000] {logging_mixin.py:190} INFO - [2025-04-05T23:41:16.395+0000] {dagbag.py:387} ERROR - Failed to import: /opt/airflow/dags/dag.py
Traceback (most recent call last):
  File "/home/airflow/.local/lib/python3.12/site-packages/airflow/models/dagbag.py", line 383, in parse
    loader.exec_module(new_module)
  File "<frozen importlib._bootstrap_external>", line 999, in exec_module
  File "<frozen importlib._bootstrap>", line 488, in _call_with_frames_removed
  File "/opt/airflow/dags/dag.py", line 25, in <module>
    storage_client = storage.Client()
                     ^^^^^^^^^^^^^^^^
  File "/home/airflow/.local/lib/python3.12/site-packages/google/cloud/storage/client.py", line 228, in __init__
    super(Client, self).__init__(
  File "/home/airflow/.local/lib/python3.12/site-packages/google/cloud/client/__init__.py", line 320, in __init__
    _ClientProjectMixin.__init__(self, project=project, credentials=credentials)
  File "/home/airflow/.local/lib/python3.12/site-packages/google/cloud/client/__init__.py", line 268, in __init__
    project = self._determine_default(project)
              ^^^^^^^^^^^^^^^^^^^^^^^^^^^^^^^^
  File "/home/airflow/.local/lib/python3.12/site-packages/google/cloud/client/__init__.py", line 287, in _determine_default
    return _determine_default_project(project)
           ^^^^^^^^^^^^^^^^^^^^^^^^^^^^^^^^^^^
  File "/home/airflow/.local/lib/python3.12/site-packages/google/cloud/_helpers/__init__.py", line 152, in _determine_default_project
    _, project = google.auth.default()
                 ^^^^^^^^^^^^^^^^^^^^^
  File "/home/airflow/.local/lib/python3.12/site-packages/google/auth/_default.py", line 685, in default
    credentials, project_id = checker()
                              ^^^^^^^^^
  File "/home/airflow/.local/lib/python3.12/site-packages/google/auth/_default.py", line 678, in <lambda>
    lambda: _get_explicit_environ_credentials(quota_project_id=quota_project_id),
            ^^^^^^^^^^^^^^^^^^^^^^^^^^^^^^^^^^^^^^^^^^^^^^^^^^^^^^^^^^^^^^^^^^^^
  File "/home/airflow/.local/lib/python3.12/site-packages/google/auth/_default.py", line 293, in _get_explicit_environ_credentials
    credentials, project_id = load_credentials_from_file(
                              ^^^^^^^^^^^^^^^^^^^^^^^^^^^
  File "/home/airflow/.local/lib/python3.12/site-packages/google/auth/_default.py", line 125, in load_credentials_from_file
    raise exceptions.DefaultCredentialsError(
google.auth.exceptions.DefaultCredentialsError: File /Users/nd_blaze/nd_blaze.dev/python_dev/DataEngineering/ZoomCamp/taxi-rides-ny-450705-77964478f823.json was not found.
[2025-04-05T23:41:16.398+0000] {processor.py:927} WARNING - No viable dags retrieved from /opt/airflow/dags/dag.py
[2025-04-05T23:41:16.427+0000] {processor.py:208} INFO - Processing /opt/airflow/dags/dag.py took 0.057 seconds
[2025-04-05T23:41:46.587+0000] {processor.py:186} INFO - Started process (PID=233) to work on /opt/airflow/dags/dag.py
[2025-04-05T23:41:46.588+0000] {processor.py:914} INFO - Processing file /opt/airflow/dags/dag.py for tasks to queue
[2025-04-05T23:41:46.590+0000] {logging_mixin.py:190} INFO - [2025-04-05T23:41:46.590+0000] {dagbag.py:588} INFO - Filling up the DagBag from /opt/airflow/dags/dag.py
[2025-04-05T23:41:46.598+0000] {logging_mixin.py:190} INFO - [2025-04-05T23:41:46.596+0000] {dagbag.py:387} ERROR - Failed to import: /opt/airflow/dags/dag.py
Traceback (most recent call last):
  File "/home/airflow/.local/lib/python3.12/site-packages/airflow/models/dagbag.py", line 383, in parse
    loader.exec_module(new_module)
  File "<frozen importlib._bootstrap_external>", line 999, in exec_module
  File "<frozen importlib._bootstrap>", line 488, in _call_with_frames_removed
  File "/opt/airflow/dags/dag.py", line 25, in <module>
    storage_client = storage.Client()
                     ^^^^^^^^^^^^^^^^
  File "/home/airflow/.local/lib/python3.12/site-packages/google/cloud/storage/client.py", line 228, in __init__
    super(Client, self).__init__(
  File "/home/airflow/.local/lib/python3.12/site-packages/google/cloud/client/__init__.py", line 320, in __init__
    _ClientProjectMixin.__init__(self, project=project, credentials=credentials)
  File "/home/airflow/.local/lib/python3.12/site-packages/google/cloud/client/__init__.py", line 268, in __init__
    project = self._determine_default(project)
              ^^^^^^^^^^^^^^^^^^^^^^^^^^^^^^^^
  File "/home/airflow/.local/lib/python3.12/site-packages/google/cloud/client/__init__.py", line 287, in _determine_default
    return _determine_default_project(project)
           ^^^^^^^^^^^^^^^^^^^^^^^^^^^^^^^^^^^
  File "/home/airflow/.local/lib/python3.12/site-packages/google/cloud/_helpers/__init__.py", line 152, in _determine_default_project
    _, project = google.auth.default()
                 ^^^^^^^^^^^^^^^^^^^^^
  File "/home/airflow/.local/lib/python3.12/site-packages/google/auth/_default.py", line 685, in default
    credentials, project_id = checker()
                              ^^^^^^^^^
  File "/home/airflow/.local/lib/python3.12/site-packages/google/auth/_default.py", line 678, in <lambda>
    lambda: _get_explicit_environ_credentials(quota_project_id=quota_project_id),
            ^^^^^^^^^^^^^^^^^^^^^^^^^^^^^^^^^^^^^^^^^^^^^^^^^^^^^^^^^^^^^^^^^^^^
  File "/home/airflow/.local/lib/python3.12/site-packages/google/auth/_default.py", line 293, in _get_explicit_environ_credentials
    credentials, project_id = load_credentials_from_file(
                              ^^^^^^^^^^^^^^^^^^^^^^^^^^^
  File "/home/airflow/.local/lib/python3.12/site-packages/google/auth/_default.py", line 125, in load_credentials_from_file
    raise exceptions.DefaultCredentialsError(
google.auth.exceptions.DefaultCredentialsError: File /Users/nd_blaze/nd_blaze.dev/python_dev/DataEngineering/ZoomCamp/taxi-rides-ny-450705-77964478f823.json was not found.
[2025-04-05T23:41:46.599+0000] {processor.py:927} WARNING - No viable dags retrieved from /opt/airflow/dags/dag.py
[2025-04-05T23:41:46.614+0000] {processor.py:208} INFO - Processing /opt/airflow/dags/dag.py took 0.034 seconds
[2025-04-05T23:42:43.915+0000] {processor.py:186} INFO - Started process (PID=48) to work on /opt/airflow/dags/dag.py
[2025-04-05T23:42:43.915+0000] {processor.py:914} INFO - Processing file /opt/airflow/dags/dag.py for tasks to queue
[2025-04-05T23:42:43.918+0000] {logging_mixin.py:190} INFO - [2025-04-05T23:42:43.918+0000] {dagbag.py:588} INFO - Filling up the DagBag from /opt/airflow/dags/dag.py
[2025-04-05T23:42:43.925+0000] {logging_mixin.py:190} INFO - [2025-04-05T23:42:43.923+0000] {dagbag.py:387} ERROR - Failed to import: /opt/airflow/dags/dag.py
Traceback (most recent call last):
  File "/home/airflow/.local/lib/python3.12/site-packages/airflow/models/dagbag.py", line 383, in parse
    loader.exec_module(new_module)
  File "<frozen importlib._bootstrap_external>", line 999, in exec_module
  File "<frozen importlib._bootstrap>", line 488, in _call_with_frames_removed
  File "/opt/airflow/dags/dag.py", line 25, in <module>
    storage_client = storage.Client()
                     ^^^^^^^^^^^^^^^^
  File "/home/airflow/.local/lib/python3.12/site-packages/google/cloud/storage/client.py", line 228, in __init__
    super(Client, self).__init__(
  File "/home/airflow/.local/lib/python3.12/site-packages/google/cloud/client/__init__.py", line 320, in __init__
    _ClientProjectMixin.__init__(self, project=project, credentials=credentials)
  File "/home/airflow/.local/lib/python3.12/site-packages/google/cloud/client/__init__.py", line 268, in __init__
    project = self._determine_default(project)
              ^^^^^^^^^^^^^^^^^^^^^^^^^^^^^^^^
  File "/home/airflow/.local/lib/python3.12/site-packages/google/cloud/client/__init__.py", line 287, in _determine_default
    return _determine_default_project(project)
           ^^^^^^^^^^^^^^^^^^^^^^^^^^^^^^^^^^^
  File "/home/airflow/.local/lib/python3.12/site-packages/google/cloud/_helpers/__init__.py", line 152, in _determine_default_project
    _, project = google.auth.default()
                 ^^^^^^^^^^^^^^^^^^^^^
  File "/home/airflow/.local/lib/python3.12/site-packages/google/auth/_default.py", line 685, in default
    credentials, project_id = checker()
                              ^^^^^^^^^
  File "/home/airflow/.local/lib/python3.12/site-packages/google/auth/_default.py", line 678, in <lambda>
    lambda: _get_explicit_environ_credentials(quota_project_id=quota_project_id),
            ^^^^^^^^^^^^^^^^^^^^^^^^^^^^^^^^^^^^^^^^^^^^^^^^^^^^^^^^^^^^^^^^^^^^
  File "/home/airflow/.local/lib/python3.12/site-packages/google/auth/_default.py", line 293, in _get_explicit_environ_credentials
    credentials, project_id = load_credentials_from_file(
                              ^^^^^^^^^^^^^^^^^^^^^^^^^^^
  File "/home/airflow/.local/lib/python3.12/site-packages/google/auth/_default.py", line 125, in load_credentials_from_file
    raise exceptions.DefaultCredentialsError(
google.auth.exceptions.DefaultCredentialsError: File /Users/nd_blaze/nd_blaze.dev/python_dev/DataEngineering/ZoomCamp/taxi-rides-ny-450705-77964478f823.json was not found.
[2025-04-05T23:42:43.926+0000] {processor.py:927} WARNING - No viable dags retrieved from /opt/airflow/dags/dag.py
[2025-04-05T23:42:43.945+0000] {processor.py:208} INFO - Processing /opt/airflow/dags/dag.py took 0.035 seconds
[2025-04-05T23:43:14.424+0000] {processor.py:186} INFO - Started process (PID=111) to work on /opt/airflow/dags/dag.py
[2025-04-05T23:43:14.426+0000] {processor.py:914} INFO - Processing file /opt/airflow/dags/dag.py for tasks to queue
[2025-04-05T23:43:14.429+0000] {logging_mixin.py:190} INFO - [2025-04-05T23:43:14.429+0000] {dagbag.py:588} INFO - Filling up the DagBag from /opt/airflow/dags/dag.py
[2025-04-05T23:43:14.441+0000] {logging_mixin.py:190} INFO - [2025-04-05T23:43:14.436+0000] {dagbag.py:387} ERROR - Failed to import: /opt/airflow/dags/dag.py
Traceback (most recent call last):
  File "/home/airflow/.local/lib/python3.12/site-packages/airflow/models/dagbag.py", line 383, in parse
    loader.exec_module(new_module)
  File "<frozen importlib._bootstrap_external>", line 999, in exec_module
  File "<frozen importlib._bootstrap>", line 488, in _call_with_frames_removed
  File "/opt/airflow/dags/dag.py", line 25, in <module>
    storage_client = storage.Client()
                     ^^^^^^^^^^^^^^^^
  File "/home/airflow/.local/lib/python3.12/site-packages/google/cloud/storage/client.py", line 228, in __init__
    super(Client, self).__init__(
  File "/home/airflow/.local/lib/python3.12/site-packages/google/cloud/client/__init__.py", line 320, in __init__
    _ClientProjectMixin.__init__(self, project=project, credentials=credentials)
  File "/home/airflow/.local/lib/python3.12/site-packages/google/cloud/client/__init__.py", line 268, in __init__
    project = self._determine_default(project)
              ^^^^^^^^^^^^^^^^^^^^^^^^^^^^^^^^
  File "/home/airflow/.local/lib/python3.12/site-packages/google/cloud/client/__init__.py", line 287, in _determine_default
    return _determine_default_project(project)
           ^^^^^^^^^^^^^^^^^^^^^^^^^^^^^^^^^^^
  File "/home/airflow/.local/lib/python3.12/site-packages/google/cloud/_helpers/__init__.py", line 152, in _determine_default_project
    _, project = google.auth.default()
                 ^^^^^^^^^^^^^^^^^^^^^
  File "/home/airflow/.local/lib/python3.12/site-packages/google/auth/_default.py", line 685, in default
    credentials, project_id = checker()
                              ^^^^^^^^^
  File "/home/airflow/.local/lib/python3.12/site-packages/google/auth/_default.py", line 678, in <lambda>
    lambda: _get_explicit_environ_credentials(quota_project_id=quota_project_id),
            ^^^^^^^^^^^^^^^^^^^^^^^^^^^^^^^^^^^^^^^^^^^^^^^^^^^^^^^^^^^^^^^^^^^^
  File "/home/airflow/.local/lib/python3.12/site-packages/google/auth/_default.py", line 293, in _get_explicit_environ_credentials
    credentials, project_id = load_credentials_from_file(
                              ^^^^^^^^^^^^^^^^^^^^^^^^^^^
  File "/home/airflow/.local/lib/python3.12/site-packages/google/auth/_default.py", line 125, in load_credentials_from_file
    raise exceptions.DefaultCredentialsError(
google.auth.exceptions.DefaultCredentialsError: File /Users/nd_blaze/nd_blaze.dev/python_dev/DataEngineering/ZoomCamp/taxi-rides-ny-450705-77964478f823.json was not found.
[2025-04-05T23:43:14.443+0000] {processor.py:927} WARNING - No viable dags retrieved from /opt/airflow/dags/dag.py
[2025-04-05T23:43:14.457+0000] {processor.py:208} INFO - Processing /opt/airflow/dags/dag.py took 0.041 seconds
[2025-04-05T23:43:44.666+0000] {processor.py:186} INFO - Started process (PID=175) to work on /opt/airflow/dags/dag.py
[2025-04-05T23:43:44.667+0000] {processor.py:914} INFO - Processing file /opt/airflow/dags/dag.py for tasks to queue
[2025-04-05T23:43:44.670+0000] {logging_mixin.py:190} INFO - [2025-04-05T23:43:44.670+0000] {dagbag.py:588} INFO - Filling up the DagBag from /opt/airflow/dags/dag.py
[2025-04-05T23:43:44.683+0000] {logging_mixin.py:190} INFO - [2025-04-05T23:43:44.678+0000] {dagbag.py:387} ERROR - Failed to import: /opt/airflow/dags/dag.py
Traceback (most recent call last):
  File "/home/airflow/.local/lib/python3.12/site-packages/airflow/models/dagbag.py", line 383, in parse
    loader.exec_module(new_module)
  File "<frozen importlib._bootstrap_external>", line 999, in exec_module
  File "<frozen importlib._bootstrap>", line 488, in _call_with_frames_removed
  File "/opt/airflow/dags/dag.py", line 25, in <module>
    storage_client = storage.Client()
                     ^^^^^^^^^^^^^^^^
  File "/home/airflow/.local/lib/python3.12/site-packages/google/cloud/storage/client.py", line 228, in __init__
    super(Client, self).__init__(
  File "/home/airflow/.local/lib/python3.12/site-packages/google/cloud/client/__init__.py", line 320, in __init__
    _ClientProjectMixin.__init__(self, project=project, credentials=credentials)
  File "/home/airflow/.local/lib/python3.12/site-packages/google/cloud/client/__init__.py", line 268, in __init__
    project = self._determine_default(project)
              ^^^^^^^^^^^^^^^^^^^^^^^^^^^^^^^^
  File "/home/airflow/.local/lib/python3.12/site-packages/google/cloud/client/__init__.py", line 287, in _determine_default
    return _determine_default_project(project)
           ^^^^^^^^^^^^^^^^^^^^^^^^^^^^^^^^^^^
  File "/home/airflow/.local/lib/python3.12/site-packages/google/cloud/_helpers/__init__.py", line 152, in _determine_default_project
    _, project = google.auth.default()
                 ^^^^^^^^^^^^^^^^^^^^^
  File "/home/airflow/.local/lib/python3.12/site-packages/google/auth/_default.py", line 685, in default
    credentials, project_id = checker()
                              ^^^^^^^^^
  File "/home/airflow/.local/lib/python3.12/site-packages/google/auth/_default.py", line 678, in <lambda>
    lambda: _get_explicit_environ_credentials(quota_project_id=quota_project_id),
            ^^^^^^^^^^^^^^^^^^^^^^^^^^^^^^^^^^^^^^^^^^^^^^^^^^^^^^^^^^^^^^^^^^^^
  File "/home/airflow/.local/lib/python3.12/site-packages/google/auth/_default.py", line 293, in _get_explicit_environ_credentials
    credentials, project_id = load_credentials_from_file(
                              ^^^^^^^^^^^^^^^^^^^^^^^^^^^
  File "/home/airflow/.local/lib/python3.12/site-packages/google/auth/_default.py", line 125, in load_credentials_from_file
    raise exceptions.DefaultCredentialsError(
google.auth.exceptions.DefaultCredentialsError: File /Users/nd_blaze/nd_blaze.dev/python_dev/DataEngineering/ZoomCamp/taxi-rides-ny-450705-77964478f823.json was not found.
[2025-04-05T23:43:44.683+0000] {processor.py:927} WARNING - No viable dags retrieved from /opt/airflow/dags/dag.py
[2025-04-05T23:43:44.697+0000] {processor.py:208} INFO - Processing /opt/airflow/dags/dag.py took 0.039 seconds
[2025-04-05T23:44:14.783+0000] {processor.py:186} INFO - Started process (PID=239) to work on /opt/airflow/dags/dag.py
[2025-04-05T23:44:14.785+0000] {processor.py:914} INFO - Processing file /opt/airflow/dags/dag.py for tasks to queue
[2025-04-05T23:44:14.788+0000] {logging_mixin.py:190} INFO - [2025-04-05T23:44:14.788+0000] {dagbag.py:588} INFO - Filling up the DagBag from /opt/airflow/dags/dag.py
[2025-04-05T23:44:14.807+0000] {logging_mixin.py:190} INFO - [2025-04-05T23:44:14.803+0000] {dagbag.py:387} ERROR - Failed to import: /opt/airflow/dags/dag.py
Traceback (most recent call last):
  File "/home/airflow/.local/lib/python3.12/site-packages/airflow/models/dagbag.py", line 383, in parse
    loader.exec_module(new_module)
  File "<frozen importlib._bootstrap_external>", line 999, in exec_module
  File "<frozen importlib._bootstrap>", line 488, in _call_with_frames_removed
  File "/opt/airflow/dags/dag.py", line 25, in <module>
    storage_client = storage.Client()
                     ^^^^^^^^^^^^^^^^
  File "/home/airflow/.local/lib/python3.12/site-packages/google/cloud/storage/client.py", line 228, in __init__
    super(Client, self).__init__(
  File "/home/airflow/.local/lib/python3.12/site-packages/google/cloud/client/__init__.py", line 320, in __init__
    _ClientProjectMixin.__init__(self, project=project, credentials=credentials)
  File "/home/airflow/.local/lib/python3.12/site-packages/google/cloud/client/__init__.py", line 268, in __init__
    project = self._determine_default(project)
              ^^^^^^^^^^^^^^^^^^^^^^^^^^^^^^^^
  File "/home/airflow/.local/lib/python3.12/site-packages/google/cloud/client/__init__.py", line 287, in _determine_default
    return _determine_default_project(project)
           ^^^^^^^^^^^^^^^^^^^^^^^^^^^^^^^^^^^
  File "/home/airflow/.local/lib/python3.12/site-packages/google/cloud/_helpers/__init__.py", line 152, in _determine_default_project
    _, project = google.auth.default()
                 ^^^^^^^^^^^^^^^^^^^^^
  File "/home/airflow/.local/lib/python3.12/site-packages/google/auth/_default.py", line 685, in default
    credentials, project_id = checker()
                              ^^^^^^^^^
  File "/home/airflow/.local/lib/python3.12/site-packages/google/auth/_default.py", line 678, in <lambda>
    lambda: _get_explicit_environ_credentials(quota_project_id=quota_project_id),
            ^^^^^^^^^^^^^^^^^^^^^^^^^^^^^^^^^^^^^^^^^^^^^^^^^^^^^^^^^^^^^^^^^^^^
  File "/home/airflow/.local/lib/python3.12/site-packages/google/auth/_default.py", line 293, in _get_explicit_environ_credentials
    credentials, project_id = load_credentials_from_file(
                              ^^^^^^^^^^^^^^^^^^^^^^^^^^^
  File "/home/airflow/.local/lib/python3.12/site-packages/google/auth/_default.py", line 125, in load_credentials_from_file
    raise exceptions.DefaultCredentialsError(
google.auth.exceptions.DefaultCredentialsError: File /Users/nd_blaze/nd_blaze.dev/python_dev/DataEngineering/ZoomCamp/taxi-rides-ny-450705-77964478f823.json was not found.
[2025-04-05T23:44:14.810+0000] {processor.py:927} WARNING - No viable dags retrieved from /opt/airflow/dags/dag.py
[2025-04-05T23:44:14.828+0000] {processor.py:208} INFO - Processing /opt/airflow/dags/dag.py took 0.055 seconds
[2025-04-05T23:44:48.811+0000] {processor.py:186} INFO - Started process (PID=41) to work on /opt/airflow/dags/dag.py
[2025-04-05T23:44:48.812+0000] {processor.py:914} INFO - Processing file /opt/airflow/dags/dag.py for tasks to queue
[2025-04-05T23:44:48.815+0000] {logging_mixin.py:190} INFO - [2025-04-05T23:44:48.814+0000] {dagbag.py:588} INFO - Filling up the DagBag from /opt/airflow/dags/dag.py
[2025-04-05T23:44:48.825+0000] {logging_mixin.py:190} INFO - [2025-04-05T23:44:48.823+0000] {dagbag.py:387} ERROR - Failed to import: /opt/airflow/dags/dag.py
Traceback (most recent call last):
  File "/home/airflow/.local/lib/python3.12/site-packages/airflow/models/dagbag.py", line 383, in parse
    loader.exec_module(new_module)
  File "<frozen importlib._bootstrap_external>", line 999, in exec_module
  File "<frozen importlib._bootstrap>", line 488, in _call_with_frames_removed
  File "/opt/airflow/dags/dag.py", line 25, in <module>
    storage_client = storage.Client()
                     ^^^^^^^^^^^^^^^^
  File "/home/airflow/.local/lib/python3.12/site-packages/google/cloud/storage/client.py", line 228, in __init__
    super(Client, self).__init__(
  File "/home/airflow/.local/lib/python3.12/site-packages/google/cloud/client/__init__.py", line 320, in __init__
    _ClientProjectMixin.__init__(self, project=project, credentials=credentials)
  File "/home/airflow/.local/lib/python3.12/site-packages/google/cloud/client/__init__.py", line 268, in __init__
    project = self._determine_default(project)
              ^^^^^^^^^^^^^^^^^^^^^^^^^^^^^^^^
  File "/home/airflow/.local/lib/python3.12/site-packages/google/cloud/client/__init__.py", line 287, in _determine_default
    return _determine_default_project(project)
           ^^^^^^^^^^^^^^^^^^^^^^^^^^^^^^^^^^^
  File "/home/airflow/.local/lib/python3.12/site-packages/google/cloud/_helpers/__init__.py", line 152, in _determine_default_project
    _, project = google.auth.default()
                 ^^^^^^^^^^^^^^^^^^^^^
  File "/home/airflow/.local/lib/python3.12/site-packages/google/auth/_default.py", line 685, in default
    credentials, project_id = checker()
                              ^^^^^^^^^
  File "/home/airflow/.local/lib/python3.12/site-packages/google/auth/_default.py", line 678, in <lambda>
    lambda: _get_explicit_environ_credentials(quota_project_id=quota_project_id),
            ^^^^^^^^^^^^^^^^^^^^^^^^^^^^^^^^^^^^^^^^^^^^^^^^^^^^^^^^^^^^^^^^^^^^
  File "/home/airflow/.local/lib/python3.12/site-packages/google/auth/_default.py", line 293, in _get_explicit_environ_credentials
    credentials, project_id = load_credentials_from_file(
                              ^^^^^^^^^^^^^^^^^^^^^^^^^^^
  File "/home/airflow/.local/lib/python3.12/site-packages/google/auth/_default.py", line 125, in load_credentials_from_file
    raise exceptions.DefaultCredentialsError(
google.auth.exceptions.DefaultCredentialsError: File /Users/nd_blaze/nd_blaze.dev/python_dev/DataEngineering/ZoomCamp/taxi-rides-ny-450705-77964478f823.json was not found.
[2025-04-05T23:44:48.829+0000] {processor.py:927} WARNING - No viable dags retrieved from /opt/airflow/dags/dag.py
[2025-04-05T23:44:48.856+0000] {processor.py:208} INFO - Processing /opt/airflow/dags/dag.py took 0.052 seconds
[2025-04-05T23:45:19.266+0000] {processor.py:186} INFO - Started process (PID=104) to work on /opt/airflow/dags/dag.py
[2025-04-05T23:45:19.268+0000] {processor.py:914} INFO - Processing file /opt/airflow/dags/dag.py for tasks to queue
[2025-04-05T23:45:19.270+0000] {logging_mixin.py:190} INFO - [2025-04-05T23:45:19.270+0000] {dagbag.py:588} INFO - Filling up the DagBag from /opt/airflow/dags/dag.py
[2025-04-05T23:45:19.275+0000] {logging_mixin.py:190} INFO - [2025-04-05T23:45:19.273+0000] {dagbag.py:387} ERROR - Failed to import: /opt/airflow/dags/dag.py
Traceback (most recent call last):
  File "/home/airflow/.local/lib/python3.12/site-packages/airflow/models/dagbag.py", line 383, in parse
    loader.exec_module(new_module)
  File "<frozen importlib._bootstrap_external>", line 999, in exec_module
  File "<frozen importlib._bootstrap>", line 488, in _call_with_frames_removed
  File "/opt/airflow/dags/dag.py", line 25, in <module>
    storage_client = storage.Client()
                     ^^^^^^^^^^^^^^^^
  File "/home/airflow/.local/lib/python3.12/site-packages/google/cloud/storage/client.py", line 228, in __init__
    super(Client, self).__init__(
  File "/home/airflow/.local/lib/python3.12/site-packages/google/cloud/client/__init__.py", line 320, in __init__
    _ClientProjectMixin.__init__(self, project=project, credentials=credentials)
  File "/home/airflow/.local/lib/python3.12/site-packages/google/cloud/client/__init__.py", line 268, in __init__
    project = self._determine_default(project)
              ^^^^^^^^^^^^^^^^^^^^^^^^^^^^^^^^
  File "/home/airflow/.local/lib/python3.12/site-packages/google/cloud/client/__init__.py", line 287, in _determine_default
    return _determine_default_project(project)
           ^^^^^^^^^^^^^^^^^^^^^^^^^^^^^^^^^^^
  File "/home/airflow/.local/lib/python3.12/site-packages/google/cloud/_helpers/__init__.py", line 152, in _determine_default_project
    _, project = google.auth.default()
                 ^^^^^^^^^^^^^^^^^^^^^
  File "/home/airflow/.local/lib/python3.12/site-packages/google/auth/_default.py", line 685, in default
    credentials, project_id = checker()
                              ^^^^^^^^^
  File "/home/airflow/.local/lib/python3.12/site-packages/google/auth/_default.py", line 678, in <lambda>
    lambda: _get_explicit_environ_credentials(quota_project_id=quota_project_id),
            ^^^^^^^^^^^^^^^^^^^^^^^^^^^^^^^^^^^^^^^^^^^^^^^^^^^^^^^^^^^^^^^^^^^^
  File "/home/airflow/.local/lib/python3.12/site-packages/google/auth/_default.py", line 293, in _get_explicit_environ_credentials
    credentials, project_id = load_credentials_from_file(
                              ^^^^^^^^^^^^^^^^^^^^^^^^^^^
  File "/home/airflow/.local/lib/python3.12/site-packages/google/auth/_default.py", line 125, in load_credentials_from_file
    raise exceptions.DefaultCredentialsError(
google.auth.exceptions.DefaultCredentialsError: File /Users/nd_blaze/nd_blaze.dev/python_dev/DataEngineering/ZoomCamp/taxi-rides-ny-450705-77964478f823.json was not found.
[2025-04-05T23:45:19.275+0000] {processor.py:927} WARNING - No viable dags retrieved from /opt/airflow/dags/dag.py
[2025-04-05T23:45:19.290+0000] {processor.py:208} INFO - Processing /opt/airflow/dags/dag.py took 0.029 seconds
[2025-04-05T23:45:49.387+0000] {processor.py:186} INFO - Started process (PID=168) to work on /opt/airflow/dags/dag.py
[2025-04-05T23:45:49.389+0000] {processor.py:914} INFO - Processing file /opt/airflow/dags/dag.py for tasks to queue
[2025-04-05T23:45:49.392+0000] {logging_mixin.py:190} INFO - [2025-04-05T23:45:49.392+0000] {dagbag.py:588} INFO - Filling up the DagBag from /opt/airflow/dags/dag.py
[2025-04-05T23:45:49.398+0000] {logging_mixin.py:190} INFO - [2025-04-05T23:45:49.396+0000] {dagbag.py:387} ERROR - Failed to import: /opt/airflow/dags/dag.py
Traceback (most recent call last):
  File "/home/airflow/.local/lib/python3.12/site-packages/airflow/models/dagbag.py", line 383, in parse
    loader.exec_module(new_module)
  File "<frozen importlib._bootstrap_external>", line 999, in exec_module
  File "<frozen importlib._bootstrap>", line 488, in _call_with_frames_removed
  File "/opt/airflow/dags/dag.py", line 25, in <module>
    storage_client = storage.Client()
                     ^^^^^^^^^^^^^^^^
  File "/home/airflow/.local/lib/python3.12/site-packages/google/cloud/storage/client.py", line 228, in __init__
    super(Client, self).__init__(
  File "/home/airflow/.local/lib/python3.12/site-packages/google/cloud/client/__init__.py", line 320, in __init__
    _ClientProjectMixin.__init__(self, project=project, credentials=credentials)
  File "/home/airflow/.local/lib/python3.12/site-packages/google/cloud/client/__init__.py", line 268, in __init__
    project = self._determine_default(project)
              ^^^^^^^^^^^^^^^^^^^^^^^^^^^^^^^^
  File "/home/airflow/.local/lib/python3.12/site-packages/google/cloud/client/__init__.py", line 287, in _determine_default
    return _determine_default_project(project)
           ^^^^^^^^^^^^^^^^^^^^^^^^^^^^^^^^^^^
  File "/home/airflow/.local/lib/python3.12/site-packages/google/cloud/_helpers/__init__.py", line 152, in _determine_default_project
    _, project = google.auth.default()
                 ^^^^^^^^^^^^^^^^^^^^^
  File "/home/airflow/.local/lib/python3.12/site-packages/google/auth/_default.py", line 685, in default
    credentials, project_id = checker()
                              ^^^^^^^^^
  File "/home/airflow/.local/lib/python3.12/site-packages/google/auth/_default.py", line 678, in <lambda>
    lambda: _get_explicit_environ_credentials(quota_project_id=quota_project_id),
            ^^^^^^^^^^^^^^^^^^^^^^^^^^^^^^^^^^^^^^^^^^^^^^^^^^^^^^^^^^^^^^^^^^^^
  File "/home/airflow/.local/lib/python3.12/site-packages/google/auth/_default.py", line 293, in _get_explicit_environ_credentials
    credentials, project_id = load_credentials_from_file(
                              ^^^^^^^^^^^^^^^^^^^^^^^^^^^
  File "/home/airflow/.local/lib/python3.12/site-packages/google/auth/_default.py", line 125, in load_credentials_from_file
    raise exceptions.DefaultCredentialsError(
google.auth.exceptions.DefaultCredentialsError: File /Users/nd_blaze/nd_blaze.dev/python_dev/DataEngineering/ZoomCamp/taxi-rides-ny-450705-77964478f823.json was not found.
[2025-04-05T23:45:49.398+0000] {processor.py:927} WARNING - No viable dags retrieved from /opt/airflow/dags/dag.py
[2025-04-05T23:45:49.411+0000] {processor.py:208} INFO - Processing /opt/airflow/dags/dag.py took 0.031 seconds
[2025-04-05T23:46:19.568+0000] {processor.py:186} INFO - Started process (PID=232) to work on /opt/airflow/dags/dag.py
[2025-04-05T23:46:19.570+0000] {processor.py:914} INFO - Processing file /opt/airflow/dags/dag.py for tasks to queue
[2025-04-05T23:46:19.574+0000] {logging_mixin.py:190} INFO - [2025-04-05T23:46:19.573+0000] {dagbag.py:588} INFO - Filling up the DagBag from /opt/airflow/dags/dag.py
[2025-04-05T23:46:19.589+0000] {logging_mixin.py:190} INFO - [2025-04-05T23:46:19.586+0000] {dagbag.py:387} ERROR - Failed to import: /opt/airflow/dags/dag.py
Traceback (most recent call last):
  File "/home/airflow/.local/lib/python3.12/site-packages/airflow/models/dagbag.py", line 383, in parse
    loader.exec_module(new_module)
  File "<frozen importlib._bootstrap_external>", line 999, in exec_module
  File "<frozen importlib._bootstrap>", line 488, in _call_with_frames_removed
  File "/opt/airflow/dags/dag.py", line 25, in <module>
    storage_client = storage.Client()
                     ^^^^^^^^^^^^^^^^
  File "/home/airflow/.local/lib/python3.12/site-packages/google/cloud/storage/client.py", line 228, in __init__
    super(Client, self).__init__(
  File "/home/airflow/.local/lib/python3.12/site-packages/google/cloud/client/__init__.py", line 320, in __init__
    _ClientProjectMixin.__init__(self, project=project, credentials=credentials)
  File "/home/airflow/.local/lib/python3.12/site-packages/google/cloud/client/__init__.py", line 268, in __init__
    project = self._determine_default(project)
              ^^^^^^^^^^^^^^^^^^^^^^^^^^^^^^^^
  File "/home/airflow/.local/lib/python3.12/site-packages/google/cloud/client/__init__.py", line 287, in _determine_default
    return _determine_default_project(project)
           ^^^^^^^^^^^^^^^^^^^^^^^^^^^^^^^^^^^
  File "/home/airflow/.local/lib/python3.12/site-packages/google/cloud/_helpers/__init__.py", line 152, in _determine_default_project
    _, project = google.auth.default()
                 ^^^^^^^^^^^^^^^^^^^^^
  File "/home/airflow/.local/lib/python3.12/site-packages/google/auth/_default.py", line 685, in default
    credentials, project_id = checker()
                              ^^^^^^^^^
  File "/home/airflow/.local/lib/python3.12/site-packages/google/auth/_default.py", line 678, in <lambda>
    lambda: _get_explicit_environ_credentials(quota_project_id=quota_project_id),
            ^^^^^^^^^^^^^^^^^^^^^^^^^^^^^^^^^^^^^^^^^^^^^^^^^^^^^^^^^^^^^^^^^^^^
  File "/home/airflow/.local/lib/python3.12/site-packages/google/auth/_default.py", line 293, in _get_explicit_environ_credentials
    credentials, project_id = load_credentials_from_file(
                              ^^^^^^^^^^^^^^^^^^^^^^^^^^^
  File "/home/airflow/.local/lib/python3.12/site-packages/google/auth/_default.py", line 125, in load_credentials_from_file
    raise exceptions.DefaultCredentialsError(
google.auth.exceptions.DefaultCredentialsError: File /Users/nd_blaze/nd_blaze.dev/python_dev/DataEngineering/ZoomCamp/taxi-rides-ny-450705-77964478f823.json was not found.
[2025-04-05T23:46:19.589+0000] {processor.py:927} WARNING - No viable dags retrieved from /opt/airflow/dags/dag.py
[2025-04-05T23:46:19.617+0000] {processor.py:208} INFO - Processing /opt/airflow/dags/dag.py took 0.065 seconds
[2025-04-05T23:46:40.983+0000] {processor.py:186} INFO - Started process (PID=40) to work on /opt/airflow/dags/dag.py
[2025-04-05T23:46:40.985+0000] {processor.py:914} INFO - Processing file /opt/airflow/dags/dag.py for tasks to queue
[2025-04-05T23:46:40.991+0000] {logging_mixin.py:190} INFO - [2025-04-05T23:46:40.990+0000] {dagbag.py:588} INFO - Filling up the DagBag from /opt/airflow/dags/dag.py
[2025-04-05T23:46:40.999+0000] {logging_mixin.py:190} INFO - [2025-04-05T23:46:40.995+0000] {dagbag.py:387} ERROR - Failed to import: /opt/airflow/dags/dag.py
Traceback (most recent call last):
  File "/home/airflow/.local/lib/python3.12/site-packages/airflow/models/dagbag.py", line 383, in parse
    loader.exec_module(new_module)
  File "<frozen importlib._bootstrap_external>", line 999, in exec_module
  File "<frozen importlib._bootstrap>", line 488, in _call_with_frames_removed
  File "/opt/airflow/dags/dag.py", line 25, in <module>
    storage_client = storage.Client()
                     ^^^^^^^^^^^^^^^^
  File "/home/airflow/.local/lib/python3.12/site-packages/google/cloud/storage/client.py", line 228, in __init__
    super(Client, self).__init__(
  File "/home/airflow/.local/lib/python3.12/site-packages/google/cloud/client/__init__.py", line 320, in __init__
    _ClientProjectMixin.__init__(self, project=project, credentials=credentials)
  File "/home/airflow/.local/lib/python3.12/site-packages/google/cloud/client/__init__.py", line 268, in __init__
    project = self._determine_default(project)
              ^^^^^^^^^^^^^^^^^^^^^^^^^^^^^^^^
  File "/home/airflow/.local/lib/python3.12/site-packages/google/cloud/client/__init__.py", line 287, in _determine_default
    return _determine_default_project(project)
           ^^^^^^^^^^^^^^^^^^^^^^^^^^^^^^^^^^^
  File "/home/airflow/.local/lib/python3.12/site-packages/google/cloud/_helpers/__init__.py", line 152, in _determine_default_project
    _, project = google.auth.default()
                 ^^^^^^^^^^^^^^^^^^^^^
  File "/home/airflow/.local/lib/python3.12/site-packages/google/auth/_default.py", line 685, in default
    credentials, project_id = checker()
                              ^^^^^^^^^
  File "/home/airflow/.local/lib/python3.12/site-packages/google/auth/_default.py", line 678, in <lambda>
    lambda: _get_explicit_environ_credentials(quota_project_id=quota_project_id),
            ^^^^^^^^^^^^^^^^^^^^^^^^^^^^^^^^^^^^^^^^^^^^^^^^^^^^^^^^^^^^^^^^^^^^
  File "/home/airflow/.local/lib/python3.12/site-packages/google/auth/_default.py", line 293, in _get_explicit_environ_credentials
    credentials, project_id = load_credentials_from_file(
                              ^^^^^^^^^^^^^^^^^^^^^^^^^^^
  File "/home/airflow/.local/lib/python3.12/site-packages/google/auth/_default.py", line 125, in load_credentials_from_file
    raise exceptions.DefaultCredentialsError(
google.auth.exceptions.DefaultCredentialsError: File /Users/nd_blaze/nd_blaze.dev/python_dev/DataEngineering/ZoomCamp/taxi-rides-ny-450705-77964478f823.json was not found.
[2025-04-05T23:46:41.000+0000] {processor.py:927} WARNING - No viable dags retrieved from /opt/airflow/dags/dag.py
[2025-04-05T23:46:41.025+0000] {processor.py:208} INFO - Processing /opt/airflow/dags/dag.py took 0.050 seconds
[2025-04-05T23:47:11.313+0000] {processor.py:186} INFO - Started process (PID=104) to work on /opt/airflow/dags/dag.py
[2025-04-05T23:47:11.316+0000] {processor.py:914} INFO - Processing file /opt/airflow/dags/dag.py for tasks to queue
[2025-04-05T23:47:11.325+0000] {logging_mixin.py:190} INFO - [2025-04-05T23:47:11.324+0000] {dagbag.py:588} INFO - Filling up the DagBag from /opt/airflow/dags/dag.py
[2025-04-05T23:47:11.331+0000] {logging_mixin.py:190} INFO - [2025-04-05T23:47:11.329+0000] {dagbag.py:387} ERROR - Failed to import: /opt/airflow/dags/dag.py
Traceback (most recent call last):
  File "/home/airflow/.local/lib/python3.12/site-packages/airflow/models/dagbag.py", line 383, in parse
    loader.exec_module(new_module)
  File "<frozen importlib._bootstrap_external>", line 999, in exec_module
  File "<frozen importlib._bootstrap>", line 488, in _call_with_frames_removed
  File "/opt/airflow/dags/dag.py", line 25, in <module>
    storage_client = storage.Client()
                     ^^^^^^^^^^^^^^^^
  File "/home/airflow/.local/lib/python3.12/site-packages/google/cloud/storage/client.py", line 228, in __init__
    super(Client, self).__init__(
  File "/home/airflow/.local/lib/python3.12/site-packages/google/cloud/client/__init__.py", line 320, in __init__
    _ClientProjectMixin.__init__(self, project=project, credentials=credentials)
  File "/home/airflow/.local/lib/python3.12/site-packages/google/cloud/client/__init__.py", line 268, in __init__
    project = self._determine_default(project)
              ^^^^^^^^^^^^^^^^^^^^^^^^^^^^^^^^
  File "/home/airflow/.local/lib/python3.12/site-packages/google/cloud/client/__init__.py", line 287, in _determine_default
    return _determine_default_project(project)
           ^^^^^^^^^^^^^^^^^^^^^^^^^^^^^^^^^^^
  File "/home/airflow/.local/lib/python3.12/site-packages/google/cloud/_helpers/__init__.py", line 152, in _determine_default_project
    _, project = google.auth.default()
                 ^^^^^^^^^^^^^^^^^^^^^
  File "/home/airflow/.local/lib/python3.12/site-packages/google/auth/_default.py", line 685, in default
    credentials, project_id = checker()
                              ^^^^^^^^^
  File "/home/airflow/.local/lib/python3.12/site-packages/google/auth/_default.py", line 678, in <lambda>
    lambda: _get_explicit_environ_credentials(quota_project_id=quota_project_id),
            ^^^^^^^^^^^^^^^^^^^^^^^^^^^^^^^^^^^^^^^^^^^^^^^^^^^^^^^^^^^^^^^^^^^^
  File "/home/airflow/.local/lib/python3.12/site-packages/google/auth/_default.py", line 293, in _get_explicit_environ_credentials
    credentials, project_id = load_credentials_from_file(
                              ^^^^^^^^^^^^^^^^^^^^^^^^^^^
  File "/home/airflow/.local/lib/python3.12/site-packages/google/auth/_default.py", line 125, in load_credentials_from_file
    raise exceptions.DefaultCredentialsError(
google.auth.exceptions.DefaultCredentialsError: File /Users/nd_blaze/nd_blaze.dev/python_dev/DataEngineering/ZoomCamp/taxi-rides-ny-450705-77964478f823.json was not found.
[2025-04-05T23:47:11.332+0000] {processor.py:927} WARNING - No viable dags retrieved from /opt/airflow/dags/dag.py
[2025-04-05T23:47:11.351+0000] {processor.py:208} INFO - Processing /opt/airflow/dags/dag.py took 0.042 seconds
[2025-04-05T23:47:41.783+0000] {processor.py:186} INFO - Started process (PID=167) to work on /opt/airflow/dags/dag.py
[2025-04-05T23:47:41.786+0000] {processor.py:914} INFO - Processing file /opt/airflow/dags/dag.py for tasks to queue
[2025-04-05T23:47:41.791+0000] {logging_mixin.py:190} INFO - [2025-04-05T23:47:41.790+0000] {dagbag.py:588} INFO - Filling up the DagBag from /opt/airflow/dags/dag.py
[2025-04-05T23:47:41.801+0000] {logging_mixin.py:190} INFO - [2025-04-05T23:47:41.798+0000] {dagbag.py:387} ERROR - Failed to import: /opt/airflow/dags/dag.py
Traceback (most recent call last):
  File "/home/airflow/.local/lib/python3.12/site-packages/airflow/models/dagbag.py", line 383, in parse
    loader.exec_module(new_module)
  File "<frozen importlib._bootstrap_external>", line 999, in exec_module
  File "<frozen importlib._bootstrap>", line 488, in _call_with_frames_removed
  File "/opt/airflow/dags/dag.py", line 25, in <module>
    storage_client = storage.Client()
                     ^^^^^^^^^^^^^^^^
  File "/home/airflow/.local/lib/python3.12/site-packages/google/cloud/storage/client.py", line 228, in __init__
    super(Client, self).__init__(
  File "/home/airflow/.local/lib/python3.12/site-packages/google/cloud/client/__init__.py", line 320, in __init__
    _ClientProjectMixin.__init__(self, project=project, credentials=credentials)
  File "/home/airflow/.local/lib/python3.12/site-packages/google/cloud/client/__init__.py", line 268, in __init__
    project = self._determine_default(project)
              ^^^^^^^^^^^^^^^^^^^^^^^^^^^^^^^^
  File "/home/airflow/.local/lib/python3.12/site-packages/google/cloud/client/__init__.py", line 287, in _determine_default
    return _determine_default_project(project)
           ^^^^^^^^^^^^^^^^^^^^^^^^^^^^^^^^^^^
  File "/home/airflow/.local/lib/python3.12/site-packages/google/cloud/_helpers/__init__.py", line 152, in _determine_default_project
    _, project = google.auth.default()
                 ^^^^^^^^^^^^^^^^^^^^^
  File "/home/airflow/.local/lib/python3.12/site-packages/google/auth/_default.py", line 685, in default
    credentials, project_id = checker()
                              ^^^^^^^^^
  File "/home/airflow/.local/lib/python3.12/site-packages/google/auth/_default.py", line 678, in <lambda>
    lambda: _get_explicit_environ_credentials(quota_project_id=quota_project_id),
            ^^^^^^^^^^^^^^^^^^^^^^^^^^^^^^^^^^^^^^^^^^^^^^^^^^^^^^^^^^^^^^^^^^^^
  File "/home/airflow/.local/lib/python3.12/site-packages/google/auth/_default.py", line 293, in _get_explicit_environ_credentials
    credentials, project_id = load_credentials_from_file(
                              ^^^^^^^^^^^^^^^^^^^^^^^^^^^
  File "/home/airflow/.local/lib/python3.12/site-packages/google/auth/_default.py", line 125, in load_credentials_from_file
    raise exceptions.DefaultCredentialsError(
google.auth.exceptions.DefaultCredentialsError: File /Users/nd_blaze/nd_blaze.dev/python_dev/DataEngineering/ZoomCamp/taxi-rides-ny-450705-77964478f823.json was not found.
[2025-04-05T23:47:41.802+0000] {processor.py:927} WARNING - No viable dags retrieved from /opt/airflow/dags/dag.py
[2025-04-05T23:47:41.822+0000] {processor.py:208} INFO - Processing /opt/airflow/dags/dag.py took 0.048 seconds
[2025-04-05T23:48:11.949+0000] {processor.py:186} INFO - Started process (PID=231) to work on /opt/airflow/dags/dag.py
[2025-04-05T23:48:11.950+0000] {processor.py:914} INFO - Processing file /opt/airflow/dags/dag.py for tasks to queue
[2025-04-05T23:48:11.953+0000] {logging_mixin.py:190} INFO - [2025-04-05T23:48:11.952+0000] {dagbag.py:588} INFO - Filling up the DagBag from /opt/airflow/dags/dag.py
[2025-04-05T23:48:11.964+0000] {logging_mixin.py:190} INFO - [2025-04-05T23:48:11.962+0000] {dagbag.py:387} ERROR - Failed to import: /opt/airflow/dags/dag.py
Traceback (most recent call last):
  File "/home/airflow/.local/lib/python3.12/site-packages/airflow/models/dagbag.py", line 383, in parse
    loader.exec_module(new_module)
  File "<frozen importlib._bootstrap_external>", line 999, in exec_module
  File "<frozen importlib._bootstrap>", line 488, in _call_with_frames_removed
  File "/opt/airflow/dags/dag.py", line 25, in <module>
    storage_client = storage.Client()
                     ^^^^^^^^^^^^^^^^
  File "/home/airflow/.local/lib/python3.12/site-packages/google/cloud/storage/client.py", line 228, in __init__
    super(Client, self).__init__(
  File "/home/airflow/.local/lib/python3.12/site-packages/google/cloud/client/__init__.py", line 320, in __init__
    _ClientProjectMixin.__init__(self, project=project, credentials=credentials)
  File "/home/airflow/.local/lib/python3.12/site-packages/google/cloud/client/__init__.py", line 268, in __init__
    project = self._determine_default(project)
              ^^^^^^^^^^^^^^^^^^^^^^^^^^^^^^^^
  File "/home/airflow/.local/lib/python3.12/site-packages/google/cloud/client/__init__.py", line 287, in _determine_default
    return _determine_default_project(project)
           ^^^^^^^^^^^^^^^^^^^^^^^^^^^^^^^^^^^
  File "/home/airflow/.local/lib/python3.12/site-packages/google/cloud/_helpers/__init__.py", line 152, in _determine_default_project
    _, project = google.auth.default()
                 ^^^^^^^^^^^^^^^^^^^^^
  File "/home/airflow/.local/lib/python3.12/site-packages/google/auth/_default.py", line 685, in default
    credentials, project_id = checker()
                              ^^^^^^^^^
  File "/home/airflow/.local/lib/python3.12/site-packages/google/auth/_default.py", line 678, in <lambda>
    lambda: _get_explicit_environ_credentials(quota_project_id=quota_project_id),
            ^^^^^^^^^^^^^^^^^^^^^^^^^^^^^^^^^^^^^^^^^^^^^^^^^^^^^^^^^^^^^^^^^^^^
  File "/home/airflow/.local/lib/python3.12/site-packages/google/auth/_default.py", line 293, in _get_explicit_environ_credentials
    credentials, project_id = load_credentials_from_file(
                              ^^^^^^^^^^^^^^^^^^^^^^^^^^^
  File "/home/airflow/.local/lib/python3.12/site-packages/google/auth/_default.py", line 125, in load_credentials_from_file
    raise exceptions.DefaultCredentialsError(
google.auth.exceptions.DefaultCredentialsError: File /Users/nd_blaze/nd_blaze.dev/python_dev/DataEngineering/ZoomCamp/taxi-rides-ny-450705-77964478f823.json was not found.
[2025-04-05T23:48:11.965+0000] {processor.py:927} WARNING - No viable dags retrieved from /opt/airflow/dags/dag.py
[2025-04-05T23:48:11.981+0000] {processor.py:208} INFO - Processing /opt/airflow/dags/dag.py took 0.041 seconds
[2025-04-05T23:48:42.391+0000] {processor.py:186} INFO - Started process (PID=295) to work on /opt/airflow/dags/dag.py
[2025-04-05T23:48:42.394+0000] {processor.py:914} INFO - Processing file /opt/airflow/dags/dag.py for tasks to queue
[2025-04-05T23:48:42.397+0000] {logging_mixin.py:190} INFO - [2025-04-05T23:48:42.397+0000] {dagbag.py:588} INFO - Filling up the DagBag from /opt/airflow/dags/dag.py
[2025-04-05T23:48:42.411+0000] {logging_mixin.py:190} INFO - [2025-04-05T23:48:42.408+0000] {dagbag.py:387} ERROR - Failed to import: /opt/airflow/dags/dag.py
Traceback (most recent call last):
  File "/home/airflow/.local/lib/python3.12/site-packages/airflow/models/dagbag.py", line 383, in parse
    loader.exec_module(new_module)
  File "<frozen importlib._bootstrap_external>", line 999, in exec_module
  File "<frozen importlib._bootstrap>", line 488, in _call_with_frames_removed
  File "/opt/airflow/dags/dag.py", line 25, in <module>
    storage_client = storage.Client()
                     ^^^^^^^^^^^^^^^^
  File "/home/airflow/.local/lib/python3.12/site-packages/google/cloud/storage/client.py", line 228, in __init__
    super(Client, self).__init__(
  File "/home/airflow/.local/lib/python3.12/site-packages/google/cloud/client/__init__.py", line 320, in __init__
    _ClientProjectMixin.__init__(self, project=project, credentials=credentials)
  File "/home/airflow/.local/lib/python3.12/site-packages/google/cloud/client/__init__.py", line 268, in __init__
    project = self._determine_default(project)
              ^^^^^^^^^^^^^^^^^^^^^^^^^^^^^^^^
  File "/home/airflow/.local/lib/python3.12/site-packages/google/cloud/client/__init__.py", line 287, in _determine_default
    return _determine_default_project(project)
           ^^^^^^^^^^^^^^^^^^^^^^^^^^^^^^^^^^^
  File "/home/airflow/.local/lib/python3.12/site-packages/google/cloud/_helpers/__init__.py", line 152, in _determine_default_project
    _, project = google.auth.default()
                 ^^^^^^^^^^^^^^^^^^^^^
  File "/home/airflow/.local/lib/python3.12/site-packages/google/auth/_default.py", line 685, in default
    credentials, project_id = checker()
                              ^^^^^^^^^
  File "/home/airflow/.local/lib/python3.12/site-packages/google/auth/_default.py", line 678, in <lambda>
    lambda: _get_explicit_environ_credentials(quota_project_id=quota_project_id),
            ^^^^^^^^^^^^^^^^^^^^^^^^^^^^^^^^^^^^^^^^^^^^^^^^^^^^^^^^^^^^^^^^^^^^
  File "/home/airflow/.local/lib/python3.12/site-packages/google/auth/_default.py", line 293, in _get_explicit_environ_credentials
    credentials, project_id = load_credentials_from_file(
                              ^^^^^^^^^^^^^^^^^^^^^^^^^^^
  File "/home/airflow/.local/lib/python3.12/site-packages/google/auth/_default.py", line 125, in load_credentials_from_file
    raise exceptions.DefaultCredentialsError(
google.auth.exceptions.DefaultCredentialsError: File /Users/nd_blaze/nd_blaze.dev/python_dev/DataEngineering/ZoomCamp/taxi-rides-ny-450705-77964478f823.json was not found.
[2025-04-05T23:48:42.412+0000] {processor.py:927} WARNING - No viable dags retrieved from /opt/airflow/dags/dag.py
[2025-04-05T23:48:42.441+0000] {processor.py:208} INFO - Processing /opt/airflow/dags/dag.py took 0.058 seconds
[2025-04-05T23:49:28.819+0000] {processor.py:186} INFO - Started process (PID=42) to work on /opt/airflow/dags/dag.py
[2025-04-05T23:49:28.821+0000] {processor.py:914} INFO - Processing file /opt/airflow/dags/dag.py for tasks to queue
[2025-04-05T23:49:28.823+0000] {logging_mixin.py:190} INFO - [2025-04-05T23:49:28.823+0000] {dagbag.py:588} INFO - Filling up the DagBag from /opt/airflow/dags/dag.py
[2025-04-05T23:49:28.833+0000] {logging_mixin.py:190} INFO - [2025-04-05T23:49:28.829+0000] {dagbag.py:387} ERROR - Failed to import: /opt/airflow/dags/dag.py
Traceback (most recent call last):
  File "/home/airflow/.local/lib/python3.12/site-packages/airflow/models/dagbag.py", line 383, in parse
    loader.exec_module(new_module)
  File "<frozen importlib._bootstrap_external>", line 999, in exec_module
  File "<frozen importlib._bootstrap>", line 488, in _call_with_frames_removed
  File "/opt/airflow/dags/dag.py", line 25, in <module>
    storage_client = storage.Client()
                     ^^^^^^^^^^^^^^^^
  File "/home/airflow/.local/lib/python3.12/site-packages/google/cloud/storage/client.py", line 228, in __init__
    super(Client, self).__init__(
  File "/home/airflow/.local/lib/python3.12/site-packages/google/cloud/client/__init__.py", line 320, in __init__
    _ClientProjectMixin.__init__(self, project=project, credentials=credentials)
  File "/home/airflow/.local/lib/python3.12/site-packages/google/cloud/client/__init__.py", line 268, in __init__
    project = self._determine_default(project)
              ^^^^^^^^^^^^^^^^^^^^^^^^^^^^^^^^
  File "/home/airflow/.local/lib/python3.12/site-packages/google/cloud/client/__init__.py", line 287, in _determine_default
    return _determine_default_project(project)
           ^^^^^^^^^^^^^^^^^^^^^^^^^^^^^^^^^^^
  File "/home/airflow/.local/lib/python3.12/site-packages/google/cloud/_helpers/__init__.py", line 152, in _determine_default_project
    _, project = google.auth.default()
                 ^^^^^^^^^^^^^^^^^^^^^
  File "/home/airflow/.local/lib/python3.12/site-packages/google/auth/_default.py", line 685, in default
    credentials, project_id = checker()
                              ^^^^^^^^^
  File "/home/airflow/.local/lib/python3.12/site-packages/google/auth/_default.py", line 678, in <lambda>
    lambda: _get_explicit_environ_credentials(quota_project_id=quota_project_id),
            ^^^^^^^^^^^^^^^^^^^^^^^^^^^^^^^^^^^^^^^^^^^^^^^^^^^^^^^^^^^^^^^^^^^^
  File "/home/airflow/.local/lib/python3.12/site-packages/google/auth/_default.py", line 293, in _get_explicit_environ_credentials
    credentials, project_id = load_credentials_from_file(
                              ^^^^^^^^^^^^^^^^^^^^^^^^^^^
  File "/home/airflow/.local/lib/python3.12/site-packages/google/auth/_default.py", line 125, in load_credentials_from_file
    raise exceptions.DefaultCredentialsError(
google.auth.exceptions.DefaultCredentialsError: File /Users/nd_blaze/nd_blaze.dev/python_dev/DataEngineering/ZoomCamp/taxi-rides-ny-450705-77964478f823.json was not found.
[2025-04-05T23:49:28.834+0000] {processor.py:927} WARNING - No viable dags retrieved from /opt/airflow/dags/dag.py
[2025-04-05T23:49:28.852+0000] {processor.py:208} INFO - Processing /opt/airflow/dags/dag.py took 0.038 seconds
[2025-04-05T23:49:59.821+0000] {processor.py:186} INFO - Started process (PID=106) to work on /opt/airflow/dags/dag.py
[2025-04-05T23:49:59.822+0000] {processor.py:914} INFO - Processing file /opt/airflow/dags/dag.py for tasks to queue
[2025-04-05T23:49:59.826+0000] {logging_mixin.py:190} INFO - [2025-04-05T23:49:59.825+0000] {dagbag.py:588} INFO - Filling up the DagBag from /opt/airflow/dags/dag.py
[2025-04-05T23:49:59.835+0000] {logging_mixin.py:190} INFO - [2025-04-05T23:49:59.832+0000] {dagbag.py:387} ERROR - Failed to import: /opt/airflow/dags/dag.py
Traceback (most recent call last):
  File "/home/airflow/.local/lib/python3.12/site-packages/airflow/models/dagbag.py", line 383, in parse
    loader.exec_module(new_module)
  File "<frozen importlib._bootstrap_external>", line 999, in exec_module
  File "<frozen importlib._bootstrap>", line 488, in _call_with_frames_removed
  File "/opt/airflow/dags/dag.py", line 25, in <module>
    storage_client = storage.Client()
                     ^^^^^^^^^^^^^^^^
  File "/home/airflow/.local/lib/python3.12/site-packages/google/cloud/storage/client.py", line 228, in __init__
    super(Client, self).__init__(
  File "/home/airflow/.local/lib/python3.12/site-packages/google/cloud/client/__init__.py", line 320, in __init__
    _ClientProjectMixin.__init__(self, project=project, credentials=credentials)
  File "/home/airflow/.local/lib/python3.12/site-packages/google/cloud/client/__init__.py", line 268, in __init__
    project = self._determine_default(project)
              ^^^^^^^^^^^^^^^^^^^^^^^^^^^^^^^^
  File "/home/airflow/.local/lib/python3.12/site-packages/google/cloud/client/__init__.py", line 287, in _determine_default
    return _determine_default_project(project)
           ^^^^^^^^^^^^^^^^^^^^^^^^^^^^^^^^^^^
  File "/home/airflow/.local/lib/python3.12/site-packages/google/cloud/_helpers/__init__.py", line 152, in _determine_default_project
    _, project = google.auth.default()
                 ^^^^^^^^^^^^^^^^^^^^^
  File "/home/airflow/.local/lib/python3.12/site-packages/google/auth/_default.py", line 685, in default
    credentials, project_id = checker()
                              ^^^^^^^^^
  File "/home/airflow/.local/lib/python3.12/site-packages/google/auth/_default.py", line 678, in <lambda>
    lambda: _get_explicit_environ_credentials(quota_project_id=quota_project_id),
            ^^^^^^^^^^^^^^^^^^^^^^^^^^^^^^^^^^^^^^^^^^^^^^^^^^^^^^^^^^^^^^^^^^^^
  File "/home/airflow/.local/lib/python3.12/site-packages/google/auth/_default.py", line 293, in _get_explicit_environ_credentials
    credentials, project_id = load_credentials_from_file(
                              ^^^^^^^^^^^^^^^^^^^^^^^^^^^
  File "/home/airflow/.local/lib/python3.12/site-packages/google/auth/_default.py", line 125, in load_credentials_from_file
    raise exceptions.DefaultCredentialsError(
google.auth.exceptions.DefaultCredentialsError: File /Users/nd_blaze/nd_blaze.dev/python_dev/DataEngineering/ZoomCamp/taxi-rides-ny-450705-77964478f823.json was not found.
[2025-04-05T23:49:59.836+0000] {processor.py:927} WARNING - No viable dags retrieved from /opt/airflow/dags/dag.py
[2025-04-05T23:49:59.860+0000] {processor.py:208} INFO - Processing /opt/airflow/dags/dag.py took 0.047 seconds
[2025-04-05T23:50:30.315+0000] {processor.py:186} INFO - Started process (PID=170) to work on /opt/airflow/dags/dag.py
[2025-04-05T23:50:30.317+0000] {processor.py:914} INFO - Processing file /opt/airflow/dags/dag.py for tasks to queue
[2025-04-05T23:50:30.324+0000] {logging_mixin.py:190} INFO - [2025-04-05T23:50:30.323+0000] {dagbag.py:588} INFO - Filling up the DagBag from /opt/airflow/dags/dag.py
[2025-04-05T23:50:30.341+0000] {logging_mixin.py:190} INFO - [2025-04-05T23:50:30.338+0000] {dagbag.py:387} ERROR - Failed to import: /opt/airflow/dags/dag.py
Traceback (most recent call last):
  File "/home/airflow/.local/lib/python3.12/site-packages/airflow/models/dagbag.py", line 383, in parse
    loader.exec_module(new_module)
  File "<frozen importlib._bootstrap_external>", line 999, in exec_module
  File "<frozen importlib._bootstrap>", line 488, in _call_with_frames_removed
  File "/opt/airflow/dags/dag.py", line 25, in <module>
    storage_client = storage.Client()
                     ^^^^^^^^^^^^^^^^
  File "/home/airflow/.local/lib/python3.12/site-packages/google/cloud/storage/client.py", line 228, in __init__
    super(Client, self).__init__(
  File "/home/airflow/.local/lib/python3.12/site-packages/google/cloud/client/__init__.py", line 320, in __init__
    _ClientProjectMixin.__init__(self, project=project, credentials=credentials)
  File "/home/airflow/.local/lib/python3.12/site-packages/google/cloud/client/__init__.py", line 268, in __init__
    project = self._determine_default(project)
              ^^^^^^^^^^^^^^^^^^^^^^^^^^^^^^^^
  File "/home/airflow/.local/lib/python3.12/site-packages/google/cloud/client/__init__.py", line 287, in _determine_default
    return _determine_default_project(project)
           ^^^^^^^^^^^^^^^^^^^^^^^^^^^^^^^^^^^
  File "/home/airflow/.local/lib/python3.12/site-packages/google/cloud/_helpers/__init__.py", line 152, in _determine_default_project
    _, project = google.auth.default()
                 ^^^^^^^^^^^^^^^^^^^^^
  File "/home/airflow/.local/lib/python3.12/site-packages/google/auth/_default.py", line 685, in default
    credentials, project_id = checker()
                              ^^^^^^^^^
  File "/home/airflow/.local/lib/python3.12/site-packages/google/auth/_default.py", line 678, in <lambda>
    lambda: _get_explicit_environ_credentials(quota_project_id=quota_project_id),
            ^^^^^^^^^^^^^^^^^^^^^^^^^^^^^^^^^^^^^^^^^^^^^^^^^^^^^^^^^^^^^^^^^^^^
  File "/home/airflow/.local/lib/python3.12/site-packages/google/auth/_default.py", line 293, in _get_explicit_environ_credentials
    credentials, project_id = load_credentials_from_file(
                              ^^^^^^^^^^^^^^^^^^^^^^^^^^^
  File "/home/airflow/.local/lib/python3.12/site-packages/google/auth/_default.py", line 125, in load_credentials_from_file
    raise exceptions.DefaultCredentialsError(
google.auth.exceptions.DefaultCredentialsError: File /Users/nd_blaze/nd_blaze.dev/python_dev/DataEngineering/ZoomCamp/taxi-rides-ny-450705-77964478f823.json was not found.
[2025-04-05T23:50:30.342+0000] {processor.py:927} WARNING - No viable dags retrieved from /opt/airflow/dags/dag.py
[2025-04-05T23:50:30.369+0000] {processor.py:208} INFO - Processing /opt/airflow/dags/dag.py took 0.070 seconds
[2025-04-05T23:51:00.788+0000] {processor.py:186} INFO - Started process (PID=234) to work on /opt/airflow/dags/dag.py
[2025-04-05T23:51:00.790+0000] {processor.py:914} INFO - Processing file /opt/airflow/dags/dag.py for tasks to queue
[2025-04-05T23:51:00.793+0000] {logging_mixin.py:190} INFO - [2025-04-05T23:51:00.793+0000] {dagbag.py:588} INFO - Filling up the DagBag from /opt/airflow/dags/dag.py
[2025-04-05T23:51:00.800+0000] {logging_mixin.py:190} INFO - [2025-04-05T23:51:00.797+0000] {dagbag.py:387} ERROR - Failed to import: /opt/airflow/dags/dag.py
Traceback (most recent call last):
  File "/home/airflow/.local/lib/python3.12/site-packages/airflow/models/dagbag.py", line 383, in parse
    loader.exec_module(new_module)
  File "<frozen importlib._bootstrap_external>", line 999, in exec_module
  File "<frozen importlib._bootstrap>", line 488, in _call_with_frames_removed
  File "/opt/airflow/dags/dag.py", line 25, in <module>
    storage_client = storage.Client()
                     ^^^^^^^^^^^^^^^^
  File "/home/airflow/.local/lib/python3.12/site-packages/google/cloud/storage/client.py", line 228, in __init__
    super(Client, self).__init__(
  File "/home/airflow/.local/lib/python3.12/site-packages/google/cloud/client/__init__.py", line 320, in __init__
    _ClientProjectMixin.__init__(self, project=project, credentials=credentials)
  File "/home/airflow/.local/lib/python3.12/site-packages/google/cloud/client/__init__.py", line 268, in __init__
    project = self._determine_default(project)
              ^^^^^^^^^^^^^^^^^^^^^^^^^^^^^^^^
  File "/home/airflow/.local/lib/python3.12/site-packages/google/cloud/client/__init__.py", line 287, in _determine_default
    return _determine_default_project(project)
           ^^^^^^^^^^^^^^^^^^^^^^^^^^^^^^^^^^^
  File "/home/airflow/.local/lib/python3.12/site-packages/google/cloud/_helpers/__init__.py", line 152, in _determine_default_project
    _, project = google.auth.default()
                 ^^^^^^^^^^^^^^^^^^^^^
  File "/home/airflow/.local/lib/python3.12/site-packages/google/auth/_default.py", line 685, in default
    credentials, project_id = checker()
                              ^^^^^^^^^
  File "/home/airflow/.local/lib/python3.12/site-packages/google/auth/_default.py", line 678, in <lambda>
    lambda: _get_explicit_environ_credentials(quota_project_id=quota_project_id),
            ^^^^^^^^^^^^^^^^^^^^^^^^^^^^^^^^^^^^^^^^^^^^^^^^^^^^^^^^^^^^^^^^^^^^
  File "/home/airflow/.local/lib/python3.12/site-packages/google/auth/_default.py", line 293, in _get_explicit_environ_credentials
    credentials, project_id = load_credentials_from_file(
                              ^^^^^^^^^^^^^^^^^^^^^^^^^^^
  File "/home/airflow/.local/lib/python3.12/site-packages/google/auth/_default.py", line 125, in load_credentials_from_file
    raise exceptions.DefaultCredentialsError(
google.auth.exceptions.DefaultCredentialsError: File /Users/nd_blaze/nd_blaze.dev/python_dev/DataEngineering/ZoomCamp/taxi-rides-ny-450705-77964478f823.json was not found.
[2025-04-05T23:51:00.800+0000] {processor.py:927} WARNING - No viable dags retrieved from /opt/airflow/dags/dag.py
[2025-04-05T23:51:00.817+0000] {processor.py:208} INFO - Processing /opt/airflow/dags/dag.py took 0.034 seconds
[2025-04-05T23:51:31.092+0000] {processor.py:186} INFO - Started process (PID=298) to work on /opt/airflow/dags/dag.py
[2025-04-05T23:51:31.096+0000] {processor.py:914} INFO - Processing file /opt/airflow/dags/dag.py for tasks to queue
[2025-04-05T23:51:31.099+0000] {logging_mixin.py:190} INFO - [2025-04-05T23:51:31.099+0000] {dagbag.py:588} INFO - Filling up the DagBag from /opt/airflow/dags/dag.py
[2025-04-05T23:51:31.106+0000] {logging_mixin.py:190} INFO - [2025-04-05T23:51:31.104+0000] {dagbag.py:387} ERROR - Failed to import: /opt/airflow/dags/dag.py
Traceback (most recent call last):
  File "/home/airflow/.local/lib/python3.12/site-packages/airflow/models/dagbag.py", line 383, in parse
    loader.exec_module(new_module)
  File "<frozen importlib._bootstrap_external>", line 999, in exec_module
  File "<frozen importlib._bootstrap>", line 488, in _call_with_frames_removed
  File "/opt/airflow/dags/dag.py", line 25, in <module>
    storage_client = storage.Client()
                     ^^^^^^^^^^^^^^^^
  File "/home/airflow/.local/lib/python3.12/site-packages/google/cloud/storage/client.py", line 228, in __init__
    super(Client, self).__init__(
  File "/home/airflow/.local/lib/python3.12/site-packages/google/cloud/client/__init__.py", line 320, in __init__
    _ClientProjectMixin.__init__(self, project=project, credentials=credentials)
  File "/home/airflow/.local/lib/python3.12/site-packages/google/cloud/client/__init__.py", line 268, in __init__
    project = self._determine_default(project)
              ^^^^^^^^^^^^^^^^^^^^^^^^^^^^^^^^
  File "/home/airflow/.local/lib/python3.12/site-packages/google/cloud/client/__init__.py", line 287, in _determine_default
    return _determine_default_project(project)
           ^^^^^^^^^^^^^^^^^^^^^^^^^^^^^^^^^^^
  File "/home/airflow/.local/lib/python3.12/site-packages/google/cloud/_helpers/__init__.py", line 152, in _determine_default_project
    _, project = google.auth.default()
                 ^^^^^^^^^^^^^^^^^^^^^
  File "/home/airflow/.local/lib/python3.12/site-packages/google/auth/_default.py", line 685, in default
    credentials, project_id = checker()
                              ^^^^^^^^^
  File "/home/airflow/.local/lib/python3.12/site-packages/google/auth/_default.py", line 678, in <lambda>
    lambda: _get_explicit_environ_credentials(quota_project_id=quota_project_id),
            ^^^^^^^^^^^^^^^^^^^^^^^^^^^^^^^^^^^^^^^^^^^^^^^^^^^^^^^^^^^^^^^^^^^^
  File "/home/airflow/.local/lib/python3.12/site-packages/google/auth/_default.py", line 293, in _get_explicit_environ_credentials
    credentials, project_id = load_credentials_from_file(
                              ^^^^^^^^^^^^^^^^^^^^^^^^^^^
  File "/home/airflow/.local/lib/python3.12/site-packages/google/auth/_default.py", line 125, in load_credentials_from_file
    raise exceptions.DefaultCredentialsError(
google.auth.exceptions.DefaultCredentialsError: File /Users/nd_blaze/nd_blaze.dev/python_dev/DataEngineering/ZoomCamp/taxi-rides-ny-450705-77964478f823.json was not found.
[2025-04-05T23:51:31.107+0000] {processor.py:927} WARNING - No viable dags retrieved from /opt/airflow/dags/dag.py
[2025-04-05T23:51:31.128+0000] {processor.py:208} INFO - Processing /opt/airflow/dags/dag.py took 0.048 seconds
[2025-04-05T23:52:01.470+0000] {processor.py:186} INFO - Started process (PID=362) to work on /opt/airflow/dags/dag.py
[2025-04-05T23:52:01.473+0000] {processor.py:914} INFO - Processing file /opt/airflow/dags/dag.py for tasks to queue
[2025-04-05T23:52:01.477+0000] {logging_mixin.py:190} INFO - [2025-04-05T23:52:01.477+0000] {dagbag.py:588} INFO - Filling up the DagBag from /opt/airflow/dags/dag.py
[2025-04-05T23:52:01.493+0000] {logging_mixin.py:190} INFO - [2025-04-05T23:52:01.487+0000] {dagbag.py:387} ERROR - Failed to import: /opt/airflow/dags/dag.py
Traceback (most recent call last):
  File "/home/airflow/.local/lib/python3.12/site-packages/airflow/models/dagbag.py", line 383, in parse
    loader.exec_module(new_module)
  File "<frozen importlib._bootstrap_external>", line 999, in exec_module
  File "<frozen importlib._bootstrap>", line 488, in _call_with_frames_removed
  File "/opt/airflow/dags/dag.py", line 25, in <module>
    storage_client = storage.Client()
                     ^^^^^^^^^^^^^^^^
  File "/home/airflow/.local/lib/python3.12/site-packages/google/cloud/storage/client.py", line 228, in __init__
    super(Client, self).__init__(
  File "/home/airflow/.local/lib/python3.12/site-packages/google/cloud/client/__init__.py", line 320, in __init__
    _ClientProjectMixin.__init__(self, project=project, credentials=credentials)
  File "/home/airflow/.local/lib/python3.12/site-packages/google/cloud/client/__init__.py", line 268, in __init__
    project = self._determine_default(project)
              ^^^^^^^^^^^^^^^^^^^^^^^^^^^^^^^^
  File "/home/airflow/.local/lib/python3.12/site-packages/google/cloud/client/__init__.py", line 287, in _determine_default
    return _determine_default_project(project)
           ^^^^^^^^^^^^^^^^^^^^^^^^^^^^^^^^^^^
  File "/home/airflow/.local/lib/python3.12/site-packages/google/cloud/_helpers/__init__.py", line 152, in _determine_default_project
    _, project = google.auth.default()
                 ^^^^^^^^^^^^^^^^^^^^^
  File "/home/airflow/.local/lib/python3.12/site-packages/google/auth/_default.py", line 685, in default
    credentials, project_id = checker()
                              ^^^^^^^^^
  File "/home/airflow/.local/lib/python3.12/site-packages/google/auth/_default.py", line 678, in <lambda>
    lambda: _get_explicit_environ_credentials(quota_project_id=quota_project_id),
            ^^^^^^^^^^^^^^^^^^^^^^^^^^^^^^^^^^^^^^^^^^^^^^^^^^^^^^^^^^^^^^^^^^^^
  File "/home/airflow/.local/lib/python3.12/site-packages/google/auth/_default.py", line 293, in _get_explicit_environ_credentials
    credentials, project_id = load_credentials_from_file(
                              ^^^^^^^^^^^^^^^^^^^^^^^^^^^
  File "/home/airflow/.local/lib/python3.12/site-packages/google/auth/_default.py", line 125, in load_credentials_from_file
    raise exceptions.DefaultCredentialsError(
google.auth.exceptions.DefaultCredentialsError: File /Users/nd_blaze/nd_blaze.dev/python_dev/DataEngineering/ZoomCamp/taxi-rides-ny-450705-77964478f823.json was not found.
[2025-04-05T23:52:01.494+0000] {processor.py:927} WARNING - No viable dags retrieved from /opt/airflow/dags/dag.py
[2025-04-05T23:52:01.542+0000] {processor.py:208} INFO - Processing /opt/airflow/dags/dag.py took 0.080 seconds
[2025-04-05T23:52:58.441+0000] {processor.py:186} INFO - Started process (PID=48) to work on /opt/airflow/dags/dag.py
[2025-04-05T23:52:58.443+0000] {processor.py:914} INFO - Processing file /opt/airflow/dags/dag.py for tasks to queue
[2025-04-05T23:52:58.446+0000] {logging_mixin.py:190} INFO - [2025-04-05T23:52:58.445+0000] {dagbag.py:588} INFO - Filling up the DagBag from /opt/airflow/dags/dag.py
[2025-04-05T23:52:58.454+0000] {logging_mixin.py:190} INFO - [2025-04-05T23:52:58.451+0000] {dagbag.py:387} ERROR - Failed to import: /opt/airflow/dags/dag.py
Traceback (most recent call last):
  File "/home/airflow/.local/lib/python3.12/site-packages/airflow/models/dagbag.py", line 383, in parse
    loader.exec_module(new_module)
  File "<frozen importlib._bootstrap_external>", line 999, in exec_module
  File "<frozen importlib._bootstrap>", line 488, in _call_with_frames_removed
  File "/opt/airflow/dags/dag.py", line 25, in <module>
    storage_client = storage.Client()
                     ^^^^^^^^^^^^^^^^
  File "/home/airflow/.local/lib/python3.12/site-packages/google/cloud/storage/client.py", line 228, in __init__
    super(Client, self).__init__(
  File "/home/airflow/.local/lib/python3.12/site-packages/google/cloud/client/__init__.py", line 320, in __init__
    _ClientProjectMixin.__init__(self, project=project, credentials=credentials)
  File "/home/airflow/.local/lib/python3.12/site-packages/google/cloud/client/__init__.py", line 268, in __init__
    project = self._determine_default(project)
              ^^^^^^^^^^^^^^^^^^^^^^^^^^^^^^^^
  File "/home/airflow/.local/lib/python3.12/site-packages/google/cloud/client/__init__.py", line 287, in _determine_default
    return _determine_default_project(project)
           ^^^^^^^^^^^^^^^^^^^^^^^^^^^^^^^^^^^
  File "/home/airflow/.local/lib/python3.12/site-packages/google/cloud/_helpers/__init__.py", line 152, in _determine_default_project
    _, project = google.auth.default()
                 ^^^^^^^^^^^^^^^^^^^^^
  File "/home/airflow/.local/lib/python3.12/site-packages/google/auth/_default.py", line 685, in default
    credentials, project_id = checker()
                              ^^^^^^^^^
  File "/home/airflow/.local/lib/python3.12/site-packages/google/auth/_default.py", line 678, in <lambda>
    lambda: _get_explicit_environ_credentials(quota_project_id=quota_project_id),
            ^^^^^^^^^^^^^^^^^^^^^^^^^^^^^^^^^^^^^^^^^^^^^^^^^^^^^^^^^^^^^^^^^^^^
  File "/home/airflow/.local/lib/python3.12/site-packages/google/auth/_default.py", line 293, in _get_explicit_environ_credentials
    credentials, project_id = load_credentials_from_file(
                              ^^^^^^^^^^^^^^^^^^^^^^^^^^^
  File "/home/airflow/.local/lib/python3.12/site-packages/google/auth/_default.py", line 125, in load_credentials_from_file
    raise exceptions.DefaultCredentialsError(
google.auth.exceptions.DefaultCredentialsError: File /Users/nd_blaze/nd_blaze.dev/python_dev/DataEngineering/ZoomCamp/taxi-rides-ny-450705-77964478f823.json was not found.
[2025-04-05T23:52:58.454+0000] {processor.py:927} WARNING - No viable dags retrieved from /opt/airflow/dags/dag.py
[2025-04-05T23:52:58.470+0000] {processor.py:208} INFO - Processing /opt/airflow/dags/dag.py took 0.034 seconds
[2025-04-05T23:53:46.607+0000] {processor.py:186} INFO - Started process (PID=42) to work on /opt/airflow/dags/dag.py
[2025-04-05T23:53:46.610+0000] {processor.py:914} INFO - Processing file /opt/airflow/dags/dag.py for tasks to queue
[2025-04-05T23:53:46.614+0000] {logging_mixin.py:190} INFO - [2025-04-05T23:53:46.613+0000] {dagbag.py:588} INFO - Filling up the DagBag from /opt/airflow/dags/dag.py
[2025-04-05T23:53:46.626+0000] {logging_mixin.py:190} INFO - [2025-04-05T23:53:46.623+0000] {dagbag.py:387} ERROR - Failed to import: /opt/airflow/dags/dag.py
Traceback (most recent call last):
  File "/home/airflow/.local/lib/python3.12/site-packages/airflow/models/dagbag.py", line 383, in parse
    loader.exec_module(new_module)
  File "<frozen importlib._bootstrap_external>", line 999, in exec_module
  File "<frozen importlib._bootstrap>", line 488, in _call_with_frames_removed
  File "/opt/airflow/dags/dag.py", line 25, in <module>
    storage_client = storage.Client()
                     ^^^^^^^^^^^^^^^^
  File "/home/airflow/.local/lib/python3.12/site-packages/google/cloud/storage/client.py", line 228, in __init__
    super(Client, self).__init__(
  File "/home/airflow/.local/lib/python3.12/site-packages/google/cloud/client/__init__.py", line 320, in __init__
    _ClientProjectMixin.__init__(self, project=project, credentials=credentials)
  File "/home/airflow/.local/lib/python3.12/site-packages/google/cloud/client/__init__.py", line 268, in __init__
    project = self._determine_default(project)
              ^^^^^^^^^^^^^^^^^^^^^^^^^^^^^^^^
  File "/home/airflow/.local/lib/python3.12/site-packages/google/cloud/client/__init__.py", line 287, in _determine_default
    return _determine_default_project(project)
           ^^^^^^^^^^^^^^^^^^^^^^^^^^^^^^^^^^^
  File "/home/airflow/.local/lib/python3.12/site-packages/google/cloud/_helpers/__init__.py", line 152, in _determine_default_project
    _, project = google.auth.default()
                 ^^^^^^^^^^^^^^^^^^^^^
  File "/home/airflow/.local/lib/python3.12/site-packages/google/auth/_default.py", line 685, in default
    credentials, project_id = checker()
                              ^^^^^^^^^
  File "/home/airflow/.local/lib/python3.12/site-packages/google/auth/_default.py", line 678, in <lambda>
    lambda: _get_explicit_environ_credentials(quota_project_id=quota_project_id),
            ^^^^^^^^^^^^^^^^^^^^^^^^^^^^^^^^^^^^^^^^^^^^^^^^^^^^^^^^^^^^^^^^^^^^
  File "/home/airflow/.local/lib/python3.12/site-packages/google/auth/_default.py", line 293, in _get_explicit_environ_credentials
    credentials, project_id = load_credentials_from_file(
                              ^^^^^^^^^^^^^^^^^^^^^^^^^^^
  File "/home/airflow/.local/lib/python3.12/site-packages/google/auth/_default.py", line 125, in load_credentials_from_file
    raise exceptions.DefaultCredentialsError(
google.auth.exceptions.DefaultCredentialsError: File /Users/nd_blaze/nd_blaze.dev/python_dev/DataEngineering/ZoomCamp/taxi-rides-ny-450705-77964478f823.json was not found.
[2025-04-05T23:53:46.626+0000] {processor.py:927} WARNING - No viable dags retrieved from /opt/airflow/dags/dag.py
[2025-04-05T23:53:46.654+0000] {processor.py:208} INFO - Processing /opt/airflow/dags/dag.py took 0.049 seconds
[2025-04-05T23:54:17.039+0000] {processor.py:186} INFO - Started process (PID=105) to work on /opt/airflow/dags/dag.py
[2025-04-05T23:54:17.041+0000] {processor.py:914} INFO - Processing file /opt/airflow/dags/dag.py for tasks to queue
[2025-04-05T23:54:17.044+0000] {logging_mixin.py:190} INFO - [2025-04-05T23:54:17.044+0000] {dagbag.py:588} INFO - Filling up the DagBag from /opt/airflow/dags/dag.py
[2025-04-05T23:54:17.059+0000] {logging_mixin.py:190} INFO - [2025-04-05T23:54:17.057+0000] {dagbag.py:387} ERROR - Failed to import: /opt/airflow/dags/dag.py
Traceback (most recent call last):
  File "/home/airflow/.local/lib/python3.12/site-packages/airflow/models/dagbag.py", line 383, in parse
    loader.exec_module(new_module)
  File "<frozen importlib._bootstrap_external>", line 999, in exec_module
  File "<frozen importlib._bootstrap>", line 488, in _call_with_frames_removed
  File "/opt/airflow/dags/dag.py", line 25, in <module>
    storage_client = storage.Client()
                     ^^^^^^^^^^^^^^^^
  File "/home/airflow/.local/lib/python3.12/site-packages/google/cloud/storage/client.py", line 228, in __init__
    super(Client, self).__init__(
  File "/home/airflow/.local/lib/python3.12/site-packages/google/cloud/client/__init__.py", line 320, in __init__
    _ClientProjectMixin.__init__(self, project=project, credentials=credentials)
  File "/home/airflow/.local/lib/python3.12/site-packages/google/cloud/client/__init__.py", line 268, in __init__
    project = self._determine_default(project)
              ^^^^^^^^^^^^^^^^^^^^^^^^^^^^^^^^
  File "/home/airflow/.local/lib/python3.12/site-packages/google/cloud/client/__init__.py", line 287, in _determine_default
    return _determine_default_project(project)
           ^^^^^^^^^^^^^^^^^^^^^^^^^^^^^^^^^^^
  File "/home/airflow/.local/lib/python3.12/site-packages/google/cloud/_helpers/__init__.py", line 152, in _determine_default_project
    _, project = google.auth.default()
                 ^^^^^^^^^^^^^^^^^^^^^
  File "/home/airflow/.local/lib/python3.12/site-packages/google/auth/_default.py", line 685, in default
    credentials, project_id = checker()
                              ^^^^^^^^^
  File "/home/airflow/.local/lib/python3.12/site-packages/google/auth/_default.py", line 678, in <lambda>
    lambda: _get_explicit_environ_credentials(quota_project_id=quota_project_id),
            ^^^^^^^^^^^^^^^^^^^^^^^^^^^^^^^^^^^^^^^^^^^^^^^^^^^^^^^^^^^^^^^^^^^^
  File "/home/airflow/.local/lib/python3.12/site-packages/google/auth/_default.py", line 293, in _get_explicit_environ_credentials
    credentials, project_id = load_credentials_from_file(
                              ^^^^^^^^^^^^^^^^^^^^^^^^^^^
  File "/home/airflow/.local/lib/python3.12/site-packages/google/auth/_default.py", line 125, in load_credentials_from_file
    raise exceptions.DefaultCredentialsError(
google.auth.exceptions.DefaultCredentialsError: File /Users/nd_blaze/nd_blaze.dev/python_dev/DataEngineering/ZoomCamp/taxi-rides-ny-450705-77964478f823.json was not found.
[2025-04-05T23:54:17.059+0000] {processor.py:927} WARNING - No viable dags retrieved from /opt/airflow/dags/dag.py
[2025-04-05T23:54:17.073+0000] {processor.py:208} INFO - Processing /opt/airflow/dags/dag.py took 0.038 seconds
[2025-04-05T23:55:49.054+0000] {processor.py:186} INFO - Started process (PID=49) to work on /opt/airflow/dags/dag.py
[2025-04-05T23:55:49.057+0000] {processor.py:914} INFO - Processing file /opt/airflow/dags/dag.py for tasks to queue
[2025-04-05T23:55:49.063+0000] {logging_mixin.py:190} INFO - [2025-04-05T23:55:49.063+0000] {dagbag.py:588} INFO - Filling up the DagBag from /opt/airflow/dags/dag.py
[2025-04-05T23:55:49.072+0000] {logging_mixin.py:190} INFO - [2025-04-05T23:55:49.068+0000] {dagbag.py:387} ERROR - Failed to import: /opt/airflow/dags/dag.py
Traceback (most recent call last):
  File "/home/airflow/.local/lib/python3.12/site-packages/airflow/models/dagbag.py", line 383, in parse
    loader.exec_module(new_module)
  File "<frozen importlib._bootstrap_external>", line 999, in exec_module
  File "<frozen importlib._bootstrap>", line 488, in _call_with_frames_removed
  File "/opt/airflow/dags/dag.py", line 25, in <module>
    storage_client = storage.Client()
                     ^^^^^^^^^^^^^^^^
  File "/home/airflow/.local/lib/python3.12/site-packages/google/cloud/storage/client.py", line 228, in __init__
    super(Client, self).__init__(
  File "/home/airflow/.local/lib/python3.12/site-packages/google/cloud/client/__init__.py", line 320, in __init__
    _ClientProjectMixin.__init__(self, project=project, credentials=credentials)
  File "/home/airflow/.local/lib/python3.12/site-packages/google/cloud/client/__init__.py", line 268, in __init__
    project = self._determine_default(project)
              ^^^^^^^^^^^^^^^^^^^^^^^^^^^^^^^^
  File "/home/airflow/.local/lib/python3.12/site-packages/google/cloud/client/__init__.py", line 287, in _determine_default
    return _determine_default_project(project)
           ^^^^^^^^^^^^^^^^^^^^^^^^^^^^^^^^^^^
  File "/home/airflow/.local/lib/python3.12/site-packages/google/cloud/_helpers/__init__.py", line 152, in _determine_default_project
    _, project = google.auth.default()
                 ^^^^^^^^^^^^^^^^^^^^^
  File "/home/airflow/.local/lib/python3.12/site-packages/google/auth/_default.py", line 685, in default
    credentials, project_id = checker()
                              ^^^^^^^^^
  File "/home/airflow/.local/lib/python3.12/site-packages/google/auth/_default.py", line 678, in <lambda>
    lambda: _get_explicit_environ_credentials(quota_project_id=quota_project_id),
            ^^^^^^^^^^^^^^^^^^^^^^^^^^^^^^^^^^^^^^^^^^^^^^^^^^^^^^^^^^^^^^^^^^^^
  File "/home/airflow/.local/lib/python3.12/site-packages/google/auth/_default.py", line 293, in _get_explicit_environ_credentials
    credentials, project_id = load_credentials_from_file(
                              ^^^^^^^^^^^^^^^^^^^^^^^^^^^
  File "/home/airflow/.local/lib/python3.12/site-packages/google/auth/_default.py", line 125, in load_credentials_from_file
    raise exceptions.DefaultCredentialsError(
google.auth.exceptions.DefaultCredentialsError: File /Users/nd_blaze/nd_blaze.dev/python_dev/DataEngineering/ZoomCamp/taxi-rides-ny-450705-77964478f823.json was not found.
[2025-04-05T23:55:49.072+0000] {processor.py:927} WARNING - No viable dags retrieved from /opt/airflow/dags/dag.py
[2025-04-05T23:55:49.098+0000] {processor.py:208} INFO - Processing /opt/airflow/dags/dag.py took 0.050 seconds
[2025-04-05T23:56:19.963+0000] {processor.py:186} INFO - Started process (PID=113) to work on /opt/airflow/dags/dag.py
[2025-04-05T23:56:19.966+0000] {processor.py:914} INFO - Processing file /opt/airflow/dags/dag.py for tasks to queue
[2025-04-05T23:56:19.968+0000] {logging_mixin.py:190} INFO - [2025-04-05T23:56:19.968+0000] {dagbag.py:588} INFO - Filling up the DagBag from /opt/airflow/dags/dag.py
[2025-04-05T23:56:19.979+0000] {logging_mixin.py:190} INFO - [2025-04-05T23:56:19.977+0000] {dagbag.py:387} ERROR - Failed to import: /opt/airflow/dags/dag.py
Traceback (most recent call last):
  File "/home/airflow/.local/lib/python3.12/site-packages/airflow/models/dagbag.py", line 383, in parse
    loader.exec_module(new_module)
  File "<frozen importlib._bootstrap_external>", line 999, in exec_module
  File "<frozen importlib._bootstrap>", line 488, in _call_with_frames_removed
  File "/opt/airflow/dags/dag.py", line 25, in <module>
    storage_client = storage.Client()
                     ^^^^^^^^^^^^^^^^
  File "/home/airflow/.local/lib/python3.12/site-packages/google/cloud/storage/client.py", line 228, in __init__
    super(Client, self).__init__(
  File "/home/airflow/.local/lib/python3.12/site-packages/google/cloud/client/__init__.py", line 320, in __init__
    _ClientProjectMixin.__init__(self, project=project, credentials=credentials)
  File "/home/airflow/.local/lib/python3.12/site-packages/google/cloud/client/__init__.py", line 268, in __init__
    project = self._determine_default(project)
              ^^^^^^^^^^^^^^^^^^^^^^^^^^^^^^^^
  File "/home/airflow/.local/lib/python3.12/site-packages/google/cloud/client/__init__.py", line 287, in _determine_default
    return _determine_default_project(project)
           ^^^^^^^^^^^^^^^^^^^^^^^^^^^^^^^^^^^
  File "/home/airflow/.local/lib/python3.12/site-packages/google/cloud/_helpers/__init__.py", line 152, in _determine_default_project
    _, project = google.auth.default()
                 ^^^^^^^^^^^^^^^^^^^^^
  File "/home/airflow/.local/lib/python3.12/site-packages/google/auth/_default.py", line 685, in default
    credentials, project_id = checker()
                              ^^^^^^^^^
  File "/home/airflow/.local/lib/python3.12/site-packages/google/auth/_default.py", line 678, in <lambda>
    lambda: _get_explicit_environ_credentials(quota_project_id=quota_project_id),
            ^^^^^^^^^^^^^^^^^^^^^^^^^^^^^^^^^^^^^^^^^^^^^^^^^^^^^^^^^^^^^^^^^^^^
  File "/home/airflow/.local/lib/python3.12/site-packages/google/auth/_default.py", line 293, in _get_explicit_environ_credentials
    credentials, project_id = load_credentials_from_file(
                              ^^^^^^^^^^^^^^^^^^^^^^^^^^^
  File "/home/airflow/.local/lib/python3.12/site-packages/google/auth/_default.py", line 125, in load_credentials_from_file
    raise exceptions.DefaultCredentialsError(
google.auth.exceptions.DefaultCredentialsError: File /Users/nd_blaze/nd_blaze.dev/python_dev/DataEngineering/ZoomCamp/taxi-rides-ny-450705-77964478f823.json was not found.
[2025-04-05T23:56:19.980+0000] {processor.py:927} WARNING - No viable dags retrieved from /opt/airflow/dags/dag.py
[2025-04-05T23:56:19.995+0000] {processor.py:208} INFO - Processing /opt/airflow/dags/dag.py took 0.039 seconds
